<sdf version='1.8'>
  <model name='tb4_lss_arm'>
    <joint name='tb4_base_joint' type='fixed'>
      <pose relative_to='__model__'>0 0 0 0 -0 0</pose>
      <parent>world</parent>
      <child>base_link</child>
    </joint>
    <link name='base_link'>
      <pose relative_to='tb4_base_joint'>0 0 0 0 -0 0</pose>
      <inertial>
        <pose>0.003623 0.000229 0.076211 0 -0 0</pose>
        <mass>2.461741081366601</mass>
        <inertia>
          <ixx>0.018686524735972779</ixx>
          <ixy>-3.3437284372753947e-05</ixy>
          <ixz>-0.00042429773144600692</ixz>
          <iyy>0.01905543337614787</iyy>
          <iyz>-8.3906898402227875e-05</iyz>
          <izz>0.032281191280270703</izz>
        </inertia>
      </inertial>
      <collision name='base_link_fixed_joint_lump__create3_base_collision_collision'>
        <pose>0 0 0.0492 0 -0 1.5708</pose>
        <geometry>
          <cylinder>
            <length>0.059999999999999998</length>
            <radius>0.16400000000000001</radius>
          </cylinder>
        </geometry>
      </collision>
      <collision name='base_link_fixed_joint_lump__lss_arm_base_link_collision_1'>
        <pose>0 0 0 0 -0 0</pose>
        <geometry>
          <mesh>
            <scale>1 1 1</scale>
            <uri>meshes/collision/lss_base.STL</uri>
          </mesh>
        </geometry>
        <surface>
          <contact>
            <ode/>
          </contact>
          <friction>
            <ode>
              <mu>0.29999999999999999</mu>
              <mu2>0.29999999999999999</mu2>
            </ode>
          </friction>
        </surface>
      </collision>
      <collision name='base_link_fixed_joint_lump__lss_arm_link_0_collision_2'>
        <pose>0.063 0 0.2 0 -0 0</pose>
        <geometry>
          <mesh>
            <scale>1 1 1</scale>
            <uri>meshes/collision/link_0.STL</uri>
          </mesh>
        </geometry>
        <surface>
          <contact>
            <ode/>
          </contact>
          <friction>
            <ode>
              <mu>0.29999999999999999</mu>
              <mu2>0.29999999999999999</mu2>
            </ode>
          </friction>
        </surface>
      </collision>
      <visual name='base_link_visual'>
        <pose>0 0 0.0392 0 -0 1.5708</pose>
        <geometry>
          <mesh>
            <scale>1 1 1</scale>
            <uri>model://irobot_create_description/meshes/body_visual.dae</uri>
          </mesh>
        </geometry>
      </visual>
      <visual name='base_link_fixed_joint_lump__lss_arm_base_link_visual_1'>
        <pose>0 0 0 0 -0 0</pose>
        <geometry>
          <mesh>
            <scale>1 1 1</scale>
            <uri>meshes/visual/lss_base.STL</uri>
          </mesh>
        </geometry>
        <material>
          <diffuse>0.375 0.375 0.375 1</diffuse>
          <ambient>0.375 0.375 0.375 1</ambient>
        </material>
      </visual>
      <visual name='base_link_fixed_joint_lump__lss_arm_link_0_visual_2'>
        <pose>0.063 0 0.2 0 -0 0</pose>
        <geometry>
          <mesh>
            <scale>1 1 1</scale>
            <uri>meshes/visual/link_0.STL</uri>
          </mesh>
        </geometry>
        <material>
          <diffuse>0.375 0.375 0.375 1</diffuse>
          <ambient>0.375 0.375 0.375 1</ambient>
        </material>
      </visual>
      <sensor name='cliff_front_left' type='ray'>
        <update_rate>62</update_rate>
        <visualize>0</visualize>
        <always_on>1</always_on>
        <ray>
          <scan>
            <horizontal>
              <samples>1</samples>
              <resolution>1</resolution>
              <min_angle>-0.043633231299858237</min_angle>
              <max_angle>0.043633231299858237</max_angle>
            </horizontal>
            <vertical>
              <samples>1</samples>
              <resolution>1</resolution>
              <min_angle>0</min_angle>
              <max_angle>0</max_angle>
            </vertical>
          </scan>
          <range>
            <min>0.0001</min>
            <max>0.14999999999999999</max>
            <resolution>1</resolution>
          </range>
        </ray>
        <plugin name='cliff_front_left' filename='libgazebo_ros_create_cliff_sensor.so'>
          <ros>
            <namespace>/</namespace>
            <remapping>~/out:=_internal/cliff_front_left/event</remapping>
          </ros>
          <detection_threshold>0.08</detection_threshold>
          <frame_id>cliff_front_left</frame_id>
        </plugin>
        <pose>0.16 0.045 0.0192 0 1.39626 1.1397</pose>
        <noise>
          <type>gaussian</type>
          <mean>0.0</mean>
          <stddev>0.0</stddev>
        </noise>
      </sensor>
      <sensor name='cliff_front_right' type='ray'>
        <update_rate>62</update_rate>
        <visualize>0</visualize>
        <always_on>1</always_on>
        <ray>
          <scan>
            <horizontal>
              <samples>1</samples>
              <resolution>1</resolution>
              <min_angle>-0.043633231299858237</min_angle>
              <max_angle>0.043633231299858237</max_angle>
            </horizontal>
            <vertical>
              <samples>1</samples>
              <resolution>1</resolution>
              <min_angle>0</min_angle>
              <max_angle>0</max_angle>
            </vertical>
          </scan>
          <range>
            <min>0.0001</min>
            <max>0.14999999999999999</max>
            <resolution>1</resolution>
          </range>
        </ray>
        <plugin name='cliff_front_right' filename='libgazebo_ros_create_cliff_sensor.so'>
          <ros>
            <namespace>/</namespace>
            <remapping>~/out:=_internal/cliff_front_right/event</remapping>
          </ros>
          <detection_threshold>0.08</detection_threshold>
          <frame_id>cliff_front_right</frame_id>
        </plugin>
        <pose>0.16 -0.045 0.0192 0 1.39626 -1.1397</pose>
        <noise>
          <type>gaussian</type>
          <mean>0.0</mean>
          <stddev>0.0</stddev>
        </noise>
      </sensor>
      <sensor name='cliff_side_left' type='ray'>
        <update_rate>62</update_rate>
        <visualize>0</visualize>
        <always_on>1</always_on>
        <ray>
          <scan>
            <horizontal>
              <samples>1</samples>
              <resolution>1</resolution>
              <min_angle>-0.043633231299858237</min_angle>
              <max_angle>0.043633231299858237</max_angle>
            </horizontal>
            <vertical>
              <samples>1</samples>
              <resolution>1</resolution>
              <min_angle>0</min_angle>
              <max_angle>0</max_angle>
            </vertical>
          </scan>
          <range>
            <min>0.0001</min>
            <max>0.14999999999999999</max>
            <resolution>1</resolution>
          </range>
        </ray>
        <plugin name='cliff_side_left' filename='libgazebo_ros_create_cliff_sensor.so'>
          <ros>
            <namespace>/</namespace>
            <remapping>~/out:=_internal/cliff_side_left/event</remapping>
          </ros>
          <detection_threshold>0.08</detection_threshold>
          <frame_id>cliff_side_left</frame_id>
        </plugin>
        <pose>0.06 0.145 0.0192 0 1.39626 2.92168</pose>
        <noise>
          <type>gaussian</type>
          <mean>0.0</mean>
          <stddev>0.0</stddev>
        </noise>
      </sensor>
      <sensor name='cliff_side_right' type='ray'>
        <update_rate>62</update_rate>
        <visualize>0</visualize>
        <always_on>1</always_on>
        <ray>
          <scan>
            <horizontal>
              <samples>1</samples>
              <resolution>1</resolution>
              <min_angle>-0.043633231299858237</min_angle>
              <max_angle>0.043633231299858237</max_angle>
            </horizontal>
            <vertical>
              <samples>1</samples>
              <resolution>1</resolution>
              <min_angle>0</min_angle>
              <max_angle>0</max_angle>
            </vertical>
          </scan>
          <range>
            <min>0.0001</min>
            <max>0.14999999999999999</max>
            <resolution>1</resolution>
          </range>
        </ray>
        <plugin name='cliff_side_right' filename='libgazebo_ros_create_cliff_sensor.so'>
          <ros>
            <namespace>/</namespace>
            <remapping>~/out:=_internal/cliff_side_right/event</remapping>
          </ros>
          <detection_threshold>0.08</detection_threshold>
          <frame_id>cliff_side_right</frame_id>
        </plugin>
        <pose>0.06 -0.145 0.0192 -0 1.39626 -2.92168</pose>
        <noise>
          <type>gaussian</type>
          <mean>0.0</mean>
          <stddev>0.0</stddev>
        </noise>
      </sensor>
    </link>
    <joint name='bump_front_center_joint' type='fixed'>
      <pose relative_to='base_link'>0 0 0.0392 0 -0 0</pose>
      <parent>base_link</parent>
      <child>bump_front_center</child>
      <axis>
        <dynamics>
          <spring_reference>0</spring_reference>
          <spring_stiffness>0</spring_stiffness>
        </dynamics>
        <xyz>0 0 1</xyz>
        <limit>
          <lower>-10000000000000000</lower>
          <upper>10000000000000000</upper>
        </limit>
      </axis>
      <physics>
        <ode>
          <limit>
            <cfm>0</cfm>
            <erp>0.20000000000000001</erp>
          </limit>
        </ode>
      </physics>
    </joint>
    <link name='bump_front_center'>
      <pose relative_to='bump_front_center_joint'>0 0 0 0 -0 0</pose>
      <inertial>
        <pose>0.08 0 0.02 0 -0 0</pose>
        <mass>0.10000000000000001</mass>
        <inertia>
          <ixx>0.0013483753404999999</ixx>
          <ixy>4.54352e-08</ixy>
          <ixz>1.4434849000000001e-06</ixz>
          <iyy>0.0002521736852</iyy>
          <iyz>-6.7209999999999998e-10</iyz>
          <izz>0.0015442525386</izz>
        </inertia>
      </inertial>
      <collision name='bump_front_center_collision'>
        <pose>0 0 0 0 -0 0</pose>
        <geometry>
          <mesh>
            <scale>1 1 1</scale>
            <uri>model://irobot_create_description/meshes/bumper_collision.dae</uri>
          </mesh>
        </geometry>
        <surface>
          <contact>
            <ode>
              <max_vel>0.01</max_vel>
              <min_depth>0.001</min_depth>
            </ode>
          </contact>
          <friction>
            <ode>
              <mu>0.10000000000000001</mu>
              <mu2>0.10000000000000001</mu2>
            </ode>
          </friction>
        </surface>
        <max_contacts>10</max_contacts>
      </collision>
      <visual name='bump_front_center_visual'>
        <pose>0 0 0 0 -0 0</pose>
        <geometry>
          <mesh>
            <scale>1 1 1</scale>
            <uri>model://irobot_create_description/meshes/bumper_visual.dae</uri>
          </mesh>
        </geometry>
        <material>
          <script>
            <name>Gazebo/DarkGrey</name>
            <uri>file://media/materials/scripts/gazebo.material</uri>
          </script>
        </material>
      </visual>
      <sensor name='bump_front_center_contact_sensor' type='contact'>
        <always_on>1</always_on>
        <update_rate>62</update_rate>
        <contact>
          <collision>bump_front_center_collision</collision>
          <topic>__default_topic__</topic>
        </contact>
        <plugin name='bump_front_center_plugin' filename='libgazebo_ros_create_bumper.so'>
          <ros>
            <namespace>/</namespace>
            <remapping>~/out:=_internal/bumper/event</remapping>
          </ros>
        </plugin>
      </sensor>
    </link>
    <joint name='front_caster_joint' type='fixed'>
      <pose relative_to='base_link'>0.125 0 0.0122 -1.5708 0 0</pose>
      <parent>base_link</parent>
      <child>front_caster_link</child>
      <axis>
        <dynamics>
          <spring_reference>0</spring_reference>
          <spring_stiffness>0</spring_stiffness>
        </dynamics>
        <xyz>0 0 1</xyz>
        <limit>
          <lower>-10000000000000000</lower>
          <upper>10000000000000000</upper>
        </limit>
      </axis>
      <physics>
        <ode>
          <limit>
            <cfm>0</cfm>
            <erp>0.20000000000000001</erp>
          </limit>
        </ode>
      </physics>
    </joint>
    <link name='front_caster_link'>
      <pose relative_to='front_caster_joint'>0 0 0 0 -0 0</pose>
      <inertial>
        <pose>0 0 0 0 -0 0</pose>
        <mass>0.01</mass>
        <inertia>
          <ixx>3.9999999999999998e-07</ixx>
          <ixy>0</ixy>
          <ixz>0</ixz>
          <iyy>3.9999999999999998e-07</iyy>
          <iyz>0</iyz>
          <izz>3.9999999999999998e-07</izz>
        </inertia>
      </inertial>
      <collision name='front_caster_link_collision'>
        <pose>0 0 0 0 -0 0</pose>
        <geometry>
          <sphere>
            <radius>0.01</radius>
          </sphere>
        </geometry>
        <surface>
          <contact>
            <ode>
              <kp>1000000</kp>
              <kd>1</kd>
            </ode>
          </contact>
          <friction>
            <ode>
              <mu>0.10000000000000001</mu>
              <mu2>0.10000000000000001</mu2>
            </ode>
          </friction>
        </surface>
      </collision>
      <visual name='front_caster_link_visual'>
        <pose>0 0 0 0 -0 0</pose>
        <geometry>
          <sphere>
            <radius>0.01</radius>
          </sphere>
        </geometry>
        <material>
          <script>
            <name>Gazebo/DarkGrey</name>
            <uri>file://media/materials/scripts/gazebo.material</uri>
          </script>
          <diffuse>0.125 0.125 0.125 1</diffuse>
          <ambient>0.125 0.125 0.125 1</ambient>
        </material>
      </visual>
    </link>
    <joint name='imu_joint' type='fixed'>
      <pose relative_to='base_link'>0.050613 0.043673 0.0844 0 -0 0</pose>
      <parent>base_link</parent>
      <child>imu_link</child>
      <axis>
        <dynamics>
          <spring_reference>0</spring_reference>
          <spring_stiffness>0</spring_stiffness>
        </dynamics>
        <xyz>0 0 1</xyz>
        <limit>
          <lower>-10000000000000000</lower>
          <upper>10000000000000000</upper>
        </limit>
      </axis>
      <physics>
        <ode>
          <limit>
            <cfm>0</cfm>
            <erp>0.20000000000000001</erp>
          </limit>
        </ode>
      </physics>
    </joint>
    <link name='imu_link'>
      <pose relative_to='imu_joint'>0 0 0 0 -0 0</pose>
      <inertial>
        <pose>0 0 0 0 -0 0</pose>
        <mass>0.01</mass>
        <inertia>
          <ixx>1.666666666666667e-07</ixx>
          <ixy>0</ixy>
          <ixz>0</ixz>
          <iyy>1.666666666666667e-07</iyy>
          <iyz>0</iyz>
          <izz>1.666666666666667e-07</izz>
        </inertia>
      </inertial>
      <sensor name='imu' type='imu'>
        <always_on>1</always_on>
        <update_rate>62</update_rate>
        <imu>
          <angular_velocity>
            <x>
              <noise type='gaussian'>
                <mean>0</mean>
                <stddev>0</stddev>
              </noise>
            </x>
            <y>
              <noise type='gaussian'>
                <mean>0</mean>
                <stddev>0</stddev>
              </noise>
            </y>
            <z>
              <noise type='gaussian'>
                <mean>0</mean>
                <stddev>0</stddev>
              </noise>
            </z>
          </angular_velocity>
          <linear_acceleration>
            <x>
              <noise type='gaussian'>
                <mean>0</mean>
                <stddev>0</stddev>
              </noise>
            </x>
            <y>
              <noise type='gaussian'>
                <mean>0</mean>
                <stddev>0</stddev>
              </noise>
            </y>
            <z>
              <noise type='gaussian'>
                <mean>0</mean>
                <stddev>0</stddev>
              </noise>
            </z>
          </linear_acceleration>
        </imu>
        <plugin name='imu_plugin' filename='libgazebo_ros_create_imu.so'>
          <ros>
            <namespace>/</namespace>
            <remapping>~/out:=imu</remapping>
          </ros>
        </plugin>
      </sensor>
    </link>
    <joint name='ir_intensity_front_center_left_joint' type='fixed'>
      <pose relative_to='base_link'>0.154 0 0.0572 0 -0 0</pose>
      <parent>base_link</parent>
      <child>ir_intensity_front_center_left</child>
      <axis>
        <dynamics>
          <spring_reference>0</spring_reference>
          <spring_stiffness>0</spring_stiffness>
        </dynamics>
        <xyz>0 0 1</xyz>
        <limit>
          <lower>-10000000000000000</lower>
          <upper>10000000000000000</upper>
        </limit>
      </axis>
      <physics>
        <ode>
          <limit>
            <cfm>0</cfm>
            <erp>0.20000000000000001</erp>
          </limit>
        </ode>
      </physics>
    </joint>
    <link name='ir_intensity_front_center_left'>
      <pose relative_to='ir_intensity_front_center_left_joint'>0 0 0 0 -0 0</pose>
      <inertial>
        <pose>0 0 0 0 -0 0</pose>
        <mass>0.01</mass>
        <inertia>
          <ixx>1.666666666666667e-07</ixx>
          <ixy>0</ixy>
          <ixz>0</ixz>
          <iyy>1.666666666666667e-07</iyy>
          <iyz>0</iyz>
          <izz>1.666666666666667e-07</izz>
        </inertia>
      </inertial>
      <sensor name='ir_intensity_front_center_left' type='ray'>
        <update_rate>62</update_rate>
        <visualize>0</visualize>
        <always_on>1</always_on>
        <ray>
          <scan>
            <horizontal>
              <samples>5</samples>
              <resolution>1</resolution>
              <min_angle>-0.087266462599716474</min_angle>
              <max_angle>0.087266462599716474</max_angle>
            </horizontal>
            <vertical>
              <samples>5</samples>
              <resolution>1</resolution>
              <min_angle>-0.087266462599716474</min_angle>
              <max_angle>0.087266462599716474</max_angle>
            </vertical>
          </scan>
          <range>
            <min>0.025000000000000001</min>
            <max>0.20000000000000001</max>
            <resolution>1</resolution>
          </range>
        </ray>
        <plugin name='ir_intensity_front_center_left' filename='libgazebo_ros_create_ir_intensity_sensor.so'>
          <ros>
            <namespace>/</namespace>
            <remapping>~/out:=_internal/ir_intensity_front_center_left</remapping>
          </ros>
        </plugin>
        <noise>
          <type>gaussian</type>
          <mean>0.0</mean>
          <stddev>0.0</stddev>
        </noise>
      </sensor>
    </link>
    <joint name='ir_intensity_front_center_right_joint' type='fixed'>
      <pose relative_to='base_link'>0.1396 -0.0651 0.0572 0 0 -0.436</pose>
      <parent>base_link</parent>
      <child>ir_intensity_front_center_right</child>
      <axis>
        <dynamics>
          <spring_reference>0</spring_reference>
          <spring_stiffness>0</spring_stiffness>
        </dynamics>
        <xyz>0 0 1</xyz>
        <limit>
          <lower>-10000000000000000</lower>
          <upper>10000000000000000</upper>
        </limit>
      </axis>
      <physics>
        <ode>
          <limit>
            <cfm>0</cfm>
            <erp>0.20000000000000001</erp>
          </limit>
        </ode>
      </physics>
    </joint>
    <link name='ir_intensity_front_center_right'>
      <pose relative_to='ir_intensity_front_center_right_joint'>0 0 0 0 -0 0</pose>
      <inertial>
        <pose>0 0 0 0 -0 0</pose>
        <mass>0.01</mass>
        <inertia>
          <ixx>1.666666666666667e-07</ixx>
          <ixy>0</ixy>
          <ixz>0</ixz>
          <iyy>1.666666666666667e-07</iyy>
          <iyz>0</iyz>
          <izz>1.666666666666667e-07</izz>
        </inertia>
      </inertial>
      <sensor name='ir_intensity_front_center_right' type='ray'>
        <update_rate>62</update_rate>
        <visualize>0</visualize>
        <always_on>1</always_on>
        <ray>
          <scan>
            <horizontal>
              <samples>5</samples>
              <resolution>1</resolution>
              <min_angle>-0.087266462599716474</min_angle>
              <max_angle>0.087266462599716474</max_angle>
            </horizontal>
            <vertical>
              <samples>5</samples>
              <resolution>1</resolution>
              <min_angle>-0.087266462599716474</min_angle>
              <max_angle>0.087266462599716474</max_angle>
            </vertical>
          </scan>
          <range>
            <min>0.025000000000000001</min>
            <max>0.20000000000000001</max>
            <resolution>1</resolution>
          </range>
        </ray>
        <plugin name='ir_intensity_front_center_right' filename='libgazebo_ros_create_ir_intensity_sensor.so'>
          <ros>
            <namespace>/</namespace>
            <remapping>~/out:=_internal/ir_intensity_front_center_right</remapping>
          </ros>
        </plugin>
        <noise>
          <type>gaussian</type>
          <mean>0.0</mean>
          <stddev>0.0</stddev>
        </noise>
      </sensor>
    </link>
    <joint name='ir_intensity_front_left_joint' type='fixed'>
      <pose relative_to='base_link'>0.1396 0.0651 0.0572 0 -0 0.436</pose>
      <parent>base_link</parent>
      <child>ir_intensity_front_left</child>
      <axis>
        <dynamics>
          <spring_reference>0</spring_reference>
          <spring_stiffness>0</spring_stiffness>
        </dynamics>
        <xyz>0 0 1</xyz>
        <limit>
          <lower>-10000000000000000</lower>
          <upper>10000000000000000</upper>
        </limit>
      </axis>
      <physics>
        <ode>
          <limit>
            <cfm>0</cfm>
            <erp>0.20000000000000001</erp>
          </limit>
        </ode>
      </physics>
    </joint>
    <link name='ir_intensity_front_left'>
      <pose relative_to='ir_intensity_front_left_joint'>0 0 0 0 -0 0</pose>
      <inertial>
        <pose>0 0 0 0 -0 0</pose>
        <mass>0.01</mass>
        <inertia>
          <ixx>1.666666666666667e-07</ixx>
          <ixy>0</ixy>
          <ixz>0</ixz>
          <iyy>1.666666666666667e-07</iyy>
          <iyz>0</iyz>
          <izz>1.666666666666667e-07</izz>
        </inertia>
      </inertial>
      <sensor name='ir_intensity_front_left' type='ray'>
        <update_rate>62</update_rate>
        <visualize>0</visualize>
        <always_on>1</always_on>
        <ray>
          <scan>
            <horizontal>
              <samples>5</samples>
              <resolution>1</resolution>
              <min_angle>-0.087266462599716474</min_angle>
              <max_angle>0.087266462599716474</max_angle>
            </horizontal>
            <vertical>
              <samples>5</samples>
              <resolution>1</resolution>
              <min_angle>-0.087266462599716474</min_angle>
              <max_angle>0.087266462599716474</max_angle>
            </vertical>
          </scan>
          <range>
            <min>0.025000000000000001</min>
            <max>0.20000000000000001</max>
            <resolution>1</resolution>
          </range>
        </ray>
        <plugin name='ir_intensity_front_left' filename='libgazebo_ros_create_ir_intensity_sensor.so'>
          <ros>
            <namespace>/</namespace>
            <remapping>~/out:=_internal/ir_intensity_front_left</remapping>
          </ros>
        </plugin>
        <noise>
          <type>gaussian</type>
          <mean>0.0</mean>
          <stddev>0.0</stddev>
        </noise>
      </sensor>
    </link>
    <joint name='ir_intensity_front_right_joint' type='fixed'>
      <pose relative_to='base_link'>0.099 -0.118 0.0572 0 0 -0.873</pose>
      <parent>base_link</parent>
      <child>ir_intensity_front_right</child>
      <axis>
        <dynamics>
          <spring_reference>0</spring_reference>
          <spring_stiffness>0</spring_stiffness>
        </dynamics>
        <xyz>0 0 1</xyz>
        <limit>
          <lower>-10000000000000000</lower>
          <upper>10000000000000000</upper>
        </limit>
      </axis>
      <physics>
        <ode>
          <limit>
            <cfm>0</cfm>
            <erp>0.20000000000000001</erp>
          </limit>
        </ode>
      </physics>
    </joint>
    <link name='ir_intensity_front_right'>
      <pose relative_to='ir_intensity_front_right_joint'>0 0 0 0 -0 0</pose>
      <inertial>
        <pose>0 0 0 0 -0 0</pose>
        <mass>0.01</mass>
        <inertia>
          <ixx>1.666666666666667e-07</ixx>
          <ixy>0</ixy>
          <ixz>0</ixz>
          <iyy>1.666666666666667e-07</iyy>
          <iyz>0</iyz>
          <izz>1.666666666666667e-07</izz>
        </inertia>
      </inertial>
      <sensor name='ir_intensity_front_right' type='ray'>
        <update_rate>62</update_rate>
        <visualize>0</visualize>
        <always_on>1</always_on>
        <ray>
          <scan>
            <horizontal>
              <samples>5</samples>
              <resolution>1</resolution>
              <min_angle>-0.087266462599716474</min_angle>
              <max_angle>0.087266462599716474</max_angle>
            </horizontal>
            <vertical>
              <samples>5</samples>
              <resolution>1</resolution>
              <min_angle>-0.087266462599716474</min_angle>
              <max_angle>0.087266462599716474</max_angle>
            </vertical>
          </scan>
          <range>
            <min>0.025000000000000001</min>
            <max>0.20000000000000001</max>
            <resolution>1</resolution>
          </range>
        </ray>
        <plugin name='ir_intensity_front_right' filename='libgazebo_ros_create_ir_intensity_sensor.so'>
          <ros>
            <namespace>/</namespace>
            <remapping>~/out:=_internal/ir_intensity_front_right</remapping>
          </ros>
        </plugin>
        <noise>
          <type>gaussian</type>
          <mean>0.0</mean>
          <stddev>0.0</stddev>
        </noise>
      </sensor>
    </link>
    <joint name='ir_intensity_left_joint' type='fixed'>
      <pose relative_to='base_link'>0.099 0.118 0.0572 0 -0 0.873</pose>
      <parent>base_link</parent>
      <child>ir_intensity_left</child>
      <axis>
        <dynamics>
          <spring_reference>0</spring_reference>
          <spring_stiffness>0</spring_stiffness>
        </dynamics>
        <xyz>0 0 1</xyz>
        <limit>
          <lower>-10000000000000000</lower>
          <upper>10000000000000000</upper>
        </limit>
      </axis>
      <physics>
        <ode>
          <limit>
            <cfm>0</cfm>
            <erp>0.20000000000000001</erp>
          </limit>
        </ode>
      </physics>
    </joint>
    <link name='ir_intensity_left'>
      <pose relative_to='ir_intensity_left_joint'>0 0 0 0 -0 0</pose>
      <inertial>
        <pose>0 0 0 0 -0 0</pose>
        <mass>0.01</mass>
        <inertia>
          <ixx>1.666666666666667e-07</ixx>
          <ixy>0</ixy>
          <ixz>0</ixz>
          <iyy>1.666666666666667e-07</iyy>
          <iyz>0</iyz>
          <izz>1.666666666666667e-07</izz>
        </inertia>
      </inertial>
      <sensor name='ir_intensity_left' type='ray'>
        <update_rate>62</update_rate>
        <visualize>0</visualize>
        <always_on>1</always_on>
        <ray>
          <scan>
            <horizontal>
              <samples>5</samples>
              <resolution>1</resolution>
              <min_angle>-0.087266462599716474</min_angle>
              <max_angle>0.087266462599716474</max_angle>
            </horizontal>
            <vertical>
              <samples>5</samples>
              <resolution>1</resolution>
              <min_angle>-0.087266462599716474</min_angle>
              <max_angle>0.087266462599716474</max_angle>
            </vertical>
          </scan>
          <range>
            <min>0.025000000000000001</min>
            <max>0.20000000000000001</max>
            <resolution>1</resolution>
          </range>
        </ray>
        <plugin name='ir_intensity_left' filename='libgazebo_ros_create_ir_intensity_sensor.so'>
          <ros>
            <namespace>/</namespace>
            <remapping>~/out:=_internal/ir_intensity_left</remapping>
          </ros>
        </plugin>
        <noise>
          <type>gaussian</type>
          <mean>0.0</mean>
          <stddev>0.0</stddev>
        </noise>
      </sensor>
    </link>
    <joint name='ir_intensity_right_joint' type='fixed'>
      <pose relative_to='base_link'>0.0399 -0.1488 0.0572 0 0 -1.309</pose>
      <parent>base_link</parent>
      <child>ir_intensity_right</child>
      <axis>
        <dynamics>
          <spring_reference>0</spring_reference>
          <spring_stiffness>0</spring_stiffness>
        </dynamics>
        <xyz>0 0 1</xyz>
        <limit>
          <lower>-10000000000000000</lower>
          <upper>10000000000000000</upper>
        </limit>
      </axis>
      <physics>
        <ode>
          <limit>
            <cfm>0</cfm>
            <erp>0.20000000000000001</erp>
          </limit>
        </ode>
      </physics>
    </joint>
    <link name='ir_intensity_right'>
      <pose relative_to='ir_intensity_right_joint'>0 0 0 0 -0 0</pose>
      <inertial>
        <pose>0 0 0 0 -0 0</pose>
        <mass>0.01</mass>
        <inertia>
          <ixx>1.666666666666667e-07</ixx>
          <ixy>0</ixy>
          <ixz>0</ixz>
          <iyy>1.666666666666667e-07</iyy>
          <iyz>0</iyz>
          <izz>1.666666666666667e-07</izz>
        </inertia>
      </inertial>
      <sensor name='ir_intensity_right' type='ray'>
        <update_rate>62</update_rate>
        <visualize>0</visualize>
        <always_on>1</always_on>
        <ray>
          <scan>
            <horizontal>
              <samples>5</samples>
              <resolution>1</resolution>
              <min_angle>-0.087266462599716474</min_angle>
              <max_angle>0.087266462599716474</max_angle>
            </horizontal>
            <vertical>
              <samples>5</samples>
              <resolution>1</resolution>
              <min_angle>-0.087266462599716474</min_angle>
              <max_angle>0.087266462599716474</max_angle>
            </vertical>
          </scan>
          <range>
            <min>0.025000000000000001</min>
            <max>0.20000000000000001</max>
            <resolution>1</resolution>
          </range>
        </ray>
        <plugin name='ir_intensity_right' filename='libgazebo_ros_create_ir_intensity_sensor.so'>
          <ros>
            <namespace>/</namespace>
            <remapping>~/out:=_internal/ir_intensity_right</remapping>
          </ros>
        </plugin>
        <noise>
          <type>gaussian</type>
          <mean>0.0</mean>
          <stddev>0.0</stddev>
        </noise>
      </sensor>
    </link>
    <joint name='ir_intensity_side_left_joint' type='fixed'>
      <pose relative_to='base_link'>0.0399 0.1488 0.0572 0 -0 1.309</pose>
      <parent>base_link</parent>
      <child>ir_intensity_side_left</child>
      <axis>
        <dynamics>
          <spring_reference>0</spring_reference>
          <spring_stiffness>0</spring_stiffness>
        </dynamics>
        <xyz>0 0 1</xyz>
        <limit>
          <lower>-10000000000000000</lower>
          <upper>10000000000000000</upper>
        </limit>
      </axis>
      <physics>
        <ode>
          <limit>
            <cfm>0</cfm>
            <erp>0.20000000000000001</erp>
          </limit>
        </ode>
      </physics>
    </joint>
    <link name='ir_intensity_side_left'>
      <pose relative_to='ir_intensity_side_left_joint'>0 0 0 0 -0 0</pose>
      <inertial>
        <pose>0 0 0 0 -0 0</pose>
        <mass>0.01</mass>
        <inertia>
          <ixx>1.666666666666667e-07</ixx>
          <ixy>0</ixy>
          <ixz>0</ixz>
          <iyy>1.666666666666667e-07</iyy>
          <iyz>0</iyz>
          <izz>1.666666666666667e-07</izz>
        </inertia>
      </inertial>
      <sensor name='ir_intensity_side_left' type='ray'>
        <update_rate>62</update_rate>
        <visualize>0</visualize>
        <always_on>1</always_on>
        <ray>
          <scan>
            <horizontal>
              <samples>5</samples>
              <resolution>1</resolution>
              <min_angle>-0.087266462599716474</min_angle>
              <max_angle>0.087266462599716474</max_angle>
            </horizontal>
            <vertical>
              <samples>5</samples>
              <resolution>1</resolution>
              <min_angle>-0.087266462599716474</min_angle>
              <max_angle>0.087266462599716474</max_angle>
            </vertical>
          </scan>
          <range>
            <min>0.025000000000000001</min>
            <max>0.20000000000000001</max>
            <resolution>1</resolution>
          </range>
        </ray>
        <plugin name='ir_intensity_side_left' filename='libgazebo_ros_create_ir_intensity_sensor.so'>
          <ros>
            <namespace>/</namespace>
            <remapping>~/out:=_internal/ir_intensity_side_left</remapping>
          </ros>
        </plugin>
        <noise>
          <type>gaussian</type>
          <mean>0.0</mean>
          <stddev>0.0</stddev>
        </noise>
      </sensor>
    </link>
    <joint name='ir_omni_joint' type='fixed'>
      <pose relative_to='base_link'>0.153 0 0.0992 0 -0 0</pose>
      <parent>base_link</parent>
      <child>ir_omni</child>
      <axis>
        <dynamics>
          <spring_reference>0</spring_reference>
          <spring_stiffness>0</spring_stiffness>
        </dynamics>
        <xyz>0 0 1</xyz>
        <limit>
          <lower>-10000000000000000</lower>
          <upper>10000000000000000</upper>
        </limit>
      </axis>
      <physics>
        <ode>
          <limit>
            <cfm>0</cfm>
            <erp>0.20000000000000001</erp>
          </limit>
        </ode>
      </physics>
    </joint>
    <link name='ir_omni'>
      <pose relative_to='ir_omni_joint'>0 0 0 0 -0 0</pose>
      <inertial>
        <pose>0 0 0 0 -0 0</pose>
        <mass>0.01</mass>
        <inertia>
          <ixx>1.666666666666667e-07</ixx>
          <ixy>0</ixy>
          <ixz>0</ixz>
          <iyy>1.666666666666667e-07</iyy>
          <iyz>0</iyz>
          <izz>1.666666666666667e-07</izz>
        </inertia>
      </inertial>
    </link>
    <joint name='lss_arm_joint1' type='revolute'>
      <pose relative_to='base_link'>0.063 0 0.2427 1.5708 -0 0</pose>
      <parent>base_link</parent>
      <child>lss_arm_link_1</child>
      <axis>
        <xyz>0 1 0</xyz>
        <limit>
          <lower>-3.1415926535897931</lower>
          <upper>3.1415926535897931</upper>
          <effort>6.5687857000000003</effort>
          <velocity>6.2830000000000004</velocity>
        </limit>
        <dynamics>
          <damping>0.01</damping>
          <friction>3.48</friction>
          <spring_reference>0</spring_reference>
          <spring_stiffness>0</spring_stiffness>
        </dynamics>
      </axis>
      <physics>
        <ode>
          <limit>
            <cfm>0</cfm>
            <erp>0.20000000000000001</erp>
          </limit>
        </ode>
      </physics>
    </joint>
    <link name='lss_arm_link_1'>
      <pose relative_to='lss_arm_joint1'>0 0 0 0 -0 0</pose>
      <inertial>
        <pose>0 0.034805 0.00015 0 -0 0</pose>
        <mass>0.062887576347183394</mass>
        <inertia>
          <ixx>2.20425725995968e-05</ixx>
          <ixy>9.1993511245884802e-11</ixy>
          <ixz>1.70368679861891e-13</ixz>
          <iyy>2.2948590897456299e-05</iyy>
          <iyz>-2.19524118186986e-07</iyz>
          <izz>1.89578527653699e-05</izz>
        </inertia>
      </inertial>
      <collision name='lss_arm_link_1_collision'>
        <pose>0 0 0 0 -0 0</pose>
        <geometry>
          <mesh>
            <scale>1 1 1</scale>
            <uri>meshes/collision/link_1.STL</uri>
          </mesh>
        </geometry>
        <surface>
          <contact>
            <ode/>
          </contact>
          <friction>
            <ode>
              <mu>0.29999999999999999</mu>
              <mu2>0.29999999999999999</mu2>
            </ode>
          </friction>
        </surface>
      </collision>
      <visual name='lss_arm_link_1_visual'>
        <pose>0 0 0 0 -0 0</pose>
        <geometry>
          <mesh>
            <scale>1 1 1</scale>
            <uri>meshes/visual/link_1.STL</uri>
          </mesh>
        </geometry>
        <material>
          <diffuse>0.375 0.375 0.375 1</diffuse>
          <ambient>0.375 0.375 0.375 1</ambient>
        </material>
      </visual>
    </link>
    <joint name='lss_arm_joint2' type='revolute'>
      <pose relative_to='lss_arm_link_1'>0 0.0588 0 0 0 -1.36211</pose>
      <parent>lss_arm_link_1</parent>
      <child>lss_arm_link_2</child>
      <axis>
        <xyz>0 0 1</xyz>
        <limit>
          <lower>-1.570796326794897</lower>
          <upper>1.570796326794897</upper>
          <effort>6.5687857000000003</effort>
          <velocity>6.2830000000000004</velocity>
        </limit>
        <dynamics>
          <damping>0.01</damping>
          <friction>3.48</friction>
          <spring_reference>0</spring_reference>
          <spring_stiffness>0</spring_stiffness>
        </dynamics>
      </axis>
      <physics>
        <ode>
          <limit>
            <cfm>0</cfm>
            <erp>0.20000000000000001</erp>
          </limit>
        </ode>
      </physics>
    </joint>
    <link name='lss_arm_link_2'>
      <pose relative_to='lss_arm_joint2'>0 0 0 0 -0 0</pose>
      <inertial>
        <pose>-0.112045 0.033642 0.000234 0 -0 0</pose>
        <mass>0.059220729789014201</mass>
        <inertia>
          <ixx>1.6633399872544299e-05</ixx>
          <ixy>-1.03352394963547e-06</ixy>
          <ixz>-4.4327410811638599e-08</ixz>
          <iyy>1.1971383214162999e-05</iyy>
          <iyz>-2.15005479062966e-07</iyz>
          <izz>1.41577057658295e-05</izz>
        </inertia>
      </inertial>
      <collision name='lss_arm_link_2_collision'>
        <pose>0 0 0 0 -0 0</pose>
        <geometry>
          <mesh>
            <scale>1 1 1</scale>
            <uri>meshes/collision/link_2.STL</uri>
          </mesh>
        </geometry>
        <surface>
          <contact>
            <ode/>
          </contact>
          <friction>
            <ode>
              <mu>0.29999999999999999</mu>
              <mu2>0.29999999999999999</mu2>
            </ode>
          </friction>
        </surface>
      </collision>
      <visual name='lss_arm_link_2_visual'>
        <pose>0 0 0 0 -0 0</pose>
        <geometry>
          <mesh>
            <scale>1 1 1</scale>
            <uri>meshes/visual/link_2.STL</uri>
          </mesh>
        </geometry>
        <material>
          <diffuse>0.375 0.375 0.375 1</diffuse>
          <ambient>0.375 0.375 0.375 1</ambient>
        </material>
      </visual>
    </link>
    <joint name='lss_arm_joint3' type='revolute'>
      <pose relative_to='lss_arm_link_2'>-0.129548 0.053398 0 0 -0 1.02985</pose>
      <parent>lss_arm_link_2</parent>
      <child>lss_arm_link_3</child>
      <axis>
        <xyz>0 0 1</xyz>
        <limit>
          <lower>-1.570796326794897</lower>
          <upper>1.570796326794897</upper>
          <effort>6.5687857000000003</effort>
          <velocity>6.2830000000000004</velocity>
        </limit>
        <dynamics>
          <damping>0.01</damping>
          <friction>3.48</friction>
          <spring_reference>0</spring_reference>
          <spring_stiffness>0</spring_stiffness>
        </dynamics>
      </axis>
      <physics>
        <ode>
          <limit>
            <cfm>0</cfm>
            <erp>0.20000000000000001</erp>
          </limit>
        </ode>
      </physics>
    </joint>
    <link name='lss_arm_link_3'>
      <pose relative_to='lss_arm_joint3'>0 0 0 0 -0 0</pose>
      <inertial>
        <pose>0.119623 0.041151 0.000345 0 -0 0</pose>
        <mass>0.060149035312470803</mass>
        <inertia>
          <ixx>1.1113660383281e-05</ixx>
          <ixy>-2.6746693260721798e-06</ixy>
          <ixz>2.0160569864272201e-07</ixz>
          <iyy>1.7941964943423101e-05</iyy>
          <iyz>-6.9564477599757001e-08</iyz>
          <izz>1.4580709936660301e-05</izz>
        </inertia>
      </inertial>
      <collision name='lss_arm_link_3_collision'>
        <pose>0 0 0 0 -0 0</pose>
        <geometry>
          <mesh>
            <scale>1 1 1</scale>
            <uri>meshes/collision/link_3.STL</uri>
          </mesh>
        </geometry>
        <surface>
          <contact>
            <ode/>
          </contact>
          <friction>
            <ode>
              <mu>0.29999999999999999</mu>
              <mu2>0.29999999999999999</mu2>
            </ode>
          </friction>
        </surface>
      </collision>
      <visual name='lss_arm_link_3_visual'>
        <pose>0 0 0 0 -0 0</pose>
        <geometry>
          <mesh>
            <scale>1 1 1</scale>
            <uri>meshes/visual/link_3.STL</uri>
          </mesh>
        </geometry>
        <material>
          <diffuse>0.375 0.375 0.375 1</diffuse>
          <ambient>0.375 0.375 0.375 1</ambient>
        </material>
      </visual>
    </link>
    <joint name='lss_arm_joint4' type='revolute'>
      <pose relative_to='lss_arm_link_3'>0.154274 0.053233 0 0 -0 0.33226</pose>
      <parent>lss_arm_link_3</parent>
      <child>lss_arm_link_4</child>
      <axis>
        <xyz>0 0 1</xyz>
        <limit>
          <lower>-1.570796326794897</lower>
          <upper>1.570796326794897</upper>
          <effort>6.5687857000000003</effort>
          <velocity>6.2830000000000004</velocity>
        </limit>
        <dynamics>
          <damping>0.01</damping>
          <friction>3.48</friction>
          <spring_reference>0</spring_reference>
          <spring_stiffness>0</spring_stiffness>
        </dynamics>
      </axis>
      <physics>
        <ode>
          <limit>
            <cfm>0</cfm>
            <erp>0.20000000000000001</erp>
          </limit>
        </ode>
      </physics>
    </joint>
    <link name='lss_arm_link_4'>
      <pose relative_to='lss_arm_joint4'>0 0 0 0 -0 0</pose>
      <inertial>
        <pose>0.044689 -0.000131 0.000356 0 -0 0</pose>
        <mass>0.0556319659037934</mass>
        <inertia>
          <ixx>1.8133774910878799e-05</ixx>
          <ixy>-6.9951384690848697e-14</ixy>
          <ixz>9.1994103666448402e-11</ixz>
          <iyy>1.49173144124065e-05</iyy>
          <iyz>2.14447838213905e-07</iyz>
          <izz>9.1279672834269492e-06</izz>
        </inertia>
      </inertial>
      <collision name='lss_arm_link_4_collision'>
        <pose>0 0 0 0 -0 0</pose>
        <geometry>
          <mesh>
            <scale>1 1 1</scale>
            <uri>meshes/collision/link_4.STL</uri>
          </mesh>
        </geometry>
        <surface>
          <contact>
            <ode/>
          </contact>
          <friction>
            <ode>
              <mu>0.29999999999999999</mu>
              <mu2>0.29999999999999999</mu2>
            </ode>
          </friction>
        </surface>
      </collision>
      <visual name='lss_arm_link_4_visual'>
        <pose>0 0 0 0 -0 0</pose>
        <geometry>
          <mesh>
            <scale>1 1 1</scale>
            <uri>meshes/visual/link_4.STL</uri>
          </mesh>
        </geometry>
        <material>
          <diffuse>0.375 0.375 0.375 1</diffuse>
          <ambient>0.375 0.375 0.375 1</ambient>
        </material>
      </visual>
    </link>
    <joint name='lss_arm_gripper_l' type='revolute'>
      <pose relative_to='lss_arm_link_4'>0.0508 -0.002739 0.013 0 -0 0</pose>
      <parent>lss_arm_link_4</parent>
      <child>lss_arm_end_effector_l</child>
      <axis>
        <xyz>0 1 0</xyz>
        <limit>
          <lower>-1.570796326794897</lower>
          <upper>0</upper>
          <effort>6.5687857000000003</effort>
          <velocity>6.2830000000000004</velocity>
        </limit>
        <dynamics>
          <damping>0.01</damping>
          <friction>0.40000000000000002</friction>
          <spring_reference>0</spring_reference>
          <spring_stiffness>0</spring_stiffness>
        </dynamics>
      </axis>
      <physics>
        <ode>
          <limit>
            <cfm>0</cfm>
            <erp>0.20000000000000001</erp>
          </limit>
        </ode>
      </physics>
    </joint>
    <link name='lss_arm_end_effector_l'>
      <pose relative_to='lss_arm_gripper_l'>0 0 0 0 -0 0</pose>
      <inertial>
        <pose>0.030773 -0.014098 -0.001327 0 -0 0</pose>
        <mass>0.0154295568992377</mass>
        <inertia>
          <ixx>6.1324288588371195e-07</ixx>
          <ixy>-1.69555790218149e-12</ixy>
          <ixz>4.4162176460178102e-07</ixz>
          <iyy>2.99899721506146e-06</iyy>
          <iyz>4.0934388850918597e-12</iyz>
          <izz>2.5471565367428799e-06</izz>
        </inertia>
      </inertial>
      <collision name='lss_arm_end_effector_l_collision'>
        <pose>0 0 0 0 -0 0</pose>
        <geometry>
          <mesh>
            <scale>1 1 1</scale>
            <uri>meshes/collision/end_effector_l.STL</uri>
          </mesh>
        </geometry>
        <surface>
          <contact>
            <ode/>
          </contact>
          <friction>
            <ode>
              <mu>0.29999999999999999</mu>
              <mu2>0.29999999999999999</mu2>
            </ode>
          </friction>
        </surface>
      </collision>
      <visual name='lss_arm_end_effector_l_visual'>
        <pose>0 0 0 0 -0 0</pose>
        <geometry>
          <mesh>
            <scale>1 1 1</scale>
            <uri>meshes/visual/end_effector_l.STL</uri>
          </mesh>
        </geometry>
        <material>
          <diffuse>0.375 0.375 0.375 1</diffuse>
          <ambient>0.375 0.375 0.375 1</ambient>
        </material>
      </visual>
    </link>
    <joint name='lss_arm_gripper_r' type='revolute'>
      <pose relative_to='lss_arm_link_4'>0.0508 -0.002739 -0.0124 0 -0 0</pose>
      <parent>lss_arm_link_4</parent>
      <child>lss_arm_end_effector_r</child>
      <axis>
        <xyz>0 1 0</xyz>
        <limit>
          <lower>0</lower>
          <upper>1.570796326794897</upper>
          <effort>6.5687857000000003</effort>
          <velocity>6.2830000000000004</velocity>
        </limit>
        <dynamics>
          <damping>0.01</damping>
          <friction>0.40000000000000002</friction>
          <spring_reference>0</spring_reference>
          <spring_stiffness>0</spring_stiffness>
        </dynamics>
      </axis>
      <physics>
        <ode>
          <limit>
            <cfm>0</cfm>
            <erp>0.20000000000000001</erp>
          </limit>
        </ode>
      </physics>
    </joint>
    <link name='lss_arm_end_effector_r'>
      <pose relative_to='lss_arm_gripper_r'>0 0 0 0 -0 0</pose>
      <inertial>
        <pose>0.031071 -0.014045 0.00134 0 -0 0</pose>
        <mass>0.0152813047822834</mass>
        <inertia>
          <ixx>6.12119941271843e-07</ixx>
          <ixy>-1.6104488931588599e-12</ixy>
          <ixz>-4.4162176335349601e-07</ixz>
          <iyy>2.99804070646807e-06</iyy>
          <iyz>-3.8879675590964998e-12</iyz>
          <izz>2.54603357212087e-06</izz>
        </inertia>
      </inertial>
      <collision name='lss_arm_end_effector_r_collision'>
        <pose>0 0 0 0 -0 0</pose>
        <geometry>
          <mesh>
            <scale>1 1 1</scale>
            <uri>meshes/collision/end_effector_r.STL</uri>
          </mesh>
        </geometry>
        <surface>
          <contact>
            <ode/>
          </contact>
          <friction>
            <ode>
              <mu>0.29999999999999999</mu>
              <mu2>0.29999999999999999</mu2>
            </ode>
          </friction>
        </surface>
      </collision>
      <visual name='lss_arm_end_effector_r_visual'>
        <pose>0 0 0 0 -0 0</pose>
        <geometry>
          <mesh>
            <scale>1 1 1</scale>
            <uri>meshes/visual/end_effector_r.STL</uri>
          </mesh>
        </geometry>
        <material>
          <diffuse>0.375 0.375 0.375 1</diffuse>
          <ambient>0.375 0.375 0.375 1</ambient>
        </material>
      </visual>
    </link>
    <joint name='mouse_joint' type='fixed'>
      <pose relative_to='base_link'>0.1015 0.087 0.0092 0 0 -0.785398</pose>
      <parent>base_link</parent>
      <child>mouse</child>
      <axis>
        <dynamics>
          <spring_reference>0</spring_reference>
          <spring_stiffness>0</spring_stiffness>
        </dynamics>
        <xyz>0 0 1</xyz>
        <limit>
          <lower>-10000000000000000</lower>
          <upper>10000000000000000</upper>
        </limit>
      </axis>
      <physics>
        <ode>
          <limit>
            <cfm>0</cfm>
            <erp>0.20000000000000001</erp>
          </limit>
        </ode>
      </physics>
    </joint>
    <link name='mouse'>
      <pose relative_to='mouse_joint'>0 0 0 0 -0 0</pose>
      <inertial>
        <pose>0 0 0 0 -0 0</pose>
        <mass>0.01</mass>
        <inertia>
          <ixx>1.666666666666667e-07</ixx>
          <ixy>0</ixy>
          <ixz>0</ixz>
          <iyy>1.666666666666667e-07</iyy>
          <iyz>0</iyz>
          <izz>1.666666666666667e-07</izz>
        </inertia>
      </inertial>
    </link>
    <joint name='oakd_lite_camera_bracket_joint' type='fixed'>
      <pose relative_to='base_link'>-0.09 0 0.093348 0 -0 0</pose>
      <parent>base_link</parent>
      <child>oakd_lite_camera_bracket</child>
      <axis>
        <dynamics>
          <spring_reference>0</spring_reference>
          <spring_stiffness>0</spring_stiffness>
        </dynamics>
        <xyz>0 0 1</xyz>
        <limit>
          <lower>-10000000000000000</lower>
          <upper>10000000000000000</upper>
        </limit>
      </axis>
      <physics>
        <ode>
          <limit>
            <cfm>0</cfm>
            <erp>0.20000000000000001</erp>
          </limit>
        </ode>
      </physics>
    </joint>
    <link name='oakd_lite_camera_bracket'>
      <pose relative_to='oakd_lite_camera_bracket_joint'>0 0 0 0 -0 0</pose>
      <inertial>
        <pose>0 0 0 0 -0 0</pose>
        <mass>0.033000000000000002</mass>
        <inertia>
          <ixx>5.7918099999999997e-05</ixx>
          <ixy>0</ixy>
          <ixz>9.0679e-06</ixz>
          <iyy>5.5978499999999999e-05</iyy>
          <iyz>0</iyz>
          <izz>1.4095500000000001e-05</izz>
        </inertia>
      </inertial>
      <visual name='oakd_lite_camera_bracket_visual'>
        <pose>0 0 0 0 -0 0</pose>
        <geometry>
          <mesh>
            <scale>1 1 1</scale>
            <uri>model://turtlebot4_description/meshes/camera_bracket.dae</uri>
          </mesh>
        </geometry>
        <material>
          <diffuse>0 0 0 1</diffuse>
          <specular>0.313726 0.313726 0.313726 1</specular>
          <emissive>0 0 0 1</emissive>
        </material>
      </visual>
    </link>
    <joint name='oakd_lite_joint' type='fixed'>
      <pose relative_to='oakd_lite_camera_bracket'>0.05294 0 0.092539 0 -0 0</pose>
      <parent>oakd_lite_camera_bracket</parent>
      <child>oakd_lite_link</child>
      <axis>
        <dynamics>
          <spring_reference>0</spring_reference>
          <spring_stiffness>0</spring_stiffness>
        </dynamics>
        <xyz>0 0 1</xyz>
        <limit>
          <lower>-10000000000000000</lower>
          <upper>10000000000000000</upper>
        </limit>
      </axis>
      <physics>
        <ode>
          <limit>
            <cfm>0</cfm>
            <erp>0.20000000000000001</erp>
          </limit>
        </ode>
      </physics>
    </joint>
    <link name='oakd_lite_link'>
      <pose relative_to='oakd_lite_joint'>0 0 0 0 -0 0</pose>
      <inertial>
        <pose>0 0 0 0 -0 0</pose>
        <mass>0.060999999999999999</mass>
        <inertia>
          <ixx>2.02475e-06</ixx>
          <ixy>0</ixy>
          <ixz>0</ixz>
          <iyy>1.5273200000000001e-05</iyy>
          <iyz>0</iyz>
          <izz>1.6055359999999999e-05</izz>
        </inertia>
      </inertial>
      <collision name='oakd_lite_link_collision'>
        <pose>-0.011 0 -0.005 0 -0 0</pose>
        <geometry>
          <box>
            <size>0.0225 0.097 0.03</size>
          </box>
        </geometry>
      </collision>
      <visual name='oakd_lite_link_visual'>
        <pose>0 0 0 0 -0 0</pose>
        <geometry>
          <mesh>
            <scale>1 1 1</scale>
            <uri>model://turtlebot4_description/meshes/oakd_lite.dae</uri>
          </mesh>
        </geometry>
      </visual>
    </link>
    <joint name='oakd_lite_imu_joint' type='fixed'>
      <pose relative_to='oakd_lite_link'>0 0 0 -1.5708 -0 -1.5708</pose>
      <parent>oakd_lite_link</parent>
      <child>oakd_lite_imu_frame</child>
      <axis>
        <dynamics>
          <spring_reference>0</spring_reference>
          <spring_stiffness>0</spring_stiffness>
        </dynamics>
        <xyz>0 0 1</xyz>
        <limit>
          <lower>-10000000000000000</lower>
          <upper>10000000000000000</upper>
        </limit>
      </axis>
      <physics>
        <ode>
          <limit>
            <cfm>0</cfm>
            <erp>0.20000000000000001</erp>
          </limit>
        </ode>
      </physics>
    </joint>
    <link name='oakd_lite_imu_frame'>
      <pose relative_to='oakd_lite_imu_joint'>0 0 0 0 -0 0</pose>
      <inertial>
        <pose>0 0 0 0 -0 0</pose>
        <mass>0.01</mass>
        <inertia>
          <ixx>1.666666666666667e-07</ixx>
          <ixy>0</ixy>
          <ixz>0</ixz>
          <iyy>1.666666666666667e-07</iyy>
          <iyz>0</iyz>
          <izz>1.666666666666667e-07</izz>
        </inertia>
      </inertial>
    </link>
    <joint name='oakd_lite_left_camera_joint' type='fixed'>
      <pose relative_to='oakd_lite_link'>0 0.0375 0 0 -0 0</pose>
      <parent>oakd_lite_link</parent>
      <child>oakd_lite_left_camera_frame</child>
      <axis>
        <dynamics>
          <spring_reference>0</spring_reference>
          <spring_stiffness>0</spring_stiffness>
        </dynamics>
        <xyz>0 0 1</xyz>
        <limit>
          <lower>-10000000000000000</lower>
          <upper>10000000000000000</upper>
        </limit>
      </axis>
      <physics>
        <ode>
          <limit>
            <cfm>0</cfm>
            <erp>0.20000000000000001</erp>
          </limit>
        </ode>
      </physics>
    </joint>
    <link name='oakd_lite_left_camera_frame'>
      <pose relative_to='oakd_lite_left_camera_joint'>0 0 0 0 -0 0</pose>
      <inertial>
        <pose>0 0 0 0 -0 0</pose>
        <mass>0.01</mass>
        <inertia>
          <ixx>1.666666666666667e-07</ixx>
          <ixy>0</ixy>
          <ixz>0</ixz>
          <iyy>1.666666666666667e-07</iyy>
          <iyz>0</iyz>
          <izz>1.666666666666667e-07</izz>
        </inertia>
      </inertial>
    </link>
    <joint name='oakd_lite_left_camera_optical_joint' type='fixed'>
      <pose relative_to='oakd_lite_left_camera_frame'>0 0 0 -1.5708 -0 -1.5708</pose>
      <parent>oakd_lite_left_camera_frame</parent>
      <child>oakd_lite_left_camera_optical_frame</child>
      <axis>
        <dynamics>
          <spring_reference>0</spring_reference>
          <spring_stiffness>0</spring_stiffness>
        </dynamics>
        <xyz>0 0 1</xyz>
        <limit>
          <lower>-10000000000000000</lower>
          <upper>10000000000000000</upper>
        </limit>
      </axis>
      <physics>
        <ode>
          <limit>
            <cfm>0</cfm>
            <erp>0.20000000000000001</erp>
          </limit>
        </ode>
      </physics>
    </joint>
    <link name='oakd_lite_left_camera_optical_frame'>
      <pose relative_to='oakd_lite_left_camera_optical_joint'>0 0 0 0 -0 0</pose>
      <inertial>
        <pose>0 0 0 0 -0 0</pose>
        <mass>0.01</mass>
        <inertia>
          <ixx>1.666666666666667e-07</ixx>
          <ixy>0</ixy>
          <ixz>0</ixz>
          <iyy>1.666666666666667e-07</iyy>
          <iyz>0</iyz>
          <izz>1.666666666666667e-07</izz>
        </inertia>
      </inertial>
    </link>
    <joint name='oakd_lite_rgb_camera_joint' type='fixed'>
      <pose relative_to='oakd_lite_link'>0 0 0 0 -0 0</pose>
      <parent>oakd_lite_link</parent>
      <child>oakd_lite_rgb_camera_frame</child>
      <axis>
        <dynamics>
          <spring_reference>0</spring_reference>
          <spring_stiffness>0</spring_stiffness>
        </dynamics>
        <xyz>0 0 1</xyz>
        <limit>
          <lower>-10000000000000000</lower>
          <upper>10000000000000000</upper>
        </limit>
      </axis>
      <physics>
        <ode>
          <limit>
            <cfm>0</cfm>
            <erp>0.20000000000000001</erp>
          </limit>
        </ode>
      </physics>
    </joint>
    <link name='oakd_lite_rgb_camera_frame'>
      <pose relative_to='oakd_lite_rgb_camera_joint'>0 0 0 0 -0 0</pose>
      <inertial>
        <pose>0 0 0 0 -0 0</pose>
        <mass>0.01</mass>
        <inertia>
          <ixx>1.666666666666667e-07</ixx>
          <ixy>0</ixy>
          <ixz>0</ixz>
          <iyy>1.666666666666667e-07</iyy>
          <iyz>0</iyz>
          <izz>1.666666666666667e-07</izz>
        </inertia>
      </inertial>
      <sensor name='rgbd_camera' type='rgbd_camera'>
        <camera>
          <horizontal_fov>1.25</horizontal_fov>
          <image>
            <width>320</width>
            <height>240</height>
          </image>
          <clip>
            <near>0.29999999999999999</near>
            <far>100</far>
          </clip>
        </camera>
        <always_on>1</always_on>
        <update_rate>30</update_rate>
        <visualize>1</visualize>
      </sensor>
    </link>
    <joint name='oakd_lite_rgb_camera_optical_joint' type='fixed'>
      <pose relative_to='oakd_lite_rgb_camera_frame'>0 0 0 -1.5708 -0 -1.5708</pose>
      <parent>oakd_lite_rgb_camera_frame</parent>
      <child>oakd_lite_rgb_camera_optical_frame</child>
      <axis>
        <dynamics>
          <spring_reference>0</spring_reference>
          <spring_stiffness>0</spring_stiffness>
        </dynamics>
        <xyz>0 0 1</xyz>
        <limit>
          <lower>-10000000000000000</lower>
          <upper>10000000000000000</upper>
        </limit>
      </axis>
      <physics>
        <ode>
          <limit>
            <cfm>0</cfm>
            <erp>0.20000000000000001</erp>
          </limit>
        </ode>
      </physics>
    </joint>
    <link name='oakd_lite_rgb_camera_optical_frame'>
      <pose relative_to='oakd_lite_rgb_camera_optical_joint'>0 0 0 0 -0 0</pose>
      <inertial>
        <pose>0 0 0 0 -0 0</pose>
        <mass>0.01</mass>
        <inertia>
          <ixx>1.666666666666667e-07</ixx>
          <ixy>0</ixy>
          <ixz>0</ixz>
          <iyy>1.666666666666667e-07</iyy>
          <iyz>0</iyz>
          <izz>1.666666666666667e-07</izz>
        </inertia>
      </inertial>
    </link>
    <joint name='oakd_lite_right_camera_joint' type='fixed'>
      <pose relative_to='oakd_lite_link'>0 -0.0375 0 0 -0 0</pose>
      <parent>oakd_lite_link</parent>
      <child>oakd_lite_right_camera_frame</child>
      <axis>
        <dynamics>
          <spring_reference>0</spring_reference>
          <spring_stiffness>0</spring_stiffness>
        </dynamics>
        <xyz>0 0 1</xyz>
        <limit>
          <lower>-10000000000000000</lower>
          <upper>10000000000000000</upper>
        </limit>
      </axis>
      <physics>
        <ode>
          <limit>
            <cfm>0</cfm>
            <erp>0.20000000000000001</erp>
          </limit>
        </ode>
      </physics>
    </joint>
    <link name='oakd_lite_right_camera_frame'>
      <pose relative_to='oakd_lite_right_camera_joint'>0 0 0 0 -0 0</pose>
      <inertial>
        <pose>0 0 0 0 -0 0</pose>
        <mass>0.01</mass>
        <inertia>
          <ixx>1.666666666666667e-07</ixx>
          <ixy>0</ixy>
          <ixz>0</ixz>
          <iyy>1.666666666666667e-07</iyy>
          <iyz>0</iyz>
          <izz>1.666666666666667e-07</izz>
        </inertia>
      </inertial>
    </link>
    <joint name='oakd_lite_right_camera_optical_joint' type='fixed'>
      <pose relative_to='oakd_lite_right_camera_frame'>0 0 0 -1.5708 -0 -1.5708</pose>
      <parent>oakd_lite_right_camera_frame</parent>
      <child>oakd_lite_right_camera_optical_frame</child>
      <axis>
        <dynamics>
          <spring_reference>0</spring_reference>
          <spring_stiffness>0</spring_stiffness>
        </dynamics>
        <xyz>0 0 1</xyz>
        <limit>
          <lower>-10000000000000000</lower>
          <upper>10000000000000000</upper>
        </limit>
      </axis>
      <physics>
        <ode>
          <limit>
            <cfm>0</cfm>
            <erp>0.20000000000000001</erp>
          </limit>
        </ode>
      </physics>
    </joint>
    <link name='oakd_lite_right_camera_optical_frame'>
      <pose relative_to='oakd_lite_right_camera_optical_joint'>0 0 0 0 -0 0</pose>
      <inertial>
        <pose>0 0 0 0 -0 0</pose>
        <mass>0.01</mass>
        <inertia>
          <ixx>1.666666666666667e-07</ixx>
          <ixy>0</ixy>
          <ixz>0</ixz>
          <iyy>1.666666666666667e-07</iyy>
          <iyz>0</iyz>
          <izz>1.666666666666667e-07</izz>
        </inertia>
      </inertial>
    </link>
    <joint name='rplidar_joint' type='fixed'>
      <pose relative_to='base_link'>0.003936 0 0.139493 0 -0 1.5708</pose>
      <parent>base_link</parent>
      <child>rplidar_link</child>
      <axis>
        <dynamics>
          <spring_reference>0</spring_reference>
          <spring_stiffness>0</spring_stiffness>
        </dynamics>
        <xyz>0 0 1</xyz>
        <limit>
          <lower>-10000000000000000</lower>
          <upper>10000000000000000</upper>
        </limit>
      </axis>
      <physics>
        <ode>
          <limit>
            <cfm>0</cfm>
            <erp>0.20000000000000001</erp>
          </limit>
        </ode>
      </physics>
    </joint>
    <link name='rplidar_link'>
      <pose relative_to='rplidar_joint'>0 0 0 0 -0 0</pose>
      <inertial>
        <pose>0 0 0 0 -0 0</pose>
        <mass>0.17000000000000001</mass>
        <inertia>
          <ixx>0.0001926666666666667</ixx>
          <ixy>0</ixy>
          <ixz>0</ixz>
          <iyy>0.00012241416666666671</iyy>
          <iyz>0</iyz>
          <izz>0.0002130808333333334</izz>
        </inertia>
      </inertial>
      <collision name='rplidar_link_collision'>
        <pose>0 0.013 -0.019 0 -0 0</pose>
        <geometry>
          <box>
            <size>0.071 0.1 0.06</size>
          </box>
        </geometry>
        <surface>
          <contact>
            <ode/>
          </contact>
          <friction>
            <ode/>
          </friction>
        </surface>
      </collision>
      <visual name='rplidar_link_visual'>
        <pose>0 0 0 0 -0 0</pose>
        <geometry>
          <mesh>
            <scale>1 1 1</scale>
            <uri>model://turtlebot4_description/meshes/rplidar.dae</uri>
          </mesh>
        </geometry>
        <material>
          <diffuse>0.0117647 0.0117647 0.0117647 1</diffuse>
          <specular>0 0 0 1</specular>
          <emissive>0 0 0 1</emissive>
        </material>
      </visual>
      <sensor name='rplidar' type='ray'>
        <update_rate>62</update_rate>
        <visualize>1</visualize>
        <always_on>1</always_on>
        <ray>
          <scan>
            <horizontal>
              <samples>640</samples>
              <resolution>1</resolution>
              <min_angle>-3.1415926535897931</min_angle>
              <max_angle>3.1415926535897931</max_angle>
            </horizontal>
            <vertical>
              <samples>1</samples>
              <resolution>1</resolution>
              <min_angle>0</min_angle>
              <max_angle>0</max_angle>
            </vertical>
          </scan>
          <range>
            <min>0.16400000000000001</min>
            <max>12</max>
            <resolution>0.01</resolution>
          </range>
        </ray>
        <plugin name='dummy' filename='dummyfile'/>
        <noise>
          <type>gaussian</type>
          <mean>0.0</mean>
          <stddev>0.0</stddev>
        </noise>
      </sensor>
    </link>
    <joint name='wheel_drop_left_joint' type='prismatic'>
      <pose relative_to='base_link'>0 0.1165 0.0402 -1.5708 0 0</pose>
      <parent>base_link</parent>
      <child>wheel_drop_left</child>
      <axis>
        <xyz>0 1 0</xyz>
        <limit>
          <lower>0</lower>
          <upper>0.029999999999999999</upper>
          <effort>0</effort>
          <velocity>0</velocity>
        </limit>
        <dynamics>
          <damping>50</damping>
          <friction>0.10000000000000001</friction>
          <spring_reference>0.029999999999999999</spring_reference>
          <spring_stiffness>400</spring_stiffness>
        </dynamics>
      </axis>
      <physics>
        <provide_feedback>0</provide_feedback>
        <ode>
          <implicit_spring_damper>1</implicit_spring_damper>
          <cfm_damping>1</cfm_damping>
          <limit>
            <cfm>0</cfm>
            <erp>0.20000000000000001</erp>
          </limit>
          <provide_feedback>0</provide_feedback>
        </ode>
      </physics>
    </joint>
    <link name='wheel_drop_left'>
      <pose relative_to='wheel_drop_left_joint'>0 0 0 0 -0 0</pose>
      <inertial>
        <pose>0 0 0 0 -0 0</pose>
        <mass>0.050000000000000003</mass>
        <inertia>
          <ixx>2.0833333333333339e-05</ixx>
          <ixy>0</ixy>
          <ixz>0</ixz>
          <iyy>2.0833333333333339e-05</iyy>
          <iyz>0</iyz>
          <izz>2.0833333333333339e-05</izz>
        </inertia>
      </inertial>
    </link>
    <joint name='left_wheel_joint' type='revolute'>
      <pose relative_to='wheel_drop_left'>0 0 0 0 -0 0</pose>
      <parent>wheel_drop_left</parent>
      <child>left_wheel</child>
      <axis>
        <xyz>0 0 1</xyz>
        <limit>
          <lower>-10000000000000000</lower>
          <upper>10000000000000000</upper>
        </limit>
        <dynamics>
          <spring_reference>0</spring_reference>
          <spring_stiffness>0</spring_stiffness>
        </dynamics>
      </axis>
    </joint>
    <link name='left_wheel'>
      <pose relative_to='left_wheel_joint'>0 0 0 0 -0 0</pose>
      <inertial>
        <pose>0 0 0 0 -0 0</pose>
        <mass>0.20000000000000001</mass>
        <inertia>
          <ixx>6.7653125000000013e-05</ixx>
          <ixy>0</ixy>
          <ixz>0</ixz>
          <iyy>6.7653125000000013e-05</iyy>
          <iyz>0</iyz>
          <izz>0.00012780625000000001</izz>
        </inertia>
      </inertial>
      <collision name='left_wheel_collision'>
        <pose>0 0 0 0 -0 0</pose>
        <geometry>
          <cylinder>
            <length>0.014999999999999999</length>
            <radius>0.035749999999999997</radius>
          </cylinder>
        </geometry>
        <surface>
          <contact>
            <ode>
              <kp>1000000</kp>
              <kd>100</kd>
              <max_vel>1</max_vel>
              <min_depth>0.0001</min_depth>
            </ode>
          </contact>
          <friction>
            <ode>
              <mu>1</mu>
              <mu2>1</mu2>
            </ode>
          </friction>
        </surface>
      </collision>
      <visual name='left_wheel_visual'>
        <pose>0 0 0 0 -0 0</pose>
        <geometry>
          <cylinder>
            <length>0.014999999999999999</length>
            <radius>0.035749999999999997</radius>
          </cylinder>
        </geometry>
        <material>
          <script>
            <name>Gazebo/DarkGrey</name>
            <uri>file://media/materials/scripts/gazebo.material</uri>
          </script>
          <diffuse>0.125 0.125 0.125 1</diffuse>
          <ambient>0.125 0.125 0.125 1</ambient>
        </material>
      </visual>
    </link>
    <joint name='wheel_drop_right_joint' type='prismatic'>
      <pose relative_to='base_link'>0 -0.1165 0.0402 -1.5708 0 0</pose>
      <parent>base_link</parent>
      <child>wheel_drop_right</child>
      <axis>
        <xyz>0 1 0</xyz>
        <limit>
          <lower>0</lower>
          <upper>0.029999999999999999</upper>
          <effort>0</effort>
          <velocity>0</velocity>
        </limit>
        <dynamics>
          <damping>50</damping>
          <friction>0.10000000000000001</friction>
          <spring_reference>0.029999999999999999</spring_reference>
          <spring_stiffness>400</spring_stiffness>
        </dynamics>
      </axis>
      <physics>
        <provide_feedback>0</provide_feedback>
        <ode>
          <implicit_spring_damper>1</implicit_spring_damper>
          <cfm_damping>1</cfm_damping>
          <limit>
            <cfm>0</cfm>
            <erp>0.20000000000000001</erp>
          </limit>
          <provide_feedback>0</provide_feedback>
        </ode>
      </physics>
    </joint>
    <link name='wheel_drop_right'>
      <pose relative_to='wheel_drop_right_joint'>0 0 0 0 -0 0</pose>
      <inertial>
        <pose>0 0 0 0 -0 0</pose>
        <mass>0.050000000000000003</mass>
        <inertia>
          <ixx>2.0833333333333339e-05</ixx>
          <ixy>0</ixy>
          <ixz>0</ixz>
          <iyy>2.0833333333333339e-05</iyy>
          <iyz>0</iyz>
          <izz>2.0833333333333339e-05</izz>
        </inertia>
      </inertial>
    </link>
    <joint name='right_wheel_joint' type='revolute'>
      <pose relative_to='wheel_drop_right'>0 0 0 0 -0 0</pose>
      <parent>wheel_drop_right</parent>
      <child>right_wheel</child>
      <axis>
        <xyz>0 0 1</xyz>
        <limit>
          <lower>-10000000000000000</lower>
          <upper>10000000000000000</upper>
        </limit>
        <dynamics>
          <spring_reference>0</spring_reference>
          <spring_stiffness>0</spring_stiffness>
        </dynamics>
      </axis>
    </joint>
    <link name='right_wheel'>
      <pose relative_to='right_wheel_joint'>0 0 0 0 -0 0</pose>
      <inertial>
        <pose>0 0 0 0 -0 0</pose>
        <mass>0.20000000000000001</mass>
        <inertia>
          <ixx>6.7653125000000013e-05</ixx>
          <ixy>0</ixy>
          <ixz>0</ixz>
          <iyy>6.7653125000000013e-05</iyy>
          <iyz>0</iyz>
          <izz>0.00012780625000000001</izz>
        </inertia>
      </inertial>
      <collision name='right_wheel_collision'>
        <pose>0 0 0 0 -0 0</pose>
        <geometry>
          <cylinder>
            <length>0.014999999999999999</length>
            <radius>0.035749999999999997</radius>
          </cylinder>
        </geometry>
        <surface>
          <contact>
            <ode>
              <kp>1000000</kp>
              <kd>100</kd>
              <max_vel>1</max_vel>
              <min_depth>0.0001</min_depth>
            </ode>
          </contact>
          <friction>
            <ode>
              <mu>1</mu>
              <mu2>1</mu2>
            </ode>
          </friction>
        </surface>
      </collision>
      <visual name='right_wheel_visual'>
        <pose>0 0 0 0 -0 0</pose>
        <geometry>
          <cylinder>
            <length>0.014999999999999999</length>
            <radius>0.035749999999999997</radius>
          </cylinder>
        </geometry>
        <material>
          <script>
            <name>Gazebo/DarkGrey</name>
            <uri>file://media/materials/scripts/gazebo.material</uri>
          </script>
          <diffuse>0.125 0.125 0.125 1</diffuse>
          <ambient>0.125 0.125 0.125 1</ambient>
        </material>
      </visual>
    </link>
    <plugin name='wheel_drop_left_plugin' filename='libgazebo_ros_create_wheel_drop.so'>
      <ros>
        <namespace>/</namespace>
        <remapping>~/out:=_internal/wheel_drop/left_wheel/event</remapping>
      </ros>
      <update_rate>62</update_rate>
      <detection_threshold>0.03</detection_threshold>
      <joint_name>wheel_drop_left_joint</joint_name>
      <frame_id>wheel_drop_left</frame_id>
    </plugin>
    <plugin name='wheel_drop_right_plugin' filename='libgazebo_ros_create_wheel_drop.so'>
      <ros>
        <namespace>/</namespace>
        <remapping>~/out:=_internal/wheel_drop/right_wheel/event</remapping>
      </ros>
      <update_rate>62</update_rate>
      <detection_threshold>0.03</detection_threshold>
      <joint_name>wheel_drop_right_joint</joint_name>
      <frame_id>wheel_drop_right</frame_id>
    </plugin>
    <plugin name='gazebo_ros2_control' filename='libgazebo_ros2_control.so'>
      <parameters>/opt/ros/galactic/share/irobot_create_control/config/control.yaml</parameters>
    </plugin>
    <plugin name='mouse_plugin' filename='libgazebo_ros_create_optical_mouse.so'>
      <ros>
        <namespace>/</namespace>
        <remapping>~/out:=mouse</remapping>
      </ros>
      <update_rate>62</update_rate>
      <link_name>mouse</link_name>
    </plugin>
    <plugin name='ir_omni_plugin' filename='libgazebo_ros_create_ir_opcode.so'>
      <ros>
        <namespace>/</namespace>
        <remapping>~/out:=ir_opcode</remapping>
      </ros>
      <update_rate>31</update_rate>
      <robot_model_name>create3</robot_model_name>
      <receiver_link_name>ir_omni</receiver_link_name>
      <dock_model_name>standard_dock</dock_model_name>
      <emitter_link_name>halo_link</emitter_link_name>
      <sensor_0_fov>3.839724354387525</sensor_0_fov>
      <sensor_0_range>0.01</sensor_0_range>
      <sensor_1_fov>1.5707963267948966</sensor_1_fov>
      <sensor_1_range>0.5</sensor_1_range>
    </plugin>
    <plugin name='gazebo_ros_p3d_robot' filename='libgazebo_ros_p3d.so'>
      <ros>
        <namespace>/</namespace>
        <remapping>odom:=sim_ground_truth_pose</remapping>
      </ros>
      <body_name>base_link</body_name>
      <frame_name>world</frame_name>
      <update_rate>62</update_rate>
      <xyz_offset>0 0 0</xyz_offset>
      <rpy_offset>0.0 0.0 0.0</rpy_offset>
      <gaussian_noise>0.0</gaussian_noise>
    </plugin>
    <plugin name='dock_status_publisher' filename='libgazebo_ros_create_docking_status.so'>
      <ros>
        <namespace>/</namespace>
        <remapping>~/out:=dock</remapping>
      </ros>
      <update_rate>1.0</update_rate>
      <robot_model_name>create3</robot_model_name>
      <receiver_link_name>ir_omni</receiver_link_name>
      <dock_model_name>standard_dock</dock_model_name>
      <emitter_link_name>halo_link</emitter_link_name>
    </plugin>
    <static>0</static>
    <plugin name='ign_ros2_control::IgnitionROS2ControlPlugin' filename='ign_ros2_control-system'>
      <parameters>/home/geraldineb/Documents/lss_ign_moveit/install/share/lss_arm_moveit/config/controllers_effort.yaml</parameters>
    </plugin>
  </model>
</sdf>
