<?xml version="1.0" ?>
<!-- =================================================================================== -->
<!-- |    This document was autogenerated by xacro from /home/geraldineb/Documents/lss_ign_moveit/src/lss_ign_moveit2/lss_arm_description/urdf/lss_arm.urdf.xacro | -->
<!-- |    EDITING THIS FILE BY HAND IS NOT RECOMMENDED                                 | -->
<!-- =================================================================================== -->
<!-- URDF for LSS 4DoF Arm -->
<robot name="lss_arm">
  <!--            -->
  <!-- Properties -->
  <!--            -->
  <!-- <xacro:property name="joint_gripper_name" value="joint_gripper"/>
  <xacro:property name="joint_gripper_type" value="fixed"/>
  <xacro:property name="hand_name" value="hand"/>
  <xacro:property name="hand_mu" value="0.85"/> -->
  <link name="world">
  </link>
  <joint name="lss_arm_joint_base" type="fixed">
    <parent link="world"/>
    <child link="lss_arm_link_0"/>
    <origin rpy="0 0 0" xyz="0 0 0"/>
  </joint>
  <link name="lss_arm_link_0">
    <visual>
      <origin rpy="0 0 0" xyz="0 0 0"/>
      <geometry>
        <mesh filename="package://lss_arm_description/meshes/visual/link_0.STL"/>
      </geometry>
      <material name="">
        <color rgba="0.3 0.3 0.3 1"/>
      </material>
    </visual>
    <collision>
      <origin rpy="0 0 0" xyz="0 0 0"/>
      <geometry>
        <mesh filename="package://lss_arm_description/meshes/collision/link_0.STL"/>
      </geometry>
    </collision>
    <inertial>
      <origin rpy="0 0 0" xyz="-9.22746070072536E-09 0.00772579323332284 0.0258164486308589"/>
      <mass value="0.0745235989082936"/>
      <inertia ixx="3.06926142332185E-05" ixy="9.19227938875618E-11" ixz="2.60960163114495E-12" iyy="2.37938175373349E-05" iyz="2.14419674075701E-07" izz="4.37402989726652E-05"/>
    </inertial>
  </link>
  <gazebo reference="lss_arm_link_0">
    <mu1 value="247.75"/>
    <mu2 value="247.75"/>
  </gazebo>
  <joint name="lss_arm_joint0" type="revolute">
    <parent link="lss_arm_link_0"/>
    <child link="lss_arm_link_1"/>
    <origin rpy="1.5708 0 0" xyz="0 0 0.0427"/>
    <axis xyz="0 1 0"/>
    <limit effort="6.5687857" lower="-3.141592653589793" upper="3.141592653589793" velocity="6.283"/>
    <dynamics damping="0.01" friction="3.48"/>
  </joint>
  <transmission name="lss_arm_joint0_transmission">
    <type>transmission_interface/SimpleTransmission</type>
    <joint name="lss_arm_joint0">
      <hardwareInterface>hardware_interface/EffortJointInterface</hardwareInterface>
    </joint>
    <actuator name="lss_arm_joint0_actuator">
      <mechanicalReduction>1</mechanicalReduction>
    </actuator>
  </transmission>
  <gazebo reference="lss_arm_joint0">
    <springStiffness value="0.0"/>
    <springReference value="0.0"/>
  </gazebo>
  <link name="lss_arm_link_1">
    <visual>
      <origin rpy="0 0 0" xyz="0 0 0"/>
      <geometry>
        <mesh filename="package://lss_arm_description/meshes/visual/link_1.STL"/>
      </geometry>
      <material name="">
        <color rgba="0.3 0.3 0.3 1"/>
      </material>
    </visual>
    <collision>
      <origin rpy="0 0 0" xyz="0 0 0"/>
      <geometry>
        <mesh filename="package://lss_arm_description/meshes/collision/link_1.STL"/>
      </geometry>
    </collision>
    <inertial>
      <origin rpy="0 0 0" xyz="1.01932002252511E-06 0.0346260395806251 0.000106547591030595"/>
      <mass value="0.0658784270809996"/>
      <inertia ixx="2.21234278407549E-05" ixy="9.24359378260813E-11" ixz="-3.0028304734589E-12" iyy="2.30585181059312E-05" iyz="-2.19526468312218E-07" izz="1.89994043624137E-05"/>
    </inertial>
  </link>
  <gazebo reference="lss_arm_link_1">
    <mu1 value="247.75"/>
    <mu2 value="247.75"/>
  </gazebo>
  <joint name="lss_arm_joint1" type="revolute">
    <parent link="lss_arm_link_1"/>
    <child link="lss_arm_link_2"/>
    <origin rpy="0 0 -1.3621104667496" xyz="0 0.0588000249999991 0"/>
    <axis xyz="0 0 1"/>
    <limit effort="6.5687857" lower="-1.5707963267948966" upper="1.5707963267948966" velocity="6.283"/>
    <dynamics damping="0.01" friction="3.48"/>
  </joint>
  <transmission name="lss_arm_joint1_transmission">
    <type>transmission_interface/SimpleTransmission</type>
    <joint name="lss_arm_joint1">
      <hardwareInterface>hardware_interface/EffortJointInterface</hardwareInterface>
    </joint>
    <actuator name="lss_arm_joint1_actuator">
      <mechanicalReduction>1</mechanicalReduction>
    </actuator>
  </transmission>
  <gazebo reference="lss_arm_joint1">
    <springStiffness value="0.0"/>
    <springReference value="0.0"/>
  </gazebo>
  <link name="lss_arm_link_2">
    <visual>
      <origin rpy="0 0 0" xyz="0 0 0"/>
      <geometry>
        <mesh filename="package://lss_arm_description/meshes/visual/link_2.STL"/>
      </geometry>
      <material name="">
        <color rgba="0.3 0.3 0.3 1"/>
      </material>
    </visual>
    <collision>
      <origin rpy="0 0 0" xyz="0 0 0"/>
      <geometry>
        <mesh filename="package://lss_arm_description/meshes/collision/link_2.STL"/>
      </geometry>
    </collision>
    <inertial>
      <origin rpy="0 0 0" xyz="-0.111778545935364 0.0336104387117684 0.000180852718742204"/>
      <mass value="0.0616037662847113"/>
      <inertia ixx="1.66852308837933E-05" ixy="-1.03329219740433E-06" ixz="-4.43310654754874E-08" iyy="1.20242622304033E-05" iyz="-2.15007795219099E-07" izz="1.41673473261847E-05"/>
    </inertial>
  </link>
  <gazebo reference="lss_arm_link_2">
    <mu1 value="247.75"/>
    <mu2 value="247.75"/>
  </gazebo>
  <joint name="lss_arm_joint2" type="revolute">
    <parent link="lss_arm_link_2"/>
    <child link="lss_arm_link_3"/>
    <origin rpy="0 0 1.02985068022995" xyz="-0.12954806230389 0.0533975613048809 0"/>
    <axis xyz="0 0 1"/>
    <limit effort="6.5687857" lower="-1.5707963267948966" upper="1.5707963267948966" velocity="6.283"/>
    <dynamics damping="0.01" friction="3.48"/>
  </joint>
  <transmission name="lss_arm_joint2_transmission">
    <type>transmission_interface/SimpleTransmission</type>
    <joint name="lss_arm_joint2">
      <hardwareInterface>hardware_interface/EffortJointInterface</hardwareInterface>
    </joint>
    <actuator name="lss_arm_joint2_actuator">
      <mechanicalReduction>1</mechanicalReduction>
    </actuator>
  </transmission>
  <gazebo reference="lss_arm_joint2">
    <springStiffness value="0.0"/>
    <springReference value="0.0"/>
  </gazebo>
  <link name="lss_arm_link_3">
    <visual>
      <origin rpy="0 0 0" xyz="0 0 0"/>
      <geometry>
        <mesh filename="package://lss_arm_description/meshes/visual/link_3.STL"/>
      </geometry>
      <material name="">
        <color rgba="0.3 0.3 0.3 1"/>
      </material>
    </visual>
    <collision>
      <origin rpy="0 0 0" xyz="0 0 0"/>
      <geometry>
        <mesh filename="package://lss_arm_description/meshes/collision/link_3.STL"/>
      </geometry>
    </collision>
    <inertial>
      <origin rpy="0 0 0" xyz="0.119392702406077 0.0410364992253052 0.000154048902422472"/>
      <mass value="0.062951277283338"/>
      <inertia ixx="1.11886789972704E-05" ixy="-2.66768170363405E-06" ixz="-2.01609481649329E-07" iyy="1.79991460198167E-05" iyz="-6.9561531958934E-08" izz="1.46158276124359E-05"/>
    </inertial>
  </link>
  <gazebo reference="lss_arm_link_3">
    <mu1 value="247.75"/>
    <mu2 value="247.75"/>
  </gazebo>
  <joint name="lss_arm_joint3" type="revolute">
    <parent link="lss_arm_link_3"/>
    <child link="lss_arm_link_4"/>
    <origin rpy="0 0 0.332259786519651" xyz="0.154274210199929 0.0532325846374996 0"/>
    <axis xyz="0 0 1"/>
    <limit effort="6.5687857" lower="-1.5707963267948966" upper="1.5707963267948966" velocity="6.283"/>
    <dynamics damping="0.01" friction="3.48"/>
  </joint>
  <transmission name="lss_arm_joint3_transmission">
    <type>transmission_interface/SimpleTransmission</type>
    <joint name="lss_arm_joint3">
      <hardwareInterface>hardware_interface/EffortJointInterface</hardwareInterface>
    </joint>
    <actuator name="lss_arm_joint3_actuator">
      <mechanicalReduction>1</mechanicalReduction>
    </actuator>
  </transmission>
  <gazebo reference="lss_arm_joint3">
    <springStiffness value="0.0"/>
    <springReference value="0.0"/>
  </gazebo>
  <link name="lss_arm_link_4">
    <visual>
      <origin rpy="0 0 0" xyz="0 0 0"/>
      <geometry>
        <mesh filename="package://lss_arm_description/meshes/visual/link_4.STL"/>
      </geometry>
      <material name="">
        <color rgba="0.3 0.3 0.3 1"/>
      </material>
    </visual>
    <collision>
      <origin rpy="0 0 0" xyz="0 0 0"/>
      <geometry>
        <mesh filename="package://lss_arm_description/meshes/collision/link_4.STL"/>
      </geometry>
    </collision>
    <inertial>
      <origin rpy="0 0 0" xyz="0.0463345232293113 -0.000217116498809761 0.000342446314582681"/>
      <mass value="0.0552917317501261"/>
      <inertia ixx="1.81135754161747E-05" ixy="3.0049831947197E-12" ixz="9.20482185162439E-11" iyy="1.48586070714427E-05" iyz="2.14450571018836E-07" izz="9.04738520213568E-06"/>
    </inertial>
  </link>
  <gazebo reference="lss_arm_link_4">
    <mu1 value="247.75"/>
    <mu2 value="247.75"/>
  </gazebo>
  <ros2_control name="lss_arm_system" type="system">
    <hardware>
      <plugin>ign_ros2_control/IgnitionSystem</plugin>
    </hardware>
    <joint name="lss_arm_joint0">
      <param name="initial_position">0.0</param>
      <command_interface name="effort"/>
      <state_interface name="position"/>
      <state_interface name="velocity"/>
      <state_interface name="effort"/>
    </joint>
    <joint name="lss_arm_joint1">
      <param name="initial_position">0.0</param>
      <command_interface name="effort"/>
      <state_interface name="position"/>
      <state_interface name="velocity"/>
      <state_interface name="effort"/>
    </joint>
    <joint name="lss_arm_joint2">
      <param name="initial_position">0.0</param>
      <command_interface name="effort"/>
      <state_interface name="position"/>
      <state_interface name="velocity"/>
      <state_interface name="effort"/>
    </joint>
    <joint name="lss_arm_joint3">
      <param name="initial_position">0.0</param>
      <command_interface name="effort"/>
      <state_interface name="position"/>
      <state_interface name="velocity"/>
      <state_interface name="effort"/>
    </joint>
  </ros2_control>
  <joint name="lss_arm_gripper_r" type="revolute">
    <parent link="lss_arm_link_4"/>
    <child link="lss_arm_end_effector_r"/>
    <origin rpy="0 0 0" xyz="0.0507999999999996 -0.00273873977545905 -0.0123999999999962"/>
    <axis xyz="0 1 0"/>
    <limit effort="6.5687857" lower="0" upper="1.5707963267948966" velocity="6.283"/>
    <dynamics damping="0.01" friction="0.4"/>
  </joint>
  <transmission name="lss_arm_gripper_r_transmission">
    <type>transmission_interface/SimpleTransmission</type>
    <joint name="lss_arm_gripper_r">
      <hardwareInterface>hardware_interface/EffortJointInterface</hardwareInterface>
    </joint>
    <actuator name="lss_arm_gripper_r_actuator">
      <mechanicalReduction>1</mechanicalReduction>
    </actuator>
  </transmission>
  <gazebo reference="lss_arm_gripper_r">
    <springStiffness value="0.0"/>
    <springReference value="0.0"/>
  </gazebo>
  <link name="lss_arm_end_effector_r">
    <visual>
      <origin rpy="0 0 0" xyz="0 0 0"/>
      <geometry>
        <mesh filename="package://lss_arm_description/meshes/visual/end_effector_r.STL"/>
      </geometry>
      <material name="">
        <color rgba="0.3 0.3 0.3 1"/>
      </material>
    </visual>
    <collision>
      <origin rpy="0 0 0" xyz="0 0 0"/>
      <geometry>
        <mesh filename="package://lss_arm_description/meshes/collision/end_effector_r.STL"/>
      </geometry>
    </collision>
    <inertial>
      <origin rpy="0 0 0" xyz="0.0308013779043008 -0.0141013526461647 0.00131237715084586"/>
      <mass value="0.0166262969986533"/>
      <inertia ixx="6.38976786525478E-07" ixy="-1.49469409770964E-12" ixz="-4.41621752133789E-07" iyy="3.00353485001635E-06" iyz="-4.34708916625113E-12" izz="2.57289120441113E-06"/>
    </inertial>
  </link>
  <gazebo reference="lss_arm_end_effector_r">
    <mu1 value="247.75"/>
    <mu2 value="247.75"/>
  </gazebo>
  <joint name="lss_arm_gripper_l" type="revolute">
    <parent link="lss_arm_link_4"/>
    <child link="lss_arm_end_effector_l"/>
    <origin rpy="0 0 0" xyz="0.0507999999999993 -0.00273873977545905 0.0130000000000038"/>
    <axis xyz="0 1 0"/>
    <limit effort="6.5687857" lower="-1.5707963267948966" upper="0" velocity="6.283"/>
    <dynamics damping="0.01" friction="0.4"/>
  </joint>
  <transmission name="lss_arm_gripper_l_transmission">
    <type>transmission_interface/SimpleTransmission</type>
    <joint name="lss_arm_gripper_l">
      <hardwareInterface>hardware_interface/EffortJointInterface</hardwareInterface>
    </joint>
    <actuator name="lss_arm_gripper_l_actuator">
      <mechanicalReduction>1</mechanicalReduction>
    </actuator>
  </transmission>
  <gazebo reference="lss_arm_gripper_l">
    <springStiffness value="0.0"/>
    <springReference value="0.0"/>
  </gazebo>
  <link name="lss_arm_end_effector_l">
    <visual>
      <origin rpy="0 0 0" xyz="0 0 0"/>
      <geometry>
        <mesh filename="package://lss_arm_description/meshes/visual/end_effector_l.STL"/>
      </geometry>
      <material name="">
        <color rgba="0.3 0.3 0.3 1"/>
      </material>
    </visual>
    <collision>
      <origin rpy="0 0 0" xyz="0 0 0"/>
      <geometry>
        <mesh filename="package://lss_arm_description/meshes/collision/end_effector_l.STL"/>
      </geometry>
    </collision>
    <inertial>
      <origin rpy="0 0 0" xyz="0.0309551132879063 -0.0140672528822861 -0.0013189270605785"/>
      <mass value="0.0165437278185932"/>
      <inertia ixx="6.37840843695913E-07" ixy="-1.67462842205218E-12" ixz="4.41621808330111E-07" iyy="3.00246171921638E-06" iyz="3.99757576475728E-12" izz="2.57175512278327E-06"/>
    </inertial>
  </link>
  <gazebo reference="lss_arm_end_effector_l">
    <mu1 value="247.75"/>
    <mu2 value="247.75"/>
  </gazebo>
  <link name="lss_arm_hand_tcp">
  </link>
  <joint name="lss_arm_hand_tcp_virtual_joint" type="fixed">
    <parent link="lss_arm_link_4"/>
    <child link="lss_arm_hand_tcp"/>
    <origin rpy="0 0 0" xyz="0.11 0 0"/>
  </joint>
  <ros2_control name="lss_gripper_system" type="system">
    <hardware>
      <plugin>ign_ros2_control/IgnitionSystem</plugin>
    </hardware>
    <joint name="lss_arm_gripper_r">
      <param name="initial_position">0.0</param>
      <command_interface name="effort"/>
      <state_interface name="position"/>
      <state_interface name="velocity"/>
      <state_interface name="effort"/>
    </joint>
    <joint name="lss_arm_gripper_l">
      <param name="initial_position">0.0</param>
      <param name="mimic">lss_arm_gripper_r</param>
      <param name="multiplier">-1</param>
      <command_interface name="effort"/>
      <state_interface name="position"/>
      <state_interface name="velocity"/>
      <state_interface name="effort"/>
    </joint>
  </ros2_control>
  <gazebo>
    <plugin filename="ign_ros2_control-system" name="ign_ros2_control::IgnitionROS2ControlPlugin">
      <parameters>/home/geraldineb/Documents/lss_ign_moveit/install/share/lss_arm_moveit/config/controllers_effort.yaml</parameters>
    </plugin>
  </gazebo>
</robot>
