<?xml version="1.0" ?>
<!-- =================================================================================== -->
<!-- |    This document was autogenerated by xacro from /home/geraldineb/Documents/lss_ign_moveit/src/lss_ign_moveit2/lss_arm_description/urdf/lss_arm.urdf.xacro | -->
<!-- |    EDITING THIS FILE BY HAND IS NOT RECOMMENDED                                 | -->
<!-- =================================================================================== -->
<!-- URDF for LSS 4DoF Arm -->
<robot name="lss_arm">
  <link name="world">
  </link>
  <joint name="lss_arm_joint0" type="fixed">
    <parent link="world"/>
    <child link="lss_arm_link_0"/>
    <origin rpy="0 0 0" xyz="0 0 0"/>
  </joint>
  <link name="lss_arm_link_0">
    <visual>
      <origin rpy="0 0 0" xyz="0 0 0"/>
      <geometry>
        <mesh filename="package://lss_arm_description/meshes/visual/link_0.STL"/>
      </geometry>
      <material name="">
        <color rgba="0.3 0.3 0.3 1"/>
      </material>
    </visual>
    <collision>
      <origin rpy="0 0 0" xyz="0 0 0"/>
      <geometry>
        <mesh filename="package://lss_arm_description/meshes/collision/link_0.STL"/>
      </geometry>
    </collision>
    <inertial>
      <origin rpy="0 0 0" xyz="-2.73691915043146E-09 0.0078496161601494 0.0255901951226594"/>
      <mass value="0.0717410813666018"/>
      <inertia ixx="3.0636904073993E-05" ixy="9.19910875697947E-11" ixz="-6.99542916495097E-14" iyy="2.37381054307842E-05" iyz="2.14417631554388E-07" izz="4.37325540149466E-05"/>
    </inertial>
  </link>
  <gazebo reference="lss_arm_link_0">
    <mu1 value="0.3"/>
    <mu2 value="0.3"/>
  </gazebo>
  <joint name="lss_arm_joint1" type="revolute">
    <parent link="lss_arm_link_0"/>
    <child link="lss_arm_link_1"/>
    <origin rpy="1.5707963267948966 0 0" xyz="0 0 0.042699975"/>
    <axis xyz="0 1 0"/>
    <limit effort="6.5687857" lower="-3.141592653589793" upper="3.141592653589793" velocity="6.283"/>
    <dynamics damping="0.01" friction="3.48"/>
  </joint>
  <transmission name="lss_arm_joint1_transmission">
    <type>transmission_interface/SimpleTransmission</type>
    <joint name="lss_arm_joint1">
      <hardwareInterface>hardware_interface/EffortJointInterface</hardwareInterface>
    </joint>
    <actuator name="lss_arm_joint1_actuator">
      <mechanicalReduction>1</mechanicalReduction>
    </actuator>
  </transmission>
  <gazebo reference="lss_arm_joint1">
    <springStiffness value="0.0"/>
    <springReference value="0.0"/>
  </gazebo>
  <link name="lss_arm_link_1">
    <visual>
      <origin rpy="0 0 0" xyz="0 0 0"/>
      <geometry>
        <mesh filename="package://lss_arm_description/meshes/visual/link_1.STL"/>
      </geometry>
      <material name="">
        <color rgba="0.3 0.3 0.3 1"/>
      </material>
    </visual>
    <collision>
      <origin rpy="0 0 0" xyz="0 0 0"/>
      <geometry>
        <mesh filename="package://lss_arm_description/meshes/collision/link_1.STL"/>
      </geometry>
    </collision>
    <inertial>
      <origin rpy="0 0 0" xyz="1.5578217768027E-09 0.0348051841749016 0.00014951767591631"/>
      <mass value="0.0628875763471834"/>
      <inertia ixx="2.20425725995968E-05" ixy="9.19935112458848E-11" ixz="1.70368679861891E-13" iyy="2.29485908974563E-05" iyz="-2.19524118186986E-07" izz="1.89578527653699E-05"/>
    </inertial>
  </link>
  <gazebo reference="lss_arm_link_1">
    <mu1 value="0.3"/>
    <mu2 value="0.3"/>
  </gazebo>
  <joint name="lss_arm_joint2" type="revolute">
    <parent link="lss_arm_link_1"/>
    <child link="lss_arm_link_2"/>
    <origin rpy="0 0 -1.3621104667496" xyz="0 0.0588000249999991 0"/>
    <axis xyz="0 0 1"/>
    <limit effort="6.5687857" lower="-1.5707963267948966" upper="1.5707963267948966" velocity="6.283"/>
    <dynamics damping="0.01" friction="3.48"/>
  </joint>
  <transmission name="lss_arm_joint2_transmission">
    <type>transmission_interface/SimpleTransmission</type>
    <joint name="lss_arm_joint2">
      <hardwareInterface>hardware_interface/EffortJointInterface</hardwareInterface>
    </joint>
    <actuator name="lss_arm_joint2_actuator">
      <mechanicalReduction>1</mechanicalReduction>
    </actuator>
  </transmission>
  <gazebo reference="lss_arm_joint2">
    <springStiffness value="0.0"/>
    <springReference value="0.0"/>
  </gazebo>
  <link name="lss_arm_link_2">
    <visual>
      <origin rpy="0 0 0" xyz="0 0 0"/>
      <geometry>
        <mesh filename="package://lss_arm_description/meshes/visual/link_2.STL"/>
      </geometry>
      <material name="">
        <color rgba="0.3 0.3 0.3 1"/>
      </material>
    </visual>
    <collision>
      <origin rpy="0 0 0" xyz="0 0 0"/>
      <geometry>
        <mesh filename="package://lss_arm_description/meshes/collision/link_2.STL"/>
      </geometry>
    </collision>
    <inertial>
      <origin rpy="0 0 0" xyz="-0.112045323028693 0.0336416089233315 0.000234166707606796"/>
      <mass value="0.0592207297890142"/>
      <inertia ixx="1.66333998725443E-05" ixy="-1.03352394963547E-06" ixz="-4.43274108116386E-08" iyy="1.1971383214163E-05" iyz="-2.15005479062966E-07" izz="1.41577057658295E-05"/>
    </inertial>
  </link>
  <gazebo reference="lss_arm_link_2">
    <mu1 value="0.3"/>
    <mu2 value="0.3"/>
  </gazebo>
  <joint name="lss_arm_joint3" type="revolute">
    <parent link="lss_arm_link_2"/>
    <child link="lss_arm_link_3"/>
    <origin rpy="0 0 1.02985068022995" xyz="-0.12954806230389 0.0533975613048809 0"/>
    <axis xyz="0 0 1"/>
    <limit effort="6.5687857" lower="-1.5707963267948966" upper="1.5707963267948966" velocity="6.283"/>
    <dynamics damping="0.01" friction="3.48"/>
  </joint>
  <transmission name="lss_arm_joint3_transmission">
    <type>transmission_interface/SimpleTransmission</type>
    <joint name="lss_arm_joint3">
      <hardwareInterface>hardware_interface/EffortJointInterface</hardwareInterface>
    </joint>
    <actuator name="lss_arm_joint3_actuator">
      <mechanicalReduction>1</mechanicalReduction>
    </actuator>
  </transmission>
  <gazebo reference="lss_arm_joint3">
    <springStiffness value="0.0"/>
    <springReference value="0.0"/>
  </gazebo>
  <link name="lss_arm_link_3">
    <visual>
      <origin rpy="0 0 0" xyz="0 0 0"/>
      <geometry>
        <mesh filename="package://lss_arm_description/meshes/visual/link_3.STL"/>
      </geometry>
      <material name="">
        <color rgba="0.3 0.3 0.3 1"/>
      </material>
    </visual>
    <collision>
      <origin rpy="0 0 0" xyz="0 0 0"/>
      <geometry>
        <mesh filename="package://lss_arm_description/meshes/collision/link_3.STL"/>
      </geometry>
    </collision>
    <inertial>
      <origin rpy="0 0 0" xyz="0.119623138465818 0.0411506770766876 0.000345214465821365"/>
      <mass value="0.0601490353124708"/>
      <inertia ixx="1.1113660383281E-05" ixy="-2.67466932607218E-06" ixz="2.01605698642722E-07" iyy="1.79419649434231E-05" iyz="-6.9564477599757E-08" izz="1.45807099366603E-05"/>
    </inertial>
  </link>
  <gazebo reference="lss_arm_link_3">
    <mu1 value="0.3"/>
    <mu2 value="0.3"/>
  </gazebo>
  <joint name="lss_arm_joint4" type="revolute">
    <parent link="lss_arm_link_3"/>
    <child link="lss_arm_link_4"/>
    <origin rpy="0 0 0.332259786519651" xyz="0.154274210199929 0.0532325846374996 0"/>
    <axis xyz="0 0 1"/>
    <limit effort="6.5687857" lower="-1.5707963267948966" upper="1.5707963267948966" velocity="6.283"/>
    <dynamics damping="0.01" friction="3.48"/>
  </joint>
  <transmission name="lss_arm_joint4_transmission">
    <type>transmission_interface/SimpleTransmission</type>
    <joint name="lss_arm_joint4">
      <hardwareInterface>hardware_interface/EffortJointInterface</hardwareInterface>
    </joint>
    <actuator name="lss_arm_joint4_actuator">
      <mechanicalReduction>1</mechanicalReduction>
    </actuator>
  </transmission>
  <gazebo reference="lss_arm_joint4">
    <springStiffness value="0.0"/>
    <springReference value="0.0"/>
  </gazebo>
  <link name="lss_arm_link_4">
    <visual>
      <origin rpy="0 0 0" xyz="0 0 0"/>
      <geometry>
        <mesh filename="package://lss_arm_description/meshes/visual/link_4.STL"/>
      </geometry>
      <material name="">
        <color rgba="0.3 0.3 0.3 1"/>
      </material>
    </visual>
    <collision>
      <origin rpy="0 0 0" xyz="0 0 0"/>
      <geometry>
        <mesh filename="package://lss_arm_description/meshes/collision/link_4.STL"/>
      </geometry>
    </collision>
    <inertial>
      <origin rpy="0 0 0" xyz="0.0446894562780881 -0.000131072409021604 0.000356231689785028"/>
      <mass value="0.0556319659037934"/>
      <inertia ixx="1.81337749108788E-05" ixy="-6.99513846908487E-14" ixz="9.19941036664484E-11" iyy="1.49173144124065E-05" iyz="2.14447838213905E-07" izz="9.12796728342695E-06"/>
    </inertial>
  </link>
  <gazebo reference="lss_arm_link_4">
    <mu1 value="0.3"/>
    <mu2 value="0.3"/>
  </gazebo>
  <ros2_control name="lss_arm_system" type="system">
    <hardware>
      <plugin>ign_ros2_control/IgnitionSystem</plugin>
    </hardware>
    <joint name="lss_arm_joint1">
      <param name="initial_position">0.0</param>
      <command_interface name="effort"/>
      <state_interface name="position"/>
      <state_interface name="velocity"/>
      <state_interface name="effort"/>
    </joint>
    <joint name="lss_arm_joint2">
      <param name="initial_position">0.8</param>
      <command_interface name="effort"/>
      <state_interface name="position"/>
      <state_interface name="velocity"/>
      <state_interface name="effort"/>
    </joint>
    <joint name="lss_arm_joint3">
      <param name="initial_position">-0.4</param>
      <command_interface name="effort"/>
      <state_interface name="position"/>
      <state_interface name="velocity"/>
      <state_interface name="effort"/>
    </joint>
    <joint name="lss_arm_joint4">
      <param name="initial_position">-0.4</param>
      <command_interface name="effort"/>
      <state_interface name="position"/>
      <state_interface name="velocity"/>
      <state_interface name="effort"/>
    </joint>
  </ros2_control>
  <joint name="lss_arm_gripper_r" type="revolute">
    <parent link="lss_arm_link_4"/>
    <child link="lss_arm_end_effector_r"/>
    <origin rpy="0 0 0" xyz="0.0507999999999996 -0.00273873977545905 -0.0123999999999962"/>
    <axis xyz="0 1 0"/>
    <limit effort="6.5687857" lower="0" upper="1.5707963267948966" velocity="6.283"/>
    <dynamics damping="0.01" friction="0.4"/>
  </joint>
  <transmission name="lss_arm_gripper_r_transmission">
    <type>transmission_interface/SimpleTransmission</type>
    <joint name="lss_arm_gripper_r">
      <hardwareInterface>hardware_interface/EffortJointInterface</hardwareInterface>
    </joint>
    <actuator name="lss_arm_gripper_r_actuator">
      <mechanicalReduction>1</mechanicalReduction>
    </actuator>
  </transmission>
  <gazebo reference="lss_arm_gripper_r">
    <springStiffness value="0.0"/>
    <springReference value="0.0"/>
  </gazebo>
  <link name="lss_arm_end_effector_r">
    <visual>
      <origin rpy="0 0 0" xyz="0 0 0"/>
      <geometry>
        <mesh filename="package://lss_arm_description/meshes/visual/end_effector_r.STL"/>
      </geometry>
      <material name="">
        <color rgba="0.3 0.3 0.3 1"/>
      </material>
    </visual>
    <collision>
      <origin rpy="0 0 0" xyz="0 0 0"/>
      <geometry>
        <mesh filename="package://lss_arm_description/meshes/collision/end_effector_r.STL"/>
      </geometry>
    </collision>
    <inertial>
      <origin rpy="0 0 0" xyz="0.0310712366675979 -0.0140452526813673 0.00133953163684892"/>
      <mass value="0.0152813047822834"/>
      <inertia ixx="6.12119941271843E-07" ixy="-1.61044889315886E-12" ixz="-4.41621763353496E-07" iyy="2.99804070646807E-06" iyz="-3.8879675590965E-12" izz="2.54603357212087E-06"/>
    </inertial>
  </link>
  <gazebo reference="lss_arm_end_effector_r">
    <mu1 value="0.3"/>
    <mu2 value="0.3"/>
  </gazebo>
  <joint name="lss_arm_gripper_l" type="revolute">
    <parent link="lss_arm_link_4"/>
    <child link="lss_arm_end_effector_l"/>
    <origin rpy="0 0 0" xyz="0.0507999999999993 -0.00273873977545905 0.0130000000000038"/>
    <axis xyz="0 1 0"/>
    <limit effort="6.5687857" lower="-1.5707963267948966" upper="0" velocity="6.283"/>
    <dynamics damping="0.01" friction="0.4"/>
  </joint>
  <transmission name="lss_arm_gripper_l_transmission">
    <type>transmission_interface/SimpleTransmission</type>
    <joint name="lss_arm_gripper_l">
      <hardwareInterface>hardware_interface/EffortJointInterface</hardwareInterface>
    </joint>
    <actuator name="lss_arm_gripper_l_actuator">
      <mechanicalReduction>1</mechanicalReduction>
    </actuator>
  </transmission>
  <gazebo reference="lss_arm_gripper_l">
    <springStiffness value="0.0"/>
    <springReference value="0.0"/>
  </gazebo>
  <link name="lss_arm_end_effector_l">
    <visual>
      <origin rpy="0 0 0" xyz="0 0 0"/>
      <geometry>
        <mesh filename="package://lss_arm_description/meshes/visual/end_effector_l.STL"/>
      </geometry>
      <material name="">
        <color rgba="0.3 0.3 0.3 1"/>
      </material>
    </visual>
    <collision>
      <origin rpy="0 0 0" xyz="0 0 0"/>
      <geometry>
        <mesh filename="package://lss_arm_description/meshes/collision/end_effector_l.STL"/>
      </geometry>
    </collision>
    <inertial>
      <origin rpy="0 0 0" xyz="0.0307726942893274 -0.0140975049159748 -0.0013266609885073"/>
      <mass value="0.0154295568992377"/>
      <inertia ixx="6.13242885883712E-07" ixy="-1.69555790218149E-12" ixz="4.41621764601781E-07" iyy="2.99899721506146E-06" iyz="4.09343888509186E-12" izz="2.54715653674288E-06"/>
    </inertial>
  </link>
  <gazebo reference="lss_arm_end_effector_l">
    <mu1 value="0.3"/>
    <mu2 value="0.3"/>
  </gazebo>
  <link name="lss_arm_hand_tcp">
  </link>
  <joint name="lss_arm_hand_tcp_virtual_joint" type="fixed">
    <parent link="lss_arm_link_4"/>
    <child link="lss_arm_hand_tcp"/>
    <origin rpy="0 0 0" xyz="0.11 0 0"/>
  </joint>
  <ros2_control name="lss_gripper_system" type="system">
    <hardware>
      <plugin>ign_ros2_control/IgnitionSystem</plugin>
    </hardware>
    <joint name="lss_arm_gripper_r">
      <param name="initial_position">0.4</param>
      <command_interface name="effort"/>
      <state_interface name="position"/>
      <state_interface name="velocity"/>
      <state_interface name="effort"/>
    </joint>
    <joint name="lss_arm_gripper_l">
      <param name="initial_position">-0.4</param>
      <param name="mimic">lss_arm_gripper_r</param>
      <param name="multiplier">-1</param>
      <command_interface name="effort"/>
      <state_interface name="position"/>
      <state_interface name="velocity"/>
      <state_interface name="effort"/>
    </joint>
  </ros2_control>
  <gazebo>
    <plugin filename="ign_ros2_control-system" name="ign_ros2_control::IgnitionROS2ControlPlugin">
      <parameters>/home/geraldineb/Documents/lss_ign_moveit/install/share/lss_arm_moveit/config/controllers_effort.yaml</parameters>
    </plugin>
  </gazebo>
</robot>
