<?xml version="1.0" ?>
<!-- =================================================================================== -->
<!-- |    This document was autogenerated by xacro from /home/geraldineb/Documents/lss_ign_moveit/src/lss_ign_moveit2/lss_arm_description/urdf/tb4_lss_arm.urdf.xacro | -->
<!-- |    EDITING THIS FILE BY HAND IS NOT RECOMMENDED                                 | -->
<!-- =================================================================================== -->
<!-- URDF for LSS 4DoF Arm -->
<robot name="tb4_lss_arm">
  <!-- Create 3 base definition-->
  <link name="base_link">
    <visual>
      <origin rpy="0 0 1.5707963267948966" xyz="0 0 0.039200000000000006"/>
      <geometry>
        <mesh filename="package://irobot_create_description/meshes/body_visual.dae"/>
      </geometry>
    </visual>
    <collision name="create3_base_collision">
      <origin rpy="0 0 1.5707963267948966" xyz="0 0 0.04920000000000001"/>
      <geometry>
        <cylinder length="0.06" radius="0.16399999999999998"/>
      </geometry>
    </collision>
    <inertial>
      <origin xyz="0.0 0 0.0742"/>
      <mass value="2.3"/>
      <inertia ixx="0.016155199999999998" ixy="0.0" ixz="0.0" iyy="0.016155199999999998" iyz="0.0" izz="0.03093039999999999"/>
    </inertial>
  </link>
  <joint name="bump_front_center_joint" type="fixed">
    <parent link="base_link"/>
    <child link="bump_front_center"/>
    <origin xyz="0 0 0.039200000000000006"/>
  </joint>
  <link name="bump_front_center">
    <visual>
      <geometry>
        <mesh filename="package://irobot_create_description/meshes/bumper_visual.dae"/>
      </geometry>
    </visual>
    <collision>
      <geometry>
        <mesh filename="package://irobot_create_description/meshes/bumper_collision.dae"/>
      </geometry>
    </collision>
    <inertial>
      <origin xyz="0.08 0 0.02"/>
      <mass value="0.1"/>
      <inertia ixx="0.0013483753405" ixy="0.0000000454352" ixz="0.0000014434849" iyy="0.0002521736852" iyz="-0.0000000006721" izz="0.0015442525386"/>
    </inertial>
  </link>
  <gazebo reference="bump_front_center">
    <mu1>0.1</mu1>
    <mu2>0.1</mu2>
    <maxVel>0.01</maxVel>
    <minDepth>0.001</minDepth>
    <maxContacts>10</maxContacts>
    <material>Gazebo/DarkGrey</material>
    <sensor name="bump_front_center_contact_sensor" type="contact">
      <always_on>true</always_on>
      <update_rate>62.0</update_rate>
      <contact>
        <collision>bump_front_center_collision</collision>
      </contact>
      <plugin filename="libgazebo_ros_create_bumper.so" name="bump_front_center_plugin">
        <ros>
          <namespace>/</namespace>
          <remapping>~/out:=_internal/bumper/event</remapping>
        </ros>
      </plugin>
    </sensor>
  </gazebo>
  <gazebo reference="bump_front_center_joint">
    <preserveFixedJoint>true</preserveFixedJoint>
  </gazebo>
  <joint name="bump_front_left_joint" type="fixed">
    <parent link="base_link"/>
    <child link="bump_front_left"/>
    <origin rpy="0 0 0.5235985" xyz="0.02345 -0.0875 0.025"/>
  </joint>
  <link name="bump_front_left"/>
  <joint name="bump_front_right_joint" type="fixed">
    <parent link="base_link"/>
    <child link="bump_front_right"/>
    <origin rpy="0 0 -0.5235985" xyz="0.02345 0.0875 0.025"/>
  </joint>
  <link name="bump_front_right"/>
  <joint name="bump_left_joint" type="fixed">
    <parent link="base_link"/>
    <child link="bump_left"/>
    <origin rpy="0 0 1.047193" xyz="0.0875 -0.15155 0.025"/>
  </joint>
  <link name="bump_left"/>
  <joint name="bump_right_joint" type="fixed">
    <parent link="base_link"/>
    <child link="bump_right"/>
    <origin rpy="0 0 -1.047193" xyz="0.0875 0.15155 0.025"/>
  </joint>
  <link name="bump_right"/>
  <joint name="wheel_drop_left_joint" type="prismatic">
    <parent link="base_link"/>
    <child link="wheel_drop_left"/>
    <origin rpy="-1.5707963267948966 0 0" xyz="0 0.1165 0.04020000000000001"/>
    <axis xyz="0 1 0"/>
    <limit effort="0" lower="0" upper="0.03" velocity="0"/>
    <!-- Damping is big enough to not make the body oscillate too much when it's lifted up -->
    <dynamics damping="50" friction="0.1"/>
  </joint>
  <!-- Gazebo parameters to simulate a spring -->
  <gazebo reference="wheel_drop_left_joint">
    <provideFeedback>false</provideFeedback>
    <implicitSpringDamper>true</implicitSpringDamper>
    <!-- This value should be high enough so that the wheeldrop can
          retract with the robot's weight (mass * gravity) -->
    <springStiffness>400</springStiffness>
    <springReference>0.03</springReference>
  </gazebo>
  <link name="wheel_drop_left">
    <inertial>
      <mass value="0.05"/>
      <origin xyz="0 0 0"/>
      <inertia ixx="2.0833333333333336e-05" ixy="0.0" ixz="0.0" iyy="2.0833333333333336e-05" iyz="0.0" izz="2.0833333333333336e-05"/>
    </inertial>
  </link>
  <gazebo>
    <plugin filename="libgazebo_ros_create_wheel_drop.so" name="wheel_drop_left_plugin">
      <ros>
        <namespace>/</namespace>
        <remapping>~/out:=_internal/wheel_drop/left_wheel/event</remapping>
      </ros>
      <update_rate>62</update_rate>
      <detection_threshold>0.03</detection_threshold>
      <joint_name>wheel_drop_left_joint</joint_name>
      <frame_id>wheel_drop_left</frame_id>
    </plugin>
  </gazebo>
  <joint name="left_wheel_joint" type="continuous">
    <parent link="wheel_drop_left"/>
    <child link="left_wheel"/>
    <origin rpy="0 0 0" xyz="0 0 0"/>
    <axis xyz="0 0 1"/>
  </joint>
  <link name="left_wheel">
    <visual>
      <geometry>
        <cylinder length="0.015" radius="0.035750000000000004"/>
      </geometry>
      <!-- Give black color to wheels in Rviz -->
      <material name="black">
        <color rgba="0.1 0.1 0.1 1"/>
      </material>
    </visual>
    <collision>
      <geometry>
        <cylinder length="0.015" radius="0.035750000000000004"/>
      </geometry>
    </collision>
    <inertial>
      <origin xyz="0 0 0"/>
      <mass value="0.2"/>
      <inertia ixx="6.765312500000001e-05" ixy="0.0" ixz="0.0" iyy="6.765312500000001e-05" iyz="0.0" izz="0.00012780625000000003"/>
    </inertial>
  </link>
  <gazebo reference="left_wheel">
    <mu1>1.0</mu1>
    <mu2>1.0</mu2>
    <kp>1000000.0</kp>
    <kd>100.0</kd>
    <minDepth>0.0001</minDepth>
    <maxVel>1.0</maxVel>
    <material>Gazebo/DarkGrey</material>
  </gazebo>
  <ros2_control name="left_wheel_controller" type="system">
    <hardware>
      <plugin>gazebo_ros2_control/GazeboSystem</plugin>
    </hardware>
    <joint name="left_wheel_joint">
      <state_interface name="velocity"/>
      <state_interface name="position"/>
      <command_interface name="velocity"/>
    </joint>
  </ros2_control>
  <joint name="wheel_drop_right_joint" type="prismatic">
    <parent link="base_link"/>
    <child link="wheel_drop_right"/>
    <origin rpy="-1.5707963267948966 0 0" xyz="0 -0.1165 0.04020000000000001"/>
    <axis xyz="0 1 0"/>
    <limit effort="0" lower="0" upper="0.03" velocity="0"/>
    <!-- Damping is big enough to not make the body oscillate too much when it's lifted up -->
    <dynamics damping="50" friction="0.1"/>
  </joint>
  <!-- Gazebo parameters to simulate a spring -->
  <gazebo reference="wheel_drop_right_joint">
    <provideFeedback>false</provideFeedback>
    <implicitSpringDamper>true</implicitSpringDamper>
    <!-- This value should be high enough so that the wheeldrop can
          retract with the robot's weight (mass * gravity) -->
    <springStiffness>400</springStiffness>
    <springReference>0.03</springReference>
  </gazebo>
  <link name="wheel_drop_right">
    <inertial>
      <mass value="0.05"/>
      <origin xyz="0 0 0"/>
      <inertia ixx="2.0833333333333336e-05" ixy="0.0" ixz="0.0" iyy="2.0833333333333336e-05" iyz="0.0" izz="2.0833333333333336e-05"/>
    </inertial>
  </link>
  <gazebo>
    <plugin filename="libgazebo_ros_create_wheel_drop.so" name="wheel_drop_right_plugin">
      <ros>
        <namespace>/</namespace>
        <remapping>~/out:=_internal/wheel_drop/right_wheel/event</remapping>
      </ros>
      <update_rate>62</update_rate>
      <detection_threshold>0.03</detection_threshold>
      <joint_name>wheel_drop_right_joint</joint_name>
      <frame_id>wheel_drop_right</frame_id>
    </plugin>
  </gazebo>
  <joint name="right_wheel_joint" type="continuous">
    <parent link="wheel_drop_right"/>
    <child link="right_wheel"/>
    <origin rpy="0 0 0" xyz="0 0 0"/>
    <axis xyz="0 0 1"/>
  </joint>
  <link name="right_wheel">
    <visual>
      <geometry>
        <cylinder length="0.015" radius="0.035750000000000004"/>
      </geometry>
      <!-- Give black color to wheels in Rviz -->
      <material name="black">
        <color rgba="0.1 0.1 0.1 1"/>
      </material>
    </visual>
    <collision>
      <geometry>
        <cylinder length="0.015" radius="0.035750000000000004"/>
      </geometry>
    </collision>
    <inertial>
      <origin xyz="0 0 0"/>
      <mass value="0.2"/>
      <inertia ixx="6.765312500000001e-05" ixy="0.0" ixz="0.0" iyy="6.765312500000001e-05" iyz="0.0" izz="0.00012780625000000003"/>
    </inertial>
  </link>
  <gazebo reference="right_wheel">
    <mu1>1.0</mu1>
    <mu2>1.0</mu2>
    <kp>1000000.0</kp>
    <kd>100.0</kd>
    <minDepth>0.0001</minDepth>
    <maxVel>1.0</maxVel>
    <material>Gazebo/DarkGrey</material>
  </gazebo>
  <ros2_control name="right_wheel_controller" type="system">
    <hardware>
      <plugin>gazebo_ros2_control/GazeboSystem</plugin>
    </hardware>
    <joint name="right_wheel_joint">
      <state_interface name="velocity"/>
      <state_interface name="position"/>
      <command_interface name="velocity"/>
    </joint>
  </ros2_control>
  <joint name="front_caster_joint" type="fixed">
    <parent link="base_link"/>
    <child link="front_caster_link"/>
    <origin rpy="-1.5707963267948966 0 0" xyz="0.125 0 0.012200000000000003"/>
  </joint>
  <link name="front_caster_link">
    <visual>
      <geometry>
        <sphere radius="0.01"/>
      </geometry>
      <!-- Give black color to caster in Rviz -->
      <material name="black">
        <color rgba="0.1 0.1 0.1 1"/>
      </material>
    </visual>
    <collision>
      <geometry>
        <sphere radius="0.01"/>
      </geometry>
    </collision>
    <inertial>
      <mass value="0.01"/>
      <inertia ixx="4.0000000000000003e-07" ixy="0.0" ixz="0.0" iyy="4.0000000000000003e-07" iyz="0.0" izz="4.0000000000000003e-07"/>
    </inertial>
  </link>
  <gazebo reference="front_caster_joint">
    <preserveFixedJoint>true</preserveFixedJoint>
  </gazebo>
  <gazebo reference="front_caster_link">
    <material>Gazebo/DarkGrey</material>
    <mu1>0.1</mu1>
    <mu2>0.1</mu2>
    <kp>1000000.0</kp>
    <kd>1.0</kd>
  </gazebo>
  <joint name="imu_joint" type="fixed">
    <origin xyz="0.050613 0.043673 0.0844"/>
    <parent link="base_link"/>
    <child link="imu_link"/>
  </joint>
  <link name="imu_link">
    <inertial>
      <mass value="0.01"/>
      <origin xyz="0 0 0"/>
      <inertia ixx="1.6666666666666668e-07" ixy="0.0" ixz="0.0" iyy="1.6666666666666668e-07" iyz="0.0" izz="1.6666666666666668e-07"/>
    </inertial>
  </link>
  <gazebo reference="imu_link">
    <sensor name="imu" type="imu">
      <always_on>true</always_on>
      <update_rate>62</update_rate>
      <imu>
        <angular_velocity>
          <x>
            <noise type="gaussian">
              <mean>0.0</mean>
              <stddev>0.0</stddev>
            </noise>
          </x>
          <y>
            <noise type="gaussian">
              <mean>0.0</mean>
              <stddev>0.0</stddev>
            </noise>
          </y>
          <z>
            <noise type="gaussian">
              <mean>0.0</mean>
              <stddev>0.0</stddev>
            </noise>
          </z>
        </angular_velocity>
        <linear_acceleration>
          <x>
            <noise type="gaussian">
              <mean>0.0</mean>
              <stddev>0.0</stddev>
            </noise>
          </x>
          <y>
            <noise type="gaussian">
              <mean>0.0</mean>
              <stddev>0.0</stddev>
            </noise>
          </y>
          <z>
            <noise type="gaussian">
              <mean>0.0</mean>
              <stddev>0.0</stddev>
            </noise>
          </z>
        </linear_acceleration>
      </imu>
      <plugin filename="libgazebo_ros_create_imu.so" name="imu_plugin">
        <ros>
          <namespace>/</namespace>
          <remapping>~/out:=imu</remapping>
        </ros>
      </plugin>
    </sensor>
  </gazebo>
  <gazebo reference="imu_joint">
    <preserveFixedJoint>true</preserveFixedJoint>
  </gazebo>
  <gazebo>
    <plugin filename="libgazebo_ros2_control.so" name="gazebo_ros2_control">
      <parameters> /opt/ros/galactic/share/irobot_create_control/config/control.yaml </parameters>
    </plugin>
  </gazebo>
  <joint name="mouse_joint" type="fixed">
    <origin rpy="0 0 -0.7853981633974483" xyz="0.1015 0.087 0.009200000000000007"/>
    <parent link="base_link"/>
    <child link="mouse"/>
  </joint>
  <link name="mouse">
    <inertial>
      <mass value="0.01"/>
      <origin xyz="0 0 0"/>
      <inertia ixx="1.6666666666666668e-07" ixy="0.0" ixz="0.0" iyy="1.6666666666666668e-07" iyz="0.0" izz="1.6666666666666668e-07"/>
    </inertial>
  </link>
  <gazebo>
    <plugin filename="libgazebo_ros_create_optical_mouse.so" name="mouse_plugin">
      <ros>
        <namespace>/</namespace>
        <remapping>~/out:=mouse</remapping>
      </ros>
      <update_rate>62</update_rate>
      <link_name>mouse</link_name>
    </plugin>
  </gazebo>
  <gazebo reference="mouse_joint">
    <preserveFixedJoint>true</preserveFixedJoint>
  </gazebo>
  <joint name="cliff_side_left_joint" type="fixed">
    <origin rpy="0 1.3962634015954636 2.921681167838508" xyz="0.06 0.145 0.01920000000000001"/>
    <parent link="base_link"/>
    <child link="cliff_side_left"/>
  </joint>
  <link name="cliff_side_left">
    <inertial>
      <mass value="0.01"/>
      <origin xyz="0 0 0"/>
      <inertia ixx="1.6666666666666668e-07" ixy="0.0" ixz="0.0" iyy="1.6666666666666668e-07" iyz="0.0" izz="1.6666666666666668e-07"/>
    </inertial>
  </link>
  <gazebo reference="cliff_side_left">
    <sensor name="cliff_side_left" type="ray">
      <update_rate>62</update_rate>
      <visualize>False</visualize>
      <always_on>true</always_on>
      <ray>
        <scan>
          <horizontal>
            <samples>1.0</samples>
            <resolution>1.0</resolution>
            <min_angle>-0.04363323129985824</min_angle>
            <max_angle>0.04363323129985824</max_angle>
          </horizontal>
          <vertical>
            <samples>1</samples>
            <resolution>1</resolution>
            <min_angle>0</min_angle>
            <max_angle>0</max_angle>
          </vertical>
        </scan>
        <range>
          <min>0.0001</min>
          <max>0.15</max>
          <resolution>1.0</resolution>
        </range>
      </ray>
      <!-- Noise is currently disabled -->
      <noise>
        <type>gaussian</type>
        <mean>0.0</mean>
        <stddev>0.0</stddev>
      </noise>
      <plugin filename="libgazebo_ros_create_cliff_sensor.so" name="cliff_side_left">
        <ros>
          <namespace>/</namespace>
          <remapping>~/out:=_internal/cliff_side_left/event</remapping>
        </ros>
        <detection_threshold>0.08</detection_threshold>
        <frame_id>cliff_side_left</frame_id>
      </plugin>
    </sensor>
  </gazebo>
  <joint name="cliff_side_right_joint" type="fixed">
    <origin rpy="0 1.3962634015954636 -2.921681167838508" xyz="0.06 -0.145 0.01920000000000001"/>
    <parent link="base_link"/>
    <child link="cliff_side_right"/>
  </joint>
  <link name="cliff_side_right">
    <inertial>
      <mass value="0.01"/>
      <origin xyz="0 0 0"/>
      <inertia ixx="1.6666666666666668e-07" ixy="0.0" ixz="0.0" iyy="1.6666666666666668e-07" iyz="0.0" izz="1.6666666666666668e-07"/>
    </inertial>
  </link>
  <gazebo reference="cliff_side_right">
    <sensor name="cliff_side_right" type="ray">
      <update_rate>62</update_rate>
      <visualize>False</visualize>
      <always_on>true</always_on>
      <ray>
        <scan>
          <horizontal>
            <samples>1.0</samples>
            <resolution>1.0</resolution>
            <min_angle>-0.04363323129985824</min_angle>
            <max_angle>0.04363323129985824</max_angle>
          </horizontal>
          <vertical>
            <samples>1</samples>
            <resolution>1</resolution>
            <min_angle>0</min_angle>
            <max_angle>0</max_angle>
          </vertical>
        </scan>
        <range>
          <min>0.0001</min>
          <max>0.15</max>
          <resolution>1.0</resolution>
        </range>
      </ray>
      <!-- Noise is currently disabled -->
      <noise>
        <type>gaussian</type>
        <mean>0.0</mean>
        <stddev>0.0</stddev>
      </noise>
      <plugin filename="libgazebo_ros_create_cliff_sensor.so" name="cliff_side_right">
        <ros>
          <namespace>/</namespace>
          <remapping>~/out:=_internal/cliff_side_right/event</remapping>
        </ros>
        <detection_threshold>0.08</detection_threshold>
        <frame_id>cliff_side_right</frame_id>
      </plugin>
    </sensor>
  </gazebo>
  <joint name="cliff_front_left_joint" type="fixed">
    <origin rpy="0 1.3962634015954636 1.1397000015522971" xyz="0.16 0.045 0.01920000000000001"/>
    <parent link="base_link"/>
    <child link="cliff_front_left"/>
  </joint>
  <link name="cliff_front_left">
    <inertial>
      <mass value="0.01"/>
      <origin xyz="0 0 0"/>
      <inertia ixx="1.6666666666666668e-07" ixy="0.0" ixz="0.0" iyy="1.6666666666666668e-07" iyz="0.0" izz="1.6666666666666668e-07"/>
    </inertial>
  </link>
  <gazebo reference="cliff_front_left">
    <sensor name="cliff_front_left" type="ray">
      <update_rate>62</update_rate>
      <visualize>False</visualize>
      <always_on>true</always_on>
      <ray>
        <scan>
          <horizontal>
            <samples>1.0</samples>
            <resolution>1.0</resolution>
            <min_angle>-0.04363323129985824</min_angle>
            <max_angle>0.04363323129985824</max_angle>
          </horizontal>
          <vertical>
            <samples>1</samples>
            <resolution>1</resolution>
            <min_angle>0</min_angle>
            <max_angle>0</max_angle>
          </vertical>
        </scan>
        <range>
          <min>0.0001</min>
          <max>0.15</max>
          <resolution>1.0</resolution>
        </range>
      </ray>
      <!-- Noise is currently disabled -->
      <noise>
        <type>gaussian</type>
        <mean>0.0</mean>
        <stddev>0.0</stddev>
      </noise>
      <plugin filename="libgazebo_ros_create_cliff_sensor.so" name="cliff_front_left">
        <ros>
          <namespace>/</namespace>
          <remapping>~/out:=_internal/cliff_front_left/event</remapping>
        </ros>
        <detection_threshold>0.08</detection_threshold>
        <frame_id>cliff_front_left</frame_id>
      </plugin>
    </sensor>
  </gazebo>
  <joint name="cliff_front_right_joint" type="fixed">
    <origin rpy="0 1.3962634015954636 -1.1397000015522971" xyz="0.16 -0.045 0.01920000000000001"/>
    <parent link="base_link"/>
    <child link="cliff_front_right"/>
  </joint>
  <link name="cliff_front_right">
    <inertial>
      <mass value="0.01"/>
      <origin xyz="0 0 0"/>
      <inertia ixx="1.6666666666666668e-07" ixy="0.0" ixz="0.0" iyy="1.6666666666666668e-07" iyz="0.0" izz="1.6666666666666668e-07"/>
    </inertial>
  </link>
  <gazebo reference="cliff_front_right">
    <sensor name="cliff_front_right" type="ray">
      <update_rate>62</update_rate>
      <visualize>False</visualize>
      <always_on>true</always_on>
      <ray>
        <scan>
          <horizontal>
            <samples>1.0</samples>
            <resolution>1.0</resolution>
            <min_angle>-0.04363323129985824</min_angle>
            <max_angle>0.04363323129985824</max_angle>
          </horizontal>
          <vertical>
            <samples>1</samples>
            <resolution>1</resolution>
            <min_angle>0</min_angle>
            <max_angle>0</max_angle>
          </vertical>
        </scan>
        <range>
          <min>0.0001</min>
          <max>0.15</max>
          <resolution>1.0</resolution>
        </range>
      </ray>
      <!-- Noise is currently disabled -->
      <noise>
        <type>gaussian</type>
        <mean>0.0</mean>
        <stddev>0.0</stddev>
      </noise>
      <plugin filename="libgazebo_ros_create_cliff_sensor.so" name="cliff_front_right">
        <ros>
          <namespace>/</namespace>
          <remapping>~/out:=_internal/cliff_front_right/event</remapping>
        </ros>
        <detection_threshold>0.08</detection_threshold>
        <frame_id>cliff_front_right</frame_id>
      </plugin>
    </sensor>
  </gazebo>
  <joint name="ir_intensity_front_center_left_joint" type="fixed">
    <origin xyz="0.1540 0 0.05720000000000001"/>
    <parent link="base_link"/>
    <child link="ir_intensity_front_center_left"/>
  </joint>
  <link name="ir_intensity_front_center_left">
    <inertial>
      <mass value="0.01"/>
      <origin xyz="0 0 0"/>
      <inertia ixx="1.6666666666666668e-07" ixy="0.0" ixz="0.0" iyy="1.6666666666666668e-07" iyz="0.0" izz="1.6666666666666668e-07"/>
    </inertial>
  </link>
  <gazebo reference="ir_intensity_front_center_left_joint">
    <preserveFixedJoint>true</preserveFixedJoint>
  </gazebo>
  <gazebo reference="ir_intensity_front_center_left">
    <sensor name="ir_intensity_front_center_left" type="ray">
      <update_rate>62.0</update_rate>
      <visualize>False</visualize>
      <always_on>true</always_on>
      <ray>
        <scan>
          <horizontal>
            <samples>5</samples>
            <resolution>1.0</resolution>
            <min_angle>-0.08726646259971647</min_angle>
            <max_angle>0.08726646259971647</max_angle>
          </horizontal>
          <vertical>
            <samples>5</samples>
            <resolution>1.0</resolution>
            <min_angle>-0.08726646259971647</min_angle>
            <max_angle>0.08726646259971647</max_angle>
          </vertical>
        </scan>
        <range>
          <min>0.025</min>
          <max>0.2</max>
          <resolution>1.0</resolution>
        </range>
      </ray>
      <!-- Noise is currently disabled -->
      <noise>
        <type>gaussian</type>
        <mean>0.0</mean>
        <stddev>0.0</stddev>
      </noise>
      <plugin filename="libgazebo_ros_create_ir_intensity_sensor.so" name="ir_intensity_front_center_left">
        <ros>
          <namespace>/</namespace>
          <remapping>~/out:=_internal/ir_intensity_front_center_left</remapping>
        </ros>
      </plugin>
    </sensor>
  </gazebo>
  <joint name="ir_intensity_front_center_right_joint" type="fixed">
    <origin rpy="0 0 -0.436" xyz="0.1396 -0.0651 0.05720000000000001"/>
    <parent link="base_link"/>
    <child link="ir_intensity_front_center_right"/>
  </joint>
  <link name="ir_intensity_front_center_right">
    <inertial>
      <mass value="0.01"/>
      <origin xyz="0 0 0"/>
      <inertia ixx="1.6666666666666668e-07" ixy="0.0" ixz="0.0" iyy="1.6666666666666668e-07" iyz="0.0" izz="1.6666666666666668e-07"/>
    </inertial>
  </link>
  <gazebo reference="ir_intensity_front_center_right_joint">
    <preserveFixedJoint>true</preserveFixedJoint>
  </gazebo>
  <gazebo reference="ir_intensity_front_center_right">
    <sensor name="ir_intensity_front_center_right" type="ray">
      <update_rate>62.0</update_rate>
      <visualize>False</visualize>
      <always_on>true</always_on>
      <ray>
        <scan>
          <horizontal>
            <samples>5</samples>
            <resolution>1.0</resolution>
            <min_angle>-0.08726646259971647</min_angle>
            <max_angle>0.08726646259971647</max_angle>
          </horizontal>
          <vertical>
            <samples>5</samples>
            <resolution>1.0</resolution>
            <min_angle>-0.08726646259971647</min_angle>
            <max_angle>0.08726646259971647</max_angle>
          </vertical>
        </scan>
        <range>
          <min>0.025</min>
          <max>0.2</max>
          <resolution>1.0</resolution>
        </range>
      </ray>
      <!-- Noise is currently disabled -->
      <noise>
        <type>gaussian</type>
        <mean>0.0</mean>
        <stddev>0.0</stddev>
      </noise>
      <plugin filename="libgazebo_ros_create_ir_intensity_sensor.so" name="ir_intensity_front_center_right">
        <ros>
          <namespace>/</namespace>
          <remapping>~/out:=_internal/ir_intensity_front_center_right</remapping>
        </ros>
      </plugin>
    </sensor>
  </gazebo>
  <joint name="ir_intensity_front_left_joint" type="fixed">
    <origin rpy="0 0 0.436" xyz="0.1396 0.0651 0.05720000000000001"/>
    <parent link="base_link"/>
    <child link="ir_intensity_front_left"/>
  </joint>
  <link name="ir_intensity_front_left">
    <inertial>
      <mass value="0.01"/>
      <origin xyz="0 0 0"/>
      <inertia ixx="1.6666666666666668e-07" ixy="0.0" ixz="0.0" iyy="1.6666666666666668e-07" iyz="0.0" izz="1.6666666666666668e-07"/>
    </inertial>
  </link>
  <gazebo reference="ir_intensity_front_left_joint">
    <preserveFixedJoint>true</preserveFixedJoint>
  </gazebo>
  <gazebo reference="ir_intensity_front_left">
    <sensor name="ir_intensity_front_left" type="ray">
      <update_rate>62.0</update_rate>
      <visualize>False</visualize>
      <always_on>true</always_on>
      <ray>
        <scan>
          <horizontal>
            <samples>5</samples>
            <resolution>1.0</resolution>
            <min_angle>-0.08726646259971647</min_angle>
            <max_angle>0.08726646259971647</max_angle>
          </horizontal>
          <vertical>
            <samples>5</samples>
            <resolution>1.0</resolution>
            <min_angle>-0.08726646259971647</min_angle>
            <max_angle>0.08726646259971647</max_angle>
          </vertical>
        </scan>
        <range>
          <min>0.025</min>
          <max>0.2</max>
          <resolution>1.0</resolution>
        </range>
      </ray>
      <!-- Noise is currently disabled -->
      <noise>
        <type>gaussian</type>
        <mean>0.0</mean>
        <stddev>0.0</stddev>
      </noise>
      <plugin filename="libgazebo_ros_create_ir_intensity_sensor.so" name="ir_intensity_front_left">
        <ros>
          <namespace>/</namespace>
          <remapping>~/out:=_internal/ir_intensity_front_left</remapping>
        </ros>
      </plugin>
    </sensor>
  </gazebo>
  <joint name="ir_intensity_front_right_joint" type="fixed">
    <origin rpy="0 0 -0.873" xyz="0.0990 -0.1180 0.05720000000000001"/>
    <parent link="base_link"/>
    <child link="ir_intensity_front_right"/>
  </joint>
  <link name="ir_intensity_front_right">
    <inertial>
      <mass value="0.01"/>
      <origin xyz="0 0 0"/>
      <inertia ixx="1.6666666666666668e-07" ixy="0.0" ixz="0.0" iyy="1.6666666666666668e-07" iyz="0.0" izz="1.6666666666666668e-07"/>
    </inertial>
  </link>
  <gazebo reference="ir_intensity_front_right_joint">
    <preserveFixedJoint>true</preserveFixedJoint>
  </gazebo>
  <gazebo reference="ir_intensity_front_right">
    <sensor name="ir_intensity_front_right" type="ray">
      <update_rate>62.0</update_rate>
      <visualize>False</visualize>
      <always_on>true</always_on>
      <ray>
        <scan>
          <horizontal>
            <samples>5</samples>
            <resolution>1.0</resolution>
            <min_angle>-0.08726646259971647</min_angle>
            <max_angle>0.08726646259971647</max_angle>
          </horizontal>
          <vertical>
            <samples>5</samples>
            <resolution>1.0</resolution>
            <min_angle>-0.08726646259971647</min_angle>
            <max_angle>0.08726646259971647</max_angle>
          </vertical>
        </scan>
        <range>
          <min>0.025</min>
          <max>0.2</max>
          <resolution>1.0</resolution>
        </range>
      </ray>
      <!-- Noise is currently disabled -->
      <noise>
        <type>gaussian</type>
        <mean>0.0</mean>
        <stddev>0.0</stddev>
      </noise>
      <plugin filename="libgazebo_ros_create_ir_intensity_sensor.so" name="ir_intensity_front_right">
        <ros>
          <namespace>/</namespace>
          <remapping>~/out:=_internal/ir_intensity_front_right</remapping>
        </ros>
      </plugin>
    </sensor>
  </gazebo>
  <joint name="ir_intensity_left_joint" type="fixed">
    <origin rpy="0 0 0.873" xyz="0.0990 0.1180 0.05720000000000001"/>
    <parent link="base_link"/>
    <child link="ir_intensity_left"/>
  </joint>
  <link name="ir_intensity_left">
    <inertial>
      <mass value="0.01"/>
      <origin xyz="0 0 0"/>
      <inertia ixx="1.6666666666666668e-07" ixy="0.0" ixz="0.0" iyy="1.6666666666666668e-07" iyz="0.0" izz="1.6666666666666668e-07"/>
    </inertial>
  </link>
  <gazebo reference="ir_intensity_left_joint">
    <preserveFixedJoint>true</preserveFixedJoint>
  </gazebo>
  <gazebo reference="ir_intensity_left">
    <sensor name="ir_intensity_left" type="ray">
      <update_rate>62.0</update_rate>
      <visualize>False</visualize>
      <always_on>true</always_on>
      <ray>
        <scan>
          <horizontal>
            <samples>5</samples>
            <resolution>1.0</resolution>
            <min_angle>-0.08726646259971647</min_angle>
            <max_angle>0.08726646259971647</max_angle>
          </horizontal>
          <vertical>
            <samples>5</samples>
            <resolution>1.0</resolution>
            <min_angle>-0.08726646259971647</min_angle>
            <max_angle>0.08726646259971647</max_angle>
          </vertical>
        </scan>
        <range>
          <min>0.025</min>
          <max>0.2</max>
          <resolution>1.0</resolution>
        </range>
      </ray>
      <!-- Noise is currently disabled -->
      <noise>
        <type>gaussian</type>
        <mean>0.0</mean>
        <stddev>0.0</stddev>
      </noise>
      <plugin filename="libgazebo_ros_create_ir_intensity_sensor.so" name="ir_intensity_left">
        <ros>
          <namespace>/</namespace>
          <remapping>~/out:=_internal/ir_intensity_left</remapping>
        </ros>
      </plugin>
    </sensor>
  </gazebo>
  <joint name="ir_intensity_right_joint" type="fixed">
    <origin rpy="0 0 -1.309" xyz="0.0399 -0.1488 0.05720000000000001"/>
    <parent link="base_link"/>
    <child link="ir_intensity_right"/>
  </joint>
  <link name="ir_intensity_right">
    <inertial>
      <mass value="0.01"/>
      <origin xyz="0 0 0"/>
      <inertia ixx="1.6666666666666668e-07" ixy="0.0" ixz="0.0" iyy="1.6666666666666668e-07" iyz="0.0" izz="1.6666666666666668e-07"/>
    </inertial>
  </link>
  <gazebo reference="ir_intensity_right_joint">
    <preserveFixedJoint>true</preserveFixedJoint>
  </gazebo>
  <gazebo reference="ir_intensity_right">
    <sensor name="ir_intensity_right" type="ray">
      <update_rate>62.0</update_rate>
      <visualize>False</visualize>
      <always_on>true</always_on>
      <ray>
        <scan>
          <horizontal>
            <samples>5</samples>
            <resolution>1.0</resolution>
            <min_angle>-0.08726646259971647</min_angle>
            <max_angle>0.08726646259971647</max_angle>
          </horizontal>
          <vertical>
            <samples>5</samples>
            <resolution>1.0</resolution>
            <min_angle>-0.08726646259971647</min_angle>
            <max_angle>0.08726646259971647</max_angle>
          </vertical>
        </scan>
        <range>
          <min>0.025</min>
          <max>0.2</max>
          <resolution>1.0</resolution>
        </range>
      </ray>
      <!-- Noise is currently disabled -->
      <noise>
        <type>gaussian</type>
        <mean>0.0</mean>
        <stddev>0.0</stddev>
      </noise>
      <plugin filename="libgazebo_ros_create_ir_intensity_sensor.so" name="ir_intensity_right">
        <ros>
          <namespace>/</namespace>
          <remapping>~/out:=_internal/ir_intensity_right</remapping>
        </ros>
      </plugin>
    </sensor>
  </gazebo>
  <joint name="ir_intensity_side_left_joint" type="fixed">
    <origin rpy="0 0 1.309" xyz="0.0399 0.1488 0.05720000000000001"/>
    <parent link="base_link"/>
    <child link="ir_intensity_side_left"/>
  </joint>
  <link name="ir_intensity_side_left">
    <inertial>
      <mass value="0.01"/>
      <origin xyz="0 0 0"/>
      <inertia ixx="1.6666666666666668e-07" ixy="0.0" ixz="0.0" iyy="1.6666666666666668e-07" iyz="0.0" izz="1.6666666666666668e-07"/>
    </inertial>
  </link>
  <gazebo reference="ir_intensity_side_left_joint">
    <preserveFixedJoint>true</preserveFixedJoint>
  </gazebo>
  <gazebo reference="ir_intensity_side_left">
    <sensor name="ir_intensity_side_left" type="ray">
      <update_rate>62.0</update_rate>
      <visualize>False</visualize>
      <always_on>true</always_on>
      <ray>
        <scan>
          <horizontal>
            <samples>5</samples>
            <resolution>1.0</resolution>
            <min_angle>-0.08726646259971647</min_angle>
            <max_angle>0.08726646259971647</max_angle>
          </horizontal>
          <vertical>
            <samples>5</samples>
            <resolution>1.0</resolution>
            <min_angle>-0.08726646259971647</min_angle>
            <max_angle>0.08726646259971647</max_angle>
          </vertical>
        </scan>
        <range>
          <min>0.025</min>
          <max>0.2</max>
          <resolution>1.0</resolution>
        </range>
      </ray>
      <!-- Noise is currently disabled -->
      <noise>
        <type>gaussian</type>
        <mean>0.0</mean>
        <stddev>0.0</stddev>
      </noise>
      <plugin filename="libgazebo_ros_create_ir_intensity_sensor.so" name="ir_intensity_side_left">
        <ros>
          <namespace>/</namespace>
          <remapping>~/out:=_internal/ir_intensity_side_left</remapping>
        </ros>
      </plugin>
    </sensor>
  </gazebo>
  <joint name="button_1_joint" type="fixed">
    <parent link="base_link"/>
    <child link="button_1"/>
    <origin rpy="0 -1.5707963267948966 0" xyz="0.06 0.37 0.1442"/>
  </joint>
  <link name="button_1"/>
  <joint name="button_2_joint" type="fixed">
    <parent link="base_link"/>
    <child link="button_2"/>
    <origin rpy="0 -1.5707963267948966 0" xyz="0.06 -0.37 0.1442"/>
  </joint>
  <link name="button_2"/>
  <joint name="button_power_joint" type="fixed">
    <parent link="base_link"/>
    <child link="button_power"/>
    <origin rpy="0 -1.5707963267948966 0" xyz="0.06 0 0.1442"/>
  </joint>
  <link name="button_power"/>
  <joint name="ir_omni_joint" type="fixed">
    <origin xyz="0.153 0 0.09920000000000001"/>
    <parent link="base_link"/>
    <child link="ir_omni"/>
  </joint>
  <link name="ir_omni">
    <inertial>
      <mass value="0.01"/>
      <origin xyz="0 0 0"/>
      <inertia ixx="1.6666666666666668e-07" ixy="0.0" ixz="0.0" iyy="1.6666666666666668e-07" iyz="0.0" izz="1.6666666666666668e-07"/>
    </inertial>
  </link>
  <gazebo>
    <plugin filename="libgazebo_ros_create_ir_opcode.so" name="ir_omni_plugin">
      <ros>
        <namespace>/</namespace>
        <remapping>~/out:=ir_opcode</remapping>
      </ros>
      <update_rate>31</update_rate>
      <robot_model_name>create3</robot_model_name>
      <receiver_link_name>ir_omni</receiver_link_name>
      <dock_model_name>standard_dock</dock_model_name>
      <emitter_link_name>halo_link</emitter_link_name>
      <sensor_0_fov>3.839724354387525</sensor_0_fov>
      <sensor_0_range>0.01</sensor_0_range>
      <sensor_1_fov>1.5707963267948966</sensor_1_fov>
      <sensor_1_range>0.5</sensor_1_range>
    </plugin>
  </gazebo>
  <gazebo reference="ir_omni_joint">
    <preserveFixedJoint>true</preserveFixedJoint>
  </gazebo>
  <!-- Ground truth pose -->
  <gazebo>
    <plugin filename="libgazebo_ros_p3d.so" name="gazebo_ros_p3d_robot">
      <ros>
        <namespace>/</namespace>
        <remapping>odom:=sim_ground_truth_pose</remapping>
      </ros>
      <body_name>base_link</body_name>
      <frame_name>world</frame_name>
      <update_rate>62</update_rate>
      <xyz_offset>0 0 0</xyz_offset>
      <rpy_offset>0.0 0.0 0.0</rpy_offset>
      <gaussian_noise>0.0</gaussian_noise>
    </plugin>
  </gazebo>
  <!-- Dock status -->
  <gazebo>
    <plugin filename="libgazebo_ros_create_docking_status.so" name="dock_status_publisher">
      <ros>
        <namespace>/</namespace>
        <remapping>~/out:=dock</remapping>
      </ros>
      <update_rate>1.0</update_rate>
      <robot_model_name>create3</robot_model_name>
      <receiver_link_name>ir_omni</receiver_link_name>
      <dock_model_name>standard_dock</dock_model_name>
      <emitter_link_name>halo_link</emitter_link_name>
    </plugin>
  </gazebo>
  <!-- Turtlebot4 sensor definitions -->
  <joint name="rplidar_joint" type="fixed">
    <parent link="base_link"/>
    <child link="rplidar_link"/>
    <origin rpy="0 0 1.5707963267948966" xyz="0.00393584 0.0 0.13949272000000001"/>
  </joint>
  <link name="rplidar_link">
    <visual>
      <geometry>
        <mesh filename="package://turtlebot4_description/meshes/rplidar.dae" scale="1 1 1"/>
      </geometry>
    </visual>
    <collision>
      <origin xyz="0.0 0.013000000000000001 -0.019"/>
      <geometry>
        <box size="0.071 0.1 0.06"/>
      </geometry>
    </collision>
    <inertial>
      <mass value="0.17"/>
      <origin xyz="0 0 0"/>
      <inertia ixx="0.0001926666666666667" ixy="0.0" ixz="0.0" iyy="0.00012241416666666666" iyz="0.0" izz="0.00021308083333333337"/>
    </inertial>
  </link>
  <gazebo reference="rplidar_link">
    <sensor name="rplidar" type="ray">
      <update_rate>62.0</update_rate>
      <visualize>1</visualize>
      <always_on>true</always_on>
      <ray>
        <scan>
          <horizontal>
            <samples>640</samples>
            <resolution>1.0</resolution>
            <min_angle>-3.141592653589793</min_angle>
            <max_angle>3.141592653589793</max_angle>
          </horizontal>
          <vertical>
            <samples>1</samples>
            <resolution>1</resolution>
            <min_angle>0</min_angle>
            <max_angle>0</max_angle>
          </vertical>
        </scan>
        <range>
          <min>0.164</min>
          <max>12.0</max>
          <resolution>0.01</resolution>
        </range>
      </ray>
      <!-- Noise is currently disabled -->
      <noise>
        <type>gaussian</type>
        <mean>0.0</mean>
        <stddev>0.0</stddev>
      </noise>
      <plugin filename="dummyfile" name="dummy"/>
    </sensor>
    <visual>
      <material>
        <diffuse>0.011764705882352941 0.011764705882352941 0.011764705882352941 1</diffuse>
        <specular>0 0 0 1</specular>
        <emissive>0 0 0 1</emissive>
      </material>
    </visual>
  </gazebo>
  <gazebo reference="rplidar_joint">
    <preserveFixedJoint>true</preserveFixedJoint>
  </gazebo>
  <joint name="oakd_lite_camera_bracket_joint" type="fixed">
    <parent link="base_link"/>
    <child link="oakd_lite_camera_bracket"/>
    <origin xyz="-0.09 0.0 0.09334772000000001"/>
  </joint>
  <link name="oakd_lite_camera_bracket">
    <visual>
      <geometry>
        <mesh filename="package://turtlebot4_description/meshes/camera_bracket.dae" scale="1 1 1"/>
      </geometry>
    </visual>
    <inertial>
      <mass value="0.033"/>
      <inertia ixx="0.0000579181" ixy="0.0" ixz="0.0000090679" iyy="0.0000559785" iyz="0.0" izz="0.0000140955"/>
    </inertial>
  </link>
  <gazebo reference="oakd_lite_camera_bracket_joint">
    <preserveFixedJoint>true</preserveFixedJoint>
  </gazebo>
  <gazebo reference="oakd_lite_camera_bracket">
    <visual>
      <material>
        <diffuse>0 0 0 1</diffuse>
        <specular>0.3137254901960784 0.3137254901960784 0.3137254901960784 1</specular>
        <emissive>0 0 0 1</emissive>
      </material>
    </visual>
  </gazebo>
  <!-- Base frame -->
  <joint name="oakd_lite_joint" type="fixed">
    <parent link="oakd_lite_camera_bracket"/>
    <child link="oakd_lite_link"/>
    <origin xyz="0.052940259999999996 0.0 0.0925385"/>
  </joint>
  <link name="oakd_lite_link">
    <visual>
      <geometry>
        <mesh filename="package://turtlebot4_description/meshes/oakd_lite.dae" scale="1 1 1"/>
      </geometry>
    </visual>
    <collision>
      <origin xyz="-0.011000000000000001 0.0 -0.005"/>
      <geometry>
        <box size="0.0225 0.09699999999999999 0.03"/>
      </geometry>
    </collision>
    <inertial>
      <mass value="0.061"/>
      <inertia ixx="0.00000202475" ixy="0.0" ixz="0.0" iyy="0.00001527320" iyz="0.0" izz="0.00001605536"/>
    </inertial>
  </link>
  <!-- RGB Camera -->
  <link name="oakd_lite_rgb_camera_frame">
    <inertial>
      <mass value="0.01"/>
      <origin xyz="0 0 0"/>
      <inertia ixx="1.6666666666666668e-07" ixy="0.0" ixz="0.0" iyy="1.6666666666666668e-07" iyz="0.0" izz="1.6666666666666668e-07"/>
    </inertial>
  </link>
  <joint name="oakd_lite_rgb_camera_joint" type="fixed">
    <parent link="oakd_lite_link"/>
    <child link="oakd_lite_rgb_camera_frame"/>
    <origin rpy="0 0 0" xyz="0 0 0"/>
  </joint>
  <link name="oakd_lite_rgb_camera_optical_frame">
    <inertial>
      <mass value="0.01"/>
      <origin xyz="0 0 0"/>
      <inertia ixx="1.6666666666666668e-07" ixy="0.0" ixz="0.0" iyy="1.6666666666666668e-07" iyz="0.0" izz="1.6666666666666668e-07"/>
    </inertial>
  </link>
  <joint name="oakd_lite_rgb_camera_optical_joint" type="fixed">
    <origin rpy="-1.5707963267948966 0.0 -1.5707963267948966" xyz="0 0 0"/>
    <parent link="oakd_lite_rgb_camera_frame"/>
    <child link="oakd_lite_rgb_camera_optical_frame"/>
  </joint>
  <!-- Left Camera -->
  <link name="oakd_lite_left_camera_frame">
    <inertial>
      <mass value="0.01"/>
      <origin xyz="0 0 0"/>
      <inertia ixx="1.6666666666666668e-07" ixy="0.0" ixz="0.0" iyy="1.6666666666666668e-07" iyz="0.0" izz="1.6666666666666668e-07"/>
    </inertial>
  </link>
  <joint name="oakd_lite_left_camera_joint" type="fixed">
    <parent link="oakd_lite_link"/>
    <child link="oakd_lite_left_camera_frame"/>
    <origin rpy="0 0 0" xyz="0 0.0375 0"/>
  </joint>
  <link name="oakd_lite_left_camera_optical_frame">
    <inertial>
      <mass value="0.01"/>
      <origin xyz="0 0 0"/>
      <inertia ixx="1.6666666666666668e-07" ixy="0.0" ixz="0.0" iyy="1.6666666666666668e-07" iyz="0.0" izz="1.6666666666666668e-07"/>
    </inertial>
  </link>
  <joint name="oakd_lite_left_camera_optical_joint" type="fixed">
    <origin rpy="-1.5707963267948966 0.0 -1.5707963267948966" xyz="0 0 0"/>
    <parent link="oakd_lite_left_camera_frame"/>
    <child link="oakd_lite_left_camera_optical_frame"/>
  </joint>
  <!-- Right Camera -->
  <link name="oakd_lite_right_camera_frame">
    <inertial>
      <mass value="0.01"/>
      <origin xyz="0 0 0"/>
      <inertia ixx="1.6666666666666668e-07" ixy="0.0" ixz="0.0" iyy="1.6666666666666668e-07" iyz="0.0" izz="1.6666666666666668e-07"/>
    </inertial>
  </link>
  <joint name="oakd_lite_right_camera_joint" type="fixed">
    <parent link="oakd_lite_link"/>
    <child link="oakd_lite_right_camera_frame"/>
    <origin rpy="0 0 0" xyz="0 -0.0375 0"/>
  </joint>
  <link name="oakd_lite_right_camera_optical_frame">
    <inertial>
      <mass value="0.01"/>
      <origin xyz="0 0 0"/>
      <inertia ixx="1.6666666666666668e-07" ixy="0.0" ixz="0.0" iyy="1.6666666666666668e-07" iyz="0.0" izz="1.6666666666666668e-07"/>
    </inertial>
  </link>
  <joint name="oakd_lite_right_camera_optical_joint" type="fixed">
    <origin rpy="-1.5707963267948966 0.0 -1.5707963267948966" xyz="0 0 0"/>
    <parent link="oakd_lite_right_camera_frame"/>
    <child link="oakd_lite_right_camera_optical_frame"/>
  </joint>
  <!-- IMU -->
  <link name="oakd_lite_imu_frame">
    <inertial>
      <mass value="0.01"/>
      <origin xyz="0 0 0"/>
      <inertia ixx="1.6666666666666668e-07" ixy="0.0" ixz="0.0" iyy="1.6666666666666668e-07" iyz="0.0" izz="1.6666666666666668e-07"/>
    </inertial>
  </link>
  <joint name="oakd_lite_imu_joint" type="fixed">
    <parent link="oakd_lite_link"/>
    <child link="oakd_lite_imu_frame"/>
    <origin rpy="-1.5707963267948966 0 -1.5707963267948966" xyz="0 0 0"/>
  </joint>
  <!-- Gazebo links and joints -->
  <gazebo reference="oakd_lite_rgb_camera_frame">
    <sensor name="rgbd_camera" type="rgbd_camera">
      <camera>
        <horizontal_fov>1.25</horizontal_fov>
        <image>
          <width>320</width>
          <height>240</height>
        </image>
        <clip>
          <near>0.3</near>
          <far>100</far>
        </clip>
      </camera>
      <always_on>1</always_on>
      <update_rate>30</update_rate>
      <visualize>true</visualize>
    </sensor>
    <visual>
      <material>
        <diffuse>0.011764705882352941 0.011764705882352941 0.011764705882352941 1</diffuse>
        <specular>0 0 0 1</specular>
        <emissive>0 0 0 1</emissive>
      </material>
    </visual>
  </gazebo>
  <gazebo reference="oakd_lite_joint">
    <preserveFixedJoint>true</preserveFixedJoint>
  </gazebo>
  <gazebo reference="oakd_lite_rgb_camera_joint">
    <preserveFixedJoint>true</preserveFixedJoint>
  </gazebo>
  <gazebo reference="oakd_lite_rgb_camera_optical_joint">
    <preserveFixedJoint>true</preserveFixedJoint>
  </gazebo>
  <gazebo reference="oakd_lite_left_camera_joint">
    <preserveFixedJoint>true</preserveFixedJoint>
  </gazebo>
  <gazebo reference="oakd_lite_left_camera_optical_joint">
    <preserveFixedJoint>true</preserveFixedJoint>
  </gazebo>
  <gazebo reference="oakd_lite_right_camera_joint">
    <preserveFixedJoint>true</preserveFixedJoint>
  </gazebo>
  <gazebo reference="oakd_lite_right_camera_optical_joint">
    <preserveFixedJoint>true</preserveFixedJoint>
  </gazebo>
  <gazebo reference="oakd_lite_imu_joint">
    <preserveFixedJoint>true</preserveFixedJoint>
  </gazebo>
  <link name="world">
  </link>
  <joint name="tb4_base_joint" type="fixed">
    <parent link="world"/>
    <child link="base_link"/>
    <origin rpy="0 0 0" xyz="0 0 0"/>
  </joint>
  <joint name="lss_arm_base_joint" type="fixed">
    <parent link="base_link"/>
    <child link="lss_arm_base_link"/>
    <origin rpy="0 0 0" xyz="0 0 0"/>
  </joint>
  <link name="lss_arm_base_link">
    <visual>
      <origin rpy="0 0 0" xyz="0 0 0"/>
      <geometry>
        <mesh filename="package://lss_arm_description/meshes/visual/lss_base.STL"/>
      </geometry>
      <material name="">
        <color rgba="0.3 0.3 0.3 1"/>
      </material>
    </visual>
    <collision>
      <origin rpy="0 0 0" xyz="0 0 0"/>
      <geometry>
        <mesh filename="package://lss_arm_description/meshes/collision/lss_base.STL"/>
      </geometry>
    </collision>
    <inertial>
      <origin rpy="0 0 0" xyz="0 0 0"/>
      <mass value="0.05"/>
      <inertia ixx="4.17127E-06" ixy="-5.07076E-17" ixz="-8.99321E-15" iyy="8.84892E-06" iyz="5.22561E-14" izz="4.67905E-06"/>
    </inertial>
  </link>
  <gazebo reference="lss_arm_base_link">
    <mu1 value="0.3"/>
    <mu2 value="0.3"/>
  </gazebo>
  <ros2_control name="lss_arm_system" type="system">
    <hardware>
      <plugin>ign_ros2_control/IgnitionSystem</plugin>
    </hardware>
    <joint name="lss_arm_joint1">
      <param name="initial_position">0.0</param>
      <command_interface name="effort"/>
      <state_interface name="position"/>
      <state_interface name="velocity"/>
      <state_interface name="effort"/>
    </joint>
    <joint name="lss_arm_joint2">
      <param name="initial_position">0.8</param>
      <command_interface name="effort"/>
      <state_interface name="position"/>
      <state_interface name="velocity"/>
      <state_interface name="effort"/>
    </joint>
    <joint name="lss_arm_joint3">
      <param name="initial_position">-0.4</param>
      <command_interface name="effort"/>
      <state_interface name="position"/>
      <state_interface name="velocity"/>
      <state_interface name="effort"/>
    </joint>
    <joint name="lss_arm_joint4">
      <param name="initial_position">-0.4</param>
      <command_interface name="effort"/>
      <state_interface name="position"/>
      <state_interface name="velocity"/>
      <state_interface name="effort"/>
    </joint>
  </ros2_control>
  <joint name="lss_arm_joint0" type="fixed">
    <parent link="lss_arm_base_link"/>
    <child link="lss_arm_link_0"/>
    <origin rpy="0 0 0" xyz="0.063 0 0.2"/>
  </joint>
  <link name="lss_arm_link_0">
    <visual>
      <origin rpy="0 0 0" xyz="0 0 0"/>
      <geometry>
        <mesh filename="package://lss_arm_description/meshes/visual/link_0.STL"/>
      </geometry>
      <material name="">
        <color rgba="0.3 0.3 0.3 1"/>
      </material>
    </visual>
    <collision>
      <origin rpy="0 0 0" xyz="0 0 0"/>
      <geometry>
        <mesh filename="package://lss_arm_description/meshes/collision/link_0.STL"/>
      </geometry>
    </collision>
    <inertial>
      <origin rpy="0 0 0" xyz="-2.73691915043146E-09 0.0078496161601494 0.0255901951226594"/>
      <mass value="0.0717410813666018"/>
      <inertia ixx="3.0636904073993E-05" ixy="9.19910875697947E-11" ixz="-6.99542916495097E-14" iyy="2.37381054307842E-05" iyz="2.14417631554388E-07" izz="4.37325540149466E-05"/>
    </inertial>
  </link>
  <gazebo reference="lss_arm_link_0">
    <mu1 value="0.3"/>
    <mu2 value="0.3"/>
  </gazebo>
  <joint name="lss_arm_joint1" type="revolute">
    <parent link="lss_arm_link_0"/>
    <child link="lss_arm_link_1"/>
    <origin rpy="1.5707963267948966 0 0" xyz="0 0 0.042699975"/>
    <axis xyz="0 1 0"/>
    <limit effort="6.5687857" lower="-3.141592653589793" upper="3.141592653589793" velocity="6.283"/>
    <dynamics damping="0.01" friction="3.48"/>
  </joint>
  <transmission name="lss_arm_joint1_transmission">
    <type>transmission_interface/SimpleTransmission</type>
    <joint name="lss_arm_joint1">
      <hardwareInterface>hardware_interface/EffortJointInterface</hardwareInterface>
    </joint>
    <actuator name="lss_arm_joint1_actuator">
      <mechanicalReduction>1</mechanicalReduction>
    </actuator>
  </transmission>
  <gazebo reference="lss_arm_joint1">
    <springStiffness value="0.0"/>
    <springReference value="0.0"/>
  </gazebo>
  <link name="lss_arm_link_1">
    <visual>
      <origin rpy="0 0 0" xyz="0 0 0"/>
      <geometry>
        <mesh filename="package://lss_arm_description/meshes/visual/link_1.STL"/>
      </geometry>
      <material name="">
        <color rgba="0.3 0.3 0.3 1"/>
      </material>
    </visual>
    <collision>
      <origin rpy="0 0 0" xyz="0 0 0"/>
      <geometry>
        <mesh filename="package://lss_arm_description/meshes/collision/link_1.STL"/>
      </geometry>
    </collision>
    <inertial>
      <origin rpy="0 0 0" xyz="1.5578217768027E-09 0.0348051841749016 0.00014951767591631"/>
      <mass value="0.0628875763471834"/>
      <inertia ixx="2.20425725995968E-05" ixy="9.19935112458848E-11" ixz="1.70368679861891E-13" iyy="2.29485908974563E-05" iyz="-2.19524118186986E-07" izz="1.89578527653699E-05"/>
    </inertial>
  </link>
  <gazebo reference="lss_arm_link_1">
    <mu1 value="0.3"/>
    <mu2 value="0.3"/>
  </gazebo>
  <joint name="lss_arm_joint2" type="revolute">
    <parent link="lss_arm_link_1"/>
    <child link="lss_arm_link_2"/>
    <origin rpy="0 0 -1.3621104667496" xyz="0 0.0588000249999991 0"/>
    <axis xyz="0 0 1"/>
    <limit effort="6.5687857" lower="-1.5707963267948966" upper="1.5707963267948966" velocity="6.283"/>
    <dynamics damping="0.01" friction="3.48"/>
  </joint>
  <transmission name="lss_arm_joint2_transmission">
    <type>transmission_interface/SimpleTransmission</type>
    <joint name="lss_arm_joint2">
      <hardwareInterface>hardware_interface/EffortJointInterface</hardwareInterface>
    </joint>
    <actuator name="lss_arm_joint2_actuator">
      <mechanicalReduction>1</mechanicalReduction>
    </actuator>
  </transmission>
  <gazebo reference="lss_arm_joint2">
    <springStiffness value="0.0"/>
    <springReference value="0.0"/>
  </gazebo>
  <link name="lss_arm_link_2">
    <visual>
      <origin rpy="0 0 0" xyz="0 0 0"/>
      <geometry>
        <mesh filename="package://lss_arm_description/meshes/visual/link_2.STL"/>
      </geometry>
      <material name="">
        <color rgba="0.3 0.3 0.3 1"/>
      </material>
    </visual>
    <collision>
      <origin rpy="0 0 0" xyz="0 0 0"/>
      <geometry>
        <mesh filename="package://lss_arm_description/meshes/collision/link_2.STL"/>
      </geometry>
    </collision>
    <inertial>
      <origin rpy="0 0 0" xyz="-0.112045323028693 0.0336416089233315 0.000234166707606796"/>
      <mass value="0.0592207297890142"/>
      <inertia ixx="1.66333998725443E-05" ixy="-1.03352394963547E-06" ixz="-4.43274108116386E-08" iyy="1.1971383214163E-05" iyz="-2.15005479062966E-07" izz="1.41577057658295E-05"/>
    </inertial>
  </link>
  <gazebo reference="lss_arm_link_2">
    <mu1 value="0.3"/>
    <mu2 value="0.3"/>
  </gazebo>
  <joint name="lss_arm_joint3" type="revolute">
    <parent link="lss_arm_link_2"/>
    <child link="lss_arm_link_3"/>
    <origin rpy="0 0 1.02985068022995" xyz="-0.12954806230389 0.0533975613048809 0"/>
    <axis xyz="0 0 1"/>
    <limit effort="6.5687857" lower="-1.5707963267948966" upper="1.5707963267948966" velocity="6.283"/>
    <dynamics damping="0.01" friction="3.48"/>
  </joint>
  <transmission name="lss_arm_joint3_transmission">
    <type>transmission_interface/SimpleTransmission</type>
    <joint name="lss_arm_joint3">
      <hardwareInterface>hardware_interface/EffortJointInterface</hardwareInterface>
    </joint>
    <actuator name="lss_arm_joint3_actuator">
      <mechanicalReduction>1</mechanicalReduction>
    </actuator>
  </transmission>
  <gazebo reference="lss_arm_joint3">
    <springStiffness value="0.0"/>
    <springReference value="0.0"/>
  </gazebo>
  <link name="lss_arm_link_3">
    <visual>
      <origin rpy="0 0 0" xyz="0 0 0"/>
      <geometry>
        <mesh filename="package://lss_arm_description/meshes/visual/link_3.STL"/>
      </geometry>
      <material name="">
        <color rgba="0.3 0.3 0.3 1"/>
      </material>
    </visual>
    <collision>
      <origin rpy="0 0 0" xyz="0 0 0"/>
      <geometry>
        <mesh filename="package://lss_arm_description/meshes/collision/link_3.STL"/>
      </geometry>
    </collision>
    <inertial>
      <origin rpy="0 0 0" xyz="0.119623138465818 0.0411506770766876 0.000345214465821365"/>
      <mass value="0.0601490353124708"/>
      <inertia ixx="1.1113660383281E-05" ixy="-2.67466932607218E-06" ixz="2.01605698642722E-07" iyy="1.79419649434231E-05" iyz="-6.9564477599757E-08" izz="1.45807099366603E-05"/>
    </inertial>
  </link>
  <gazebo reference="lss_arm_link_3">
    <mu1 value="0.3"/>
    <mu2 value="0.3"/>
  </gazebo>
  <joint name="lss_arm_joint4" type="revolute">
    <parent link="lss_arm_link_3"/>
    <child link="lss_arm_link_4"/>
    <origin rpy="0 0 0.332259786519651" xyz="0.154274210199929 0.0532325846374996 0"/>
    <axis xyz="0 0 1"/>
    <limit effort="6.5687857" lower="-1.5707963267948966" upper="1.5707963267948966" velocity="6.283"/>
    <dynamics damping="0.01" friction="3.48"/>
  </joint>
  <transmission name="lss_arm_joint4_transmission">
    <type>transmission_interface/SimpleTransmission</type>
    <joint name="lss_arm_joint4">
      <hardwareInterface>hardware_interface/EffortJointInterface</hardwareInterface>
    </joint>
    <actuator name="lss_arm_joint4_actuator">
      <mechanicalReduction>1</mechanicalReduction>
    </actuator>
  </transmission>
  <gazebo reference="lss_arm_joint4">
    <springStiffness value="0.0"/>
    <springReference value="0.0"/>
  </gazebo>
  <link name="lss_arm_link_4">
    <visual>
      <origin rpy="0 0 0" xyz="0 0 0"/>
      <geometry>
        <mesh filename="package://lss_arm_description/meshes/visual/link_4.STL"/>
      </geometry>
      <material name="">
        <color rgba="0.3 0.3 0.3 1"/>
      </material>
    </visual>
    <collision>
      <origin rpy="0 0 0" xyz="0 0 0"/>
      <geometry>
        <mesh filename="package://lss_arm_description/meshes/collision/link_4.STL"/>
      </geometry>
    </collision>
    <inertial>
      <origin rpy="0 0 0" xyz="0.0446894562780881 -0.000131072409021604 0.000356231689785028"/>
      <mass value="0.0556319659037934"/>
      <inertia ixx="1.81337749108788E-05" ixy="-6.99513846908487E-14" ixz="9.19941036664484E-11" iyy="1.49173144124065E-05" iyz="2.14447838213905E-07" izz="9.12796728342695E-06"/>
    </inertial>
  </link>
  <gazebo reference="lss_arm_link_4">
    <mu1 value="0.3"/>
    <mu2 value="0.3"/>
  </gazebo>
  <ros2_control name="lss_arm_system" type="system">
    <hardware>
      <plugin>ign_ros2_control/IgnitionSystem</plugin>
    </hardware>
    <joint name="lss_arm_joint1">
      <param name="initial_position">0.0</param>
      <command_interface name="effort"/>
      <state_interface name="position"/>
      <state_interface name="velocity"/>
      <state_interface name="effort"/>
    </joint>
    <joint name="lss_arm_joint2">
      <param name="initial_position">0.8</param>
      <command_interface name="effort"/>
      <state_interface name="position"/>
      <state_interface name="velocity"/>
      <state_interface name="effort"/>
    </joint>
    <joint name="lss_arm_joint3">
      <param name="initial_position">-0.4</param>
      <command_interface name="effort"/>
      <state_interface name="position"/>
      <state_interface name="velocity"/>
      <state_interface name="effort"/>
    </joint>
    <joint name="lss_arm_joint4">
      <param name="initial_position">-0.4</param>
      <command_interface name="effort"/>
      <state_interface name="position"/>
      <state_interface name="velocity"/>
      <state_interface name="effort"/>
    </joint>
  </ros2_control>
  <joint name="lss_arm_gripper_r" type="revolute">
    <parent link="lss_arm_link_4"/>
    <child link="lss_arm_end_effector_r"/>
    <origin rpy="0 0 0" xyz="0.0507999999999996 -0.00273873977545905 -0.0123999999999962"/>
    <axis xyz="0 1 0"/>
    <limit effort="6.5687857" lower="0" upper="1.5707963267948966" velocity="6.283"/>
    <dynamics damping="0.01" friction="0.4"/>
  </joint>
  <transmission name="lss_arm_gripper_r_transmission">
    <type>transmission_interface/SimpleTransmission</type>
    <joint name="lss_arm_gripper_r">
      <hardwareInterface>hardware_interface/EffortJointInterface</hardwareInterface>
    </joint>
    <actuator name="lss_arm_gripper_r_actuator">
      <mechanicalReduction>1</mechanicalReduction>
    </actuator>
  </transmission>
  <gazebo reference="lss_arm_gripper_r">
    <springStiffness value="0.0"/>
    <springReference value="0.0"/>
  </gazebo>
  <link name="lss_arm_end_effector_r">
    <visual>
      <origin rpy="0 0 0" xyz="0 0 0"/>
      <geometry>
        <mesh filename="package://lss_arm_description/meshes/visual/end_effector_r.STL"/>
      </geometry>
      <material name="">
        <color rgba="0.3 0.3 0.3 1"/>
      </material>
    </visual>
    <collision>
      <origin rpy="0 0 0" xyz="0 0 0"/>
      <geometry>
        <mesh filename="package://lss_arm_description/meshes/collision/end_effector_r.STL"/>
      </geometry>
    </collision>
    <inertial>
      <origin rpy="0 0 0" xyz="0.0310712366675979 -0.0140452526813673 0.00133953163684892"/>
      <mass value="0.0152813047822834"/>
      <inertia ixx="6.12119941271843E-07" ixy="-1.61044889315886E-12" ixz="-4.41621763353496E-07" iyy="2.99804070646807E-06" iyz="-3.8879675590965E-12" izz="2.54603357212087E-06"/>
    </inertial>
  </link>
  <gazebo reference="lss_arm_end_effector_r">
    <mu1 value="0.3"/>
    <mu2 value="0.3"/>
  </gazebo>
  <joint name="lss_arm_gripper_l" type="revolute">
    <parent link="lss_arm_link_4"/>
    <child link="lss_arm_end_effector_l"/>
    <origin rpy="0 0 0" xyz="0.0507999999999993 -0.00273873977545905 0.0130000000000038"/>
    <axis xyz="0 1 0"/>
    <limit effort="6.5687857" lower="-1.5707963267948966" upper="0" velocity="6.283"/>
    <dynamics damping="0.01" friction="0.4"/>
  </joint>
  <transmission name="lss_arm_gripper_l_transmission">
    <type>transmission_interface/SimpleTransmission</type>
    <joint name="lss_arm_gripper_l">
      <hardwareInterface>hardware_interface/EffortJointInterface</hardwareInterface>
    </joint>
    <actuator name="lss_arm_gripper_l_actuator">
      <mechanicalReduction>1</mechanicalReduction>
    </actuator>
  </transmission>
  <gazebo reference="lss_arm_gripper_l">
    <springStiffness value="0.0"/>
    <springReference value="0.0"/>
  </gazebo>
  <link name="lss_arm_end_effector_l">
    <visual>
      <origin rpy="0 0 0" xyz="0 0 0"/>
      <geometry>
        <mesh filename="package://lss_arm_description/meshes/visual/end_effector_l.STL"/>
      </geometry>
      <material name="">
        <color rgba="0.3 0.3 0.3 1"/>
      </material>
    </visual>
    <collision>
      <origin rpy="0 0 0" xyz="0 0 0"/>
      <geometry>
        <mesh filename="package://lss_arm_description/meshes/collision/end_effector_l.STL"/>
      </geometry>
    </collision>
    <inertial>
      <origin rpy="0 0 0" xyz="0.0307726942893274 -0.0140975049159748 -0.0013266609885073"/>
      <mass value="0.0154295568992377"/>
      <inertia ixx="6.13242885883712E-07" ixy="-1.69555790218149E-12" ixz="4.41621764601781E-07" iyy="2.99899721506146E-06" iyz="4.09343888509186E-12" izz="2.54715653674288E-06"/>
    </inertial>
  </link>
  <gazebo reference="lss_arm_end_effector_l">
    <mu1 value="0.3"/>
    <mu2 value="0.3"/>
  </gazebo>
  <link name="lss_arm_hand_tcp">
  </link>
  <joint name="lss_arm_hand_tcp_virtual_joint" type="fixed">
    <parent link="lss_arm_link_4"/>
    <child link="lss_arm_hand_tcp"/>
    <origin rpy="0 0 0" xyz="0.11 0 0"/>
  </joint>
  <ros2_control name="lss_gripper_system" type="system">
    <hardware>
      <plugin>ign_ros2_control/IgnitionSystem</plugin>
    </hardware>
    <joint name="lss_arm_gripper_r">
      <param name="initial_position">0.4</param>
      <command_interface name="effort"/>
      <state_interface name="position"/>
      <state_interface name="velocity"/>
      <state_interface name="effort"/>
    </joint>
    <joint name="lss_arm_gripper_l">
      <param name="initial_position">-0.4</param>
      <param name="mimic">lss_arm_gripper_r</param>
      <param name="multiplier">-1</param>
      <command_interface name="effort"/>
      <state_interface name="position"/>
      <state_interface name="velocity"/>
      <state_interface name="effort"/>
    </joint>
  </ros2_control>
  <gazebo>
    <plugin filename="ign_ros2_control-system" name="ign_ros2_control::IgnitionROS2ControlPlugin">
      <parameters>/home/geraldineb/Documents/lss_ign_moveit/install/share/lss_arm_moveit/config/controllers_effort.yaml</parameters>
    </plugin>
  </gazebo>
</robot>
