<?xml version="1.0" encoding="utf-8" ?>
<!-- This URDF was automatically created by SolidWorks to URDF Exporter! Originally created by Stephen Brawner (brawner@gmail.com) 
     Commit Version: 1.5.1-0-g916b5db  Build Version: 1.5.7152.31018
     For more information, please see http://wiki.ros.org/sw_urdf_exporter -->
<robot name="lss_4dof_arm">
    <link name="dummy">
    </link>
    <link name="link_0">
        <inertial>
            <origin xyz="-9.22746070072536E-09 0.00772579323332284 0.0258164486308589" rpy="0 0 0" />
            <mass value="0.0745235989082936" />
            <inertia ixx="3.06926142332185E-05" ixy="9.19227938875618E-11" ixz="2.60960163114495E-12" iyy="2.37938175373349E-05" iyz="2.14419674075701E-07" izz="4.37402989726652E-05" />
        </inertial>
        <visual>
            <origin xyz="0 0 0" rpy="0 0 0" />
            <geometry>
                <mesh filename="package://lss_arm_description/meshes/link_0.STL" />
            </geometry>
            <material name="">
                <color rgba="0.3 0.3 0.3 1" />
            </material>
        </visual>
        <collision>
            <origin xyz="0 0 0" rpy="0 0 0" />
            <geometry>
                <mesh filename="package://lss_arm_description/meshes/link_0.STL" />
            </geometry>
        </collision>
    </link>
    <joint name="dummy_joint" type="fixed">
     <parent link="dummy"/>
     <child link="link_0"/>
    </joint>
    <link name="link_1">
        <inertial>
            <origin xyz="1.01932002252511E-06 0.0346260395806251 0.000106547591030595" rpy="0 0 0" />
            <mass value="0.0658784270809996" />
            <inertia ixx="2.21234278407549E-05" ixy="9.24359378260813E-11" ixz="-3.0028304734589E-12" iyy="2.30585181059312E-05" iyz="-2.19526468312218E-07" izz="1.89994043624137E-05" />
        </inertial>
        <visual>
            <origin xyz="0 0 0" rpy="0 0 0" />
            <geometry>
                <mesh filename="package://lss_arm_description/meshes/link_1.STL" />
            </geometry>
            <material name="">
                <color rgba="0.3 0.3 0.3 1" />
            </material>
        </visual>
        <collision>
            <origin xyz="0 0 0" rpy="0 0 0" />
            <geometry>
                <mesh filename="package://lss_arm_description/meshes/link_1.STL" />
            </geometry>
        </collision>
    </link>
    <joint name="joint0" type="revolute">
        <origin xyz="0 0 0.0427" rpy="1.5708 0 0" />
        <parent link="link_0" />
        <child link="link_1" />
        <axis xyz="0 1 0" />
        <limit lower="-1.57" upper="1.57" effort="0.27" velocity="5.23" />
    </joint>
    <link name="link_2">
        <inertial>
            <origin xyz="-0.111778545935364 0.0336104387117684 0.000180852718742204" rpy="0 0 0" />
            <mass value="0.0616037662847113" />
            <inertia ixx="1.66852308837933E-05" ixy="-1.03329219740433E-06" ixz="-4.43310654754874E-08" iyy="1.20242622304033E-05" iyz="-2.15007795219099E-07" izz="1.41673473261847E-05" />
        </inertial>
        <visual>
            <origin xyz="0 0 0" rpy="0 0 0" />
            <geometry>
                <mesh filename="package://lss_arm_description/meshes/link_2.STL" />
            </geometry>
            <material name="">
                <color rgba="0.3 0.3 0.3 1" />
            </material>
        </visual>
        <collision>
            <origin xyz="0 0 0" rpy="0 0 0" />
            <geometry>
                <mesh filename="package://lss_arm_description/meshes/link_2.STL" />
            </geometry>
        </collision>
    </link>
    <joint name="joint1" type="revolute">
        <origin xyz="0 0.0588000249999991 0" rpy="0 0 -1.3621104667496" />
        <parent link="link_1" />
        <child link="link_2" />
        <axis xyz="0 0 1" />
        <limit lower="-1.57" upper="1.57" effort="0.57" velocity="5.23" />
    </joint>
    <link name="link_3">
        <inertial>
            <origin xyz="0.119392702406077 0.0410364992253052 0.000154048902422472" rpy="0 0 0" />
            <mass value="0.062951277283338" />
            <inertia ixx="1.11886789972704E-05" ixy="-2.66768170363405E-06" ixz="-2.01609481649329E-07" iyy="1.79991460198167E-05" iyz="-6.9561531958934E-08" izz="1.46158276124359E-05" />
        </inertial>
        <visual>
            <origin xyz="0 0 0" rpy="0 0 0" />
            <geometry>
                <mesh filename="package://lss_arm_description/meshes/link_3.STL" />
            </geometry>
            <material name="">
                <color rgba="0.3 0.3 0.3 1" />
            </material>
        </visual>
        <collision>
            <origin xyz="0 0 0" rpy="0 0 0" />
            <geometry>
                <mesh filename="package://lss_arm_description/meshes/link_3.STL" />
            </geometry>
        </collision>
    </link>
    <joint name="joint2" type="revolute">
        <origin xyz="-0.12954806230389 0.0533975613048809 0" rpy="0 0 1.02985068022995" />
        <parent link="link_2" />
        <child link="link_3" />
        <axis xyz="0 0 1" />
        <limit lower="-1.57" upper="1.57" effort="0.57" velocity="5.23" />
    </joint>
    <link name="link_4">
        <inertial>
            <origin xyz="0.0463345232293113 -0.000217116498809761 0.000342446314582681" rpy="0 0 0" />
            <mass value="0.0552917317501261" />
            <inertia ixx="1.81135754161747E-05" ixy="3.0049831947197E-12" ixz="9.20482185162439E-11" iyy="1.48586070714427E-05" iyz="2.14450571018836E-07" izz="9.04738520213568E-06" />
        </inertial>
        <visual>
            <origin xyz="0 0 0" rpy="0 0 0" />
            <geometry>
                <mesh filename="package://lss_arm_description/meshes/link_4.STL" />
            </geometry>
            <material name="">
                <color rgba="0.3 0.3 0.3 1" />
            </material>
        </visual>
        <collision>
            <origin xyz="0 0 0" rpy="0 0 0" />
            <geometry>
                <mesh filename="package://lss_arm_description/meshes/link_4.STL" />
            </geometry>
        </collision>
    </link>
    <joint name="joint3" type="revolute">
        <origin xyz="0.154274210199929 0.0532325846374996 0" rpy="0 0 0.332259786519651" />
        <parent link="link_3" />
        <child link="link_4" />
        <axis xyz="0 0 1" />
        <limit lower="-1.57" upper="1.57" effort="0.27" velocity="5.23" />
    </joint>
    <link name="end_effector_r">
        <inertial>
            <origin xyz="0.0308013779043008 -0.0141013526461647 0.00131237715084586" rpy="0 0 0" />
            <mass value="0.0166262969986533" />
            <inertia ixx="6.38976786525478E-07" ixy="-1.49469409770964E-12" ixz="-4.41621752133789E-07" iyy="3.00353485001635E-06" iyz="-4.34708916625113E-12" izz="2.57289120441113E-06" />
        </inertial>
        <visual>
            <origin xyz="0 0 0" rpy="0 0 0" />
            <geometry>
                <mesh filename="package://lss_arm_description/meshes/end_effector_r.STL" />
            </geometry>
            <material name="">
                <color rgba="0.3 0.3 0.3 1" />
            </material>
        </visual>
        <collision>
            <origin xyz="0 0 0" rpy="0 0 0" />
            <geometry>
                <mesh filename="package://lss_arm_description/meshes/end_effector_r.STL" />
            </geometry>
        </collision>
    </link>
    <joint name="gripper_r" type="revolute">
        <origin xyz="0.0507999999999996 -0.00273873977545905 -0.0123999999999962" rpy="0 0 0" />
        <parent link="link_4" />
        <child link="end_effector_r" />
        <axis xyz="0 1 0" />
        <limit lower="0" upper="1.57" effort="0.27" velocity="5.23" />
    </joint>
    <link name="end_effector_l">
        <inertial>
            <origin xyz="0.0309551132879063 -0.0140672528822861 -0.0013189270605785" rpy="0 0 0" />
            <mass value="0.0165437278185932" />
            <inertia ixx="6.37840843695913E-07" ixy="-1.67462842205218E-12" ixz="4.41621808330111E-07" iyy="3.00246171921638E-06" iyz="3.99757576475728E-12" izz="2.57175512278327E-06" />
        </inertial>
        <visual>
            <origin xyz="0 0 0" rpy="0 0 0" />
            <geometry>
                <mesh filename="package://lss_arm_description/meshes/end_effector_l.STL" />
            </geometry>
            <material name="">
                <color rgba="0.3 0.3 0.3 1" />
            </material>
        </visual>
        <collision>
            <origin xyz="0 0 0" rpy="0 0 0" />
            <geometry>
                <mesh filename="package://lss_arm_description/meshes/end_effector_l.STL" />
            </geometry>
        </collision>
    </link>
    <joint name="gripper_l" type="revolute">
        <origin xyz="0.0507999999999993 -0.00273873977545905 0.0130000000000038" rpy="0 0 0" />
        <parent link="link_4" />
        <child link="end_effector_l" />
        <axis xyz="0 1 0" />
        <limit lower="-1.57" upper="0" effort="0.27" velocity="5.23" />
        <mimic joint="gripper_r" multiplier="-1" offset="0" />
    </joint>
    <transmission name="trans_joint0">
        <type>transmission_interface/SimpleTransmission</type>
        <joint name="joint0">
            <hardwareInterface>hardware_interface/EffortJointInterface</hardwareInterface>
        </joint>
        <actuator name="joint0_motor">
            <hardwareInterface>hardware_interface/EffortJointInterface</hardwareInterface>
            <mechanicalReduction>1</mechanicalReduction>
        </actuator>
    </transmission>
    <transmission name="trans_joint1">
        <type>transmission_interface/SimpleTransmission</type>
        <joint name="joint1">
            <hardwareInterface>hardware_interface/EffortJointInterface</hardwareInterface>
        </joint>
        <actuator name="joint1_motor">
            <hardwareInterface>hardware_interface/EffortJointInterface</hardwareInterface>
            <mechanicalReduction>1</mechanicalReduction>
        </actuator>
    </transmission>
    <transmission name="trans_joint2">
        <type>transmission_interface/SimpleTransmission</type>
        <joint name="joint2">
            <hardwareInterface>hardware_interface/EffortJointInterface</hardwareInterface>
        </joint>
        <actuator name="joint2_motor">
            <hardwareInterface>hardware_interface/EffortJointInterface</hardwareInterface>
            <mechanicalReduction>1</mechanicalReduction>
        </actuator>
    </transmission>
    <transmission name="trans_joint3">
        <type>transmission_interface/SimpleTransmission</type>
        <joint name="joint3">
            <hardwareInterface>hardware_interface/EffortJointInterface</hardwareInterface>
        </joint>
        <actuator name="joint3_motor">
            <hardwareInterface>hardware_interface/EffortJointInterface</hardwareInterface>
            <mechanicalReduction>1</mechanicalReduction>
        </actuator>
    </transmission>
    <transmission name="trans_gripper_r">
        <type>transmission_interface/SimpleTransmission</type>
        <joint name="gripper_r">
            <hardwareInterface>hardware_interface/EffortJointInterface</hardwareInterface>
        </joint>
        <actuator name="gripper_r_motor">
            <hardwareInterface>hardware_interface/EffortJointInterface</hardwareInterface>
            <mechanicalReduction>1</mechanicalReduction>
        </actuator>
    </transmission>
    <transmission name="trans_gripper_l">
        <type>transmission_interface/SimpleTransmission</type>
        <joint name="gripper_l">
            <hardwareInterface>hardware_interface/EffortJointInterface</hardwareInterface>
        </joint>
        <actuator name="gripper_l_motor">
            <hardwareInterface>hardware_interface/EffortJointInterface</hardwareInterface>
            <mechanicalReduction>1</mechanicalReduction>
        </actuator>
    </transmission>
    <gazebo>
        <plugin name="gazebo_ros_control">
            <robotNamespace>/</robotNamespace>
        </plugin>
    </gazebo>
</robot>

