<sdf version='1.8'>
  <model name='lss_arm'>
    <joint name='lss_arm_joint_0' type='fixed'>
      <pose relative_to='__model__'>0 0 0 0 -0 0</pose>
      <parent>world</parent>
      <child>lss_arm_link_0</child>
    </joint>
    <link name='lss_arm_link_0'>
      <pose relative_to='lss_arm_joint_0'>0 0 0 0 -0 0</pose>
      <inertial>
        <pose>-0 0.00785 0.02559 0 -0 0</pose>
        <mass>0.071741081366601803</mass>
        <inertia>
          <ixx>3.0636904073992999e-05</ixx>
          <ixy>9.1991087569794703e-11</ixy>
          <ixz>-6.9954291649509698e-14</ixz>
          <iyy>2.3738105430784199e-05</iyy>
          <iyz>2.1441763155438801e-07</iyz>
          <izz>4.3732554014946597e-05</izz>
        </inertia>
      </inertial>
      <collision name='lss_arm_link_0_collision'>
        <pose>0 0 0 0 -0 0</pose>
        <geometry>
          <mesh>
            <scale>1 1 1</scale>
            <uri>meshes/collision/link_0.STL</uri>
          </mesh>
        </geometry>
        <surface>
          <contact>
            <ode/>
          </contact>
          <friction>
            <ode>
              <mu>0.29999999999999999</mu>
              <mu2>0.29999999999999999</mu2>
            </ode>
          </friction>
        </surface>
      </collision>
      <visual name='lss_arm_link_0_visual'>
        <pose>0 0 0 0 -0 0</pose>
        <geometry>
          <mesh>
            <scale>1 1 1</scale>
            <uri>meshes/visual/link_0.STL</uri>
          </mesh>
        </geometry>
        <material>
          <diffuse>0.375 0.375 0.375 1</diffuse>
          <ambient>0.375 0.375 0.375 1</ambient>
        </material>
      </visual>
    </link>
    <joint name='lss_arm_joint_1' type='revolute'>
      <pose relative_to='lss_arm_link_0'>0 0 0.0427 1.5708 -0 0</pose>
      <parent>lss_arm_link_0</parent>
      <child>lss_arm_link_1</child>
      <axis>
        <xyz>0 1 0</xyz>
        <limit>
          <lower>-3.1415926535897931</lower>
          <upper>3.1415926535897931</upper>
          <effort>6.8439284999999996</effort>
          <velocity>6.2830000000000004</velocity>
        </limit>
        <dynamics>
          <damping>0.01</damping>
          <friction>3.48</friction>
          <spring_reference>0</spring_reference>
          <spring_stiffness>0</spring_stiffness>
        </dynamics>
      </axis>
      <physics>
        <ode>
          <limit>
            <cfm>0</cfm>
            <erp>0.20000000000000001</erp>
          </limit>
        </ode>
      </physics>
    </joint>
    <link name='lss_arm_link_1'>
      <pose relative_to='lss_arm_joint_1'>0 0 0 0 -0 0</pose>
      <inertial>
        <pose>0 0.034805 0.00015 0 -0 0</pose>
        <mass>0.062887576347183394</mass>
        <inertia>
          <ixx>2.20425725995968e-05</ixx>
          <ixy>9.1993511245884802e-11</ixy>
          <ixz>1.70368679861891e-13</ixz>
          <iyy>2.2948590897456299e-05</iyy>
          <iyz>-2.19524118186986e-07</iyz>
          <izz>1.89578527653699e-05</izz>
        </inertia>
      </inertial>
      <collision name='lss_arm_link_1_collision'>
        <pose>0 0 0 0 -0 0</pose>
        <geometry>
          <mesh>
            <scale>1 1 1</scale>
            <uri>meshes/collision/link_1.STL</uri>
          </mesh>
        </geometry>
        <surface>
          <contact>
            <ode/>
          </contact>
          <friction>
            <ode>
              <mu>0.29999999999999999</mu>
              <mu2>0.29999999999999999</mu2>
            </ode>
          </friction>
        </surface>
      </collision>
      <visual name='lss_arm_link_1_visual'>
        <pose>0 0 0 0 -0 0</pose>
        <geometry>
          <mesh>
            <scale>1 1 1</scale>
            <uri>meshes/visual/link_1.STL</uri>
          </mesh>
        </geometry>
        <material>
          <diffuse>0.375 0.375 0.375 1</diffuse>
          <ambient>0.375 0.375 0.375 1</ambient>
        </material>
      </visual>
    </link>
    <joint name='lss_arm_joint_2' type='revolute'>
      <pose relative_to='lss_arm_link_1'>0 0.0588 0 0 0 -1.36211</pose>
      <parent>lss_arm_link_1</parent>
      <child>lss_arm_link_2</child>
      <axis>
        <xyz>0 0 1</xyz>
        <limit>
          <lower>-2.1816615649929121</lower>
          <upper>2.1816615649929121</upper>
          <effort>6.8439284999999996</effort>
          <velocity>6.2830000000000004</velocity>
        </limit>
        <dynamics>
          <damping>0.01</damping>
          <friction>3.48</friction>
          <spring_reference>0</spring_reference>
          <spring_stiffness>0</spring_stiffness>
        </dynamics>
      </axis>
      <physics>
        <ode>
          <limit>
            <cfm>0</cfm>
            <erp>0.20000000000000001</erp>
          </limit>
        </ode>
      </physics>
    </joint>
    <link name='lss_arm_link_2'>
      <pose relative_to='lss_arm_joint_2'>0 0 0 0 -0 0</pose>
      <inertial>
        <pose>-0.112045 0.033642 0.000234 0 -0 0</pose>
        <mass>0.059220729789014201</mass>
        <inertia>
          <ixx>1.6633399872544299e-05</ixx>
          <ixy>-1.03352394963547e-06</ixy>
          <ixz>-4.4327410811638599e-08</ixz>
          <iyy>1.1971383214162999e-05</iyy>
          <iyz>-2.15005479062966e-07</iyz>
          <izz>1.41577057658295e-05</izz>
        </inertia>
      </inertial>
      <collision name='lss_arm_link_2_collision'>
        <pose>0 0 0 0 -0 0</pose>
        <geometry>
          <mesh>
            <scale>1 1 1</scale>
            <uri>meshes/collision/link_2.STL</uri>
          </mesh>
        </geometry>
        <surface>
          <contact>
            <ode/>
          </contact>
          <friction>
            <ode>
              <mu>0.29999999999999999</mu>
              <mu2>0.29999999999999999</mu2>
            </ode>
          </friction>
        </surface>
      </collision>
      <visual name='lss_arm_link_2_visual'>
        <pose>0 0 0 0 -0 0</pose>
        <geometry>
          <mesh>
            <scale>1 1 1</scale>
            <uri>meshes/visual/link_2.STL</uri>
          </mesh>
        </geometry>
        <material>
          <diffuse>0.375 0.375 0.375 1</diffuse>
          <ambient>0.375 0.375 0.375 1</ambient>
        </material>
      </visual>
    </link>
    <joint name='lss_arm_joint_3' type='revolute'>
      <pose relative_to='lss_arm_link_2'>-0.129548 0.053398 0 0 -0 1.02985</pose>
      <parent>lss_arm_link_2</parent>
      <child>lss_arm_link_3</child>
      <axis>
        <xyz>0 0 1</xyz>
        <limit>
          <lower>-1.919862177193763</lower>
          <upper>1.570796326794897</upper>
          <effort>6.8439284999999996</effort>
          <velocity>6.2830000000000004</velocity>
        </limit>
        <dynamics>
          <damping>0.01</damping>
          <friction>3.48</friction>
          <spring_reference>0</spring_reference>
          <spring_stiffness>0</spring_stiffness>
        </dynamics>
      </axis>
      <physics>
        <ode>
          <limit>
            <cfm>0</cfm>
            <erp>0.20000000000000001</erp>
          </limit>
        </ode>
      </physics>
    </joint>
    <link name='lss_arm_link_3'>
      <pose relative_to='lss_arm_joint_3'>0 0 0 0 -0 0</pose>
      <inertial>
        <pose>0.119623 0.041151 0.000345 0 -0 0</pose>
        <mass>0.060149035312470803</mass>
        <inertia>
          <ixx>1.1113660383281e-05</ixx>
          <ixy>-2.6746693260721798e-06</ixy>
          <ixz>2.0160569864272201e-07</ixz>
          <iyy>1.7941964943423101e-05</iyy>
          <iyz>-6.9564477599757001e-08</iyz>
          <izz>1.4580709936660301e-05</izz>
        </inertia>
      </inertial>
      <collision name='lss_arm_link_3_collision'>
        <pose>0 0 0 0 -0 0</pose>
        <geometry>
          <mesh>
            <scale>1 1 1</scale>
            <uri>meshes/collision/link_3.STL</uri>
          </mesh>
        </geometry>
        <surface>
          <contact>
            <ode/>
          </contact>
          <friction>
            <ode>
              <mu>0.29999999999999999</mu>
              <mu2>0.29999999999999999</mu2>
            </ode>
          </friction>
        </surface>
      </collision>
      <visual name='lss_arm_link_3_visual'>
        <pose>0 0 0 0 -0 0</pose>
        <geometry>
          <mesh>
            <scale>1 1 1</scale>
            <uri>meshes/visual/link_3.STL</uri>
          </mesh>
        </geometry>
        <material>
          <diffuse>0.375 0.375 0.375 1</diffuse>
          <ambient>0.375 0.375 0.375 1</ambient>
        </material>
      </visual>
    </link>
    <joint name='lss_arm_joint_4' type='revolute'>
      <pose relative_to='lss_arm_link_3'>0.154274 0.053233 0 0 -0 0.33226</pose>
      <parent>lss_arm_link_3</parent>
      <child>lss_arm_link_4</child>
      <axis>
        <xyz>0 0 1</xyz>
        <limit>
          <lower>-1.919862177193763</lower>
          <upper>1.919862177193763</upper>
          <effort>6.8439284999999996</effort>
          <velocity>6.2830000000000004</velocity>
        </limit>
        <dynamics>
          <damping>0.01</damping>
          <friction>3.48</friction>
          <spring_reference>0</spring_reference>
          <spring_stiffness>0</spring_stiffness>
        </dynamics>
      </axis>
      <physics>
        <ode>
          <limit>
            <cfm>0</cfm>
            <erp>0.20000000000000001</erp>
          </limit>
        </ode>
      </physics>
    </joint>
    <link name='lss_arm_link_4'>
      <pose relative_to='lss_arm_joint_4'>0 0 0 0 -0 0</pose>
      <inertial>
        <pose>0.044689 -0.000131 0.000356 0 -0 0</pose>
        <mass>0.0556319659037934</mass>
        <inertia>
          <ixx>1.8133774910878799e-05</ixx>
          <ixy>-6.9951384690848697e-14</ixy>
          <ixz>9.1994103666448402e-11</ixz>
          <iyy>1.49173144124065e-05</iyy>
          <iyz>2.14447838213905e-07</iyz>
          <izz>9.1279672834269492e-06</izz>
        </inertia>
      </inertial>
      <collision name='lss_arm_link_4_collision'>
        <pose>0 0 0 0 -0 0</pose>
        <geometry>
          <mesh>
            <scale>1 1 1</scale>
            <uri>meshes/collision/link_4.STL</uri>
          </mesh>
        </geometry>
        <surface>
          <contact>
            <ode/>
          </contact>
          <friction>
            <ode>
              <mu>0.29999999999999999</mu>
              <mu2>0.29999999999999999</mu2>
            </ode>
          </friction>
        </surface>
      </collision>
      <visual name='lss_arm_link_4_visual'>
        <pose>0 0 0 0 -0 0</pose>
        <geometry>
          <mesh>
            <scale>1 1 1</scale>
            <uri>meshes/visual/link_4.STL</uri>
          </mesh>
        </geometry>
        <material>
          <diffuse>0.375 0.375 0.375 1</diffuse>
          <ambient>0.375 0.375 0.375 1</ambient>
        </material>
      </visual>
    </link>
    <joint name='lss_arm_joint_5' type='revolute'>
      <pose relative_to='lss_arm_link_4'>0.0508 -0.002739 -0.0124 0 -0 0</pose>
      <parent>lss_arm_link_4</parent>
      <child>lss_arm_finger_r</child>
      <axis>
        <xyz>0 1 0</xyz>
        <limit>
          <lower>0</lower>
          <upper>1.570796326794897</upper>
          <effort>1.45</effort>
          <velocity>6.2830000000000004</velocity>
        </limit>
        <dynamics>
          <damping>0.01</damping>
          <friction>0.40000000000000002</friction>
          <spring_reference>0</spring_reference>
          <spring_stiffness>0</spring_stiffness>
        </dynamics>
      </axis>
      <physics>
        <ode>
          <limit>
            <cfm>0</cfm>
            <erp>0.20000000000000001</erp>
          </limit>
        </ode>
      </physics>
    </joint>
    <link name='lss_arm_finger_r'>
      <pose relative_to='lss_arm_joint_5'>0 0 0 0 -0 0</pose>
      <inertial>
        <pose>0.031071 -0.014045 0.00134 0 -0 0</pose>
        <mass>0.0152813047822834</mass>
        <inertia>
          <ixx>6.12119941271843e-07</ixx>
          <ixy>-1.6104488931588599e-12</ixy>
          <ixz>-4.4162176335349601e-07</ixz>
          <iyy>2.99804070646807e-06</iyy>
          <iyz>-3.8879675590964998e-12</iyz>
          <izz>2.54603357212087e-06</izz>
        </inertia>
      </inertial>
      <collision name='lss_arm_finger_r_collision'>
        <pose>0 0 0 0 -0 0</pose>
        <geometry>
          <mesh>
            <scale>1 1 1</scale>
            <uri>meshes/collision/finger_r.STL</uri>
          </mesh>
        </geometry>
        <surface>
          <contact>
            <ode/>
          </contact>
          <friction>
            <ode>
              <mu>0.29999999999999999</mu>
              <mu2>0.29999999999999999</mu2>
            </ode>
          </friction>
        </surface>
      </collision>
      <visual name='lss_arm_finger_r_visual'>
        <pose>0 0 0 0 -0 0</pose>
        <geometry>
          <mesh>
            <scale>1 1 1</scale>
            <uri>meshes/visual/finger_r.STL</uri>
          </mesh>
        </geometry>
        <material>
          <diffuse>0.375 0.375 0.375 1</diffuse>
          <ambient>0.375 0.375 0.375 1</ambient>
        </material>
      </visual>
    </link>
    <joint name='lss_arm_joint_6' type='revolute'>
      <pose relative_to='lss_arm_link_4'>0.0508 -0.002739 0.013 0 -0 0</pose>
      <parent>lss_arm_link_4</parent>
      <child>lss_arm_finger_l</child>
      <axis>
        <xyz>0 1 0</xyz>
        <limit>
          <lower>-1.570796326794897</lower>
          <upper>0</upper>
          <effort>1.45</effort>
          <velocity>6.2830000000000004</velocity>
        </limit>
        <dynamics>
          <damping>0.01</damping>
          <friction>0.40000000000000002</friction>
          <spring_reference>0</spring_reference>
          <spring_stiffness>0</spring_stiffness>
        </dynamics>
      </axis>
      <physics>
        <ode>
          <limit>
            <cfm>0</cfm>
            <erp>0.20000000000000001</erp>
          </limit>
        </ode>
      </physics>
    </joint>
    <link name='lss_arm_finger_l'>
      <pose relative_to='lss_arm_joint_6'>0 0 0 0 -0 0</pose>
      <inertial>
        <pose>0.030773 -0.014098 -0.001327 0 -0 0</pose>
        <mass>0.0154295568992377</mass>
        <inertia>
          <ixx>6.1324288588371195e-07</ixx>
          <ixy>-1.69555790218149e-12</ixy>
          <ixz>4.4162176460178102e-07</ixz>
          <iyy>2.99899721506146e-06</iyy>
          <iyz>4.0934388850918597e-12</iyz>
          <izz>2.5471565367428799e-06</izz>
        </inertia>
      </inertial>
      <collision name='lss_arm_finger_l_collision'>
        <pose>0 0 0 0 -0 0</pose>
        <geometry>
          <mesh>
            <scale>1 1 1</scale>
            <uri>meshes/collision/finger_l.STL</uri>
          </mesh>
        </geometry>
        <surface>
          <contact>
            <ode/>
          </contact>
          <friction>
            <ode>
              <mu>0.29999999999999999</mu>
              <mu2>0.29999999999999999</mu2>
            </ode>
          </friction>
        </surface>
      </collision>
      <visual name='lss_arm_finger_l_visual'>
        <pose>0 0 0 0 -0 0</pose>
        <geometry>
          <mesh>
            <scale>1 1 1</scale>
            <uri>meshes/visual/finger_l.STL</uri>
          </mesh>
        </geometry>
        <material>
          <diffuse>0.375 0.375 0.375 1</diffuse>
          <ambient>0.375 0.375 0.375 1</ambient>
        </material>
      </visual>
    </link>
    <static>0</static>
    <plugin name='ign_ros2_control::IgnitionROS2ControlPlugin' filename='libign_ros2_control-system.so'>
      <parameters>/home/geraldinebc/Documents/TB4_LSS_PROJECT/lss_arm/install/lss_arm_moveit/share/lss_arm_moveit/config/controllers_position.yaml</parameters>
    </plugin>
  </model>
</sdf>
